[{"market":"0x37a6de1b21803e5f3fb1965116218215d79963af4f7e51659696366267a63a03","asset_id":"69910730841487615802736046038473620030754616421912831175284551372639933569112","timestamp":"1779223882222","hash":"9b947278caccb41d166fb08a02fa98fdf095e8a9","bids":[{"price":"0.001","size":"2034238"},{"price":"0.002","size":"1210090"},{"price":"0.003","size":"11000"},{"price":"0.005","size":"500"},{"price":"0.006","size":"20"},{"price":"0.007","size":"500"},{"price":"0.009","size":"120"},{"price":"0.01","size":"8199.91"},{"price":"0.011","size":"15074.93"},{"price":"0.012","size":"15483.26"},{"price":"0.013","size":"569468.36"},{"price":"0.014","size":"588462.84"},{"price":"0.015","size":"336766.55"}],"asks":[{"price":"0.999","size":"6705"},{"price":"0.998","size":"116.73"},{"price":"0.95","size":"20"},{"price":"0.949","size":"11.52"},{"price":"0.9","size":"1700"},{"price":"0.8","size":"750"},{"price":"0.799","size":"5.84"},{"price":"0.754","size":"121.95"},{"price":"0.7","size":"627.11"},{"price":"0.6","size":"34375"},{"price":"0.599","size":"1496"},{"price":"0.5","size":"26682.99"},{"price":"0.49","size":"62.5"},{"price":"0.47","size":"175536.88"},{"price":"0.469","size":"1099.34"},{"price":"0.4","size":"54833.33"},{"price":"0.35","size":"15384.62"},{"price":"0.346","size":"1500"},{"price":"0.34","size":"4000"},{"price":"0.28","size":"4600"},{"price":"0.25","size":"600"},{"price":"0.22","size":"4600"},{"price":"0.2","size":"7599.9"},{"price":"0.199","size":"5000"},{"price":"0.19","size":"600"},{"price":"0.175","size":"3199.97"},{"price":"0.162","size":"100"},{"price":"0.16","size":"5600"},{"price":"0.15","size":"7499.9"},{"price":"0.148","size":"3484.72"},{"price":"0.141","size":"100"},{"price":"0.139","size":"5000"},{"price":"0.135","size":"4310"},{"price":"0.13","size":"600"},{"price":"0.128","size":"3125"},{"price":"0.12","size":"300"},{"price":"0.11","size":"600"},{"price":"0.1","size":"13468.82"},{"price":"0.099","size":"4100"},{"price":"0.097","size":"5000"},{"price":"0.095","size":"3200"},{"price":"0.09","size":"24067.5"},{"price":"0.089","size":"62484.66"},{"price":"0.087","size":"4000"},{"price":"0.084","size":"30"},{"price":"0.08","size":"9400"},{"price":"0.079","size":"5000"},{"price":"0.078","size":"100"},{"price":"0.077","size":"100"},{"price":"0.074","size":"4000"},{"price":"0.069","size":"4600"},{"price":"0.068","size":"1500"},{"price":"0.067","size":"5000"},{"price":"0.065","size":"3200"},{"price":"0.064","size":"3125"},{"price":"0.06","size":"4200"},{"price":"0.059","size":"4600"},{"price":"0.057","size":"100"},{"price":"0.055","size":"5000"},{"price":"0.051","size":"59"},{"price":"0.05","size":"12352.65"},{"price":"0.049","size":"5882"},{"price":"0.046","size":"1550"},{"price":"0.045","size":"4000"},{"price":"0.044","size":"5007.22"},{"price":"0.04","size":"6530.1"},{"price":"0.039","size":"4000"},{"price":"0.038","size":"4052.63"},{"price":"0.037","size":"1953.02"},{"price":"0.036","size":"1500"},{"price":"0.035","size":"4835.66"},{"price":"0.034","size":"7118"},{"price":"0.033","size":"2123.78"},{"price":"0.032","size":"16812.5"},{"price":"0.031","size":"3875.93"},{"price":"0.03","size":"7633.29"},{"price":"0.029","size":"5000"},{"price":"0.028","size":"11559.05"},{"price":"0.027","size":"4186.25"},{"price":"0.026","size":"9020"},{"price":"0.025","size":"1730"},{"price":"0.024","size":"6361.8"},{"price":"0.022","size":"6130.27"},{"price":"0.021","size":"21830.56"},{"price":"0.02","size":"69078.32"},{"price":"0.019","size":"1224.93"},{"price":"0.018","size":"26940"},{"price":"0.017","size":"3180.61"},{"price":"0.016","size":"2054127.47"}],"tick_size":"0.001","event_type":"book","last_trade_price":"0.015"},{"market":"0xaa145cf5714455f546afe53037b8712df749ba96c04820c2d41f37f877f29697","asset_id":"88815071170531292306771197855496056590773004819748629645131852770667568975872","timestamp":"1779223820968","hash":"eaef34f3fa18c50ef7fd47ace265997a0891c7a8","bids":[{"price":"0.001","size":"106142.87"},{"price":"0.002","size":"15621.03"},{"price":"0.003","size":"6000"},{"price":"0.004","size":"2500"},{"price":"0.005","size":"1000"},{"price":"0.007","size":"1765.63"},{"price":"0.01","size":"131795.39"},{"price":"0.011","size":"5000"},{"price":"0.02","size":"28642.74"},{"price":"0.021","size":"2513.88"},{"price":"0.022","size":"5000"},{"price":"0.023","size":"500"},{"price":"0.025","size":"30561.75"},{"price":"0.03","size":"30025.9"},{"price":"0.04","size":"65080.66"},{"price":"0.05","size":"7370"},{"price":"0.053","size":"500"},{"price":"0.075","size":"4065.33"},{"price":"0.1","size":"21764.74"},{"price":"0.101","size":"3739.67"},{"price":"0.13","size":"100"},{"price":"0.15","size":"15205.95"},{"price":"0.151","size":"6082.38"},{"price":"0.18","size":"200"},{"price":"0.2","size":"950"},{"price":"0.287","size":"129.99"},{"price":"0.3","size":"934.1"},{"price":"0.35","size":"1691.83"},{"price":"0.351","size":"2500"},{"price":"0.4","size":"200"},{"price":"0.48","size":"12097.73"},{"price":"0.481","size":"311"},{"price":"0.501","size":"300"},{"price":"0.51","size":"1254.57"},{"price":"0.6","size":"63.99"},{"price":"0.601","size":"25"},{"price":"0.7","size":"200"},{"price":"0.778","size":"10000"},{"price":"0.8","size":"12.5"},{"price":"0.86","size":"484.88"},{"price":"0.868","size":"454.33"},{"price":"0.873","size":"100"},{"price":"0.874","size":"413.15"},{"price":"0.881","size":"385.56"},{"price":"0.889","size":"351.67"},{"price":"0.89","size":"7746.79"},{"price":"0.894","size":"50"},{"price":"0.897","size":"317.55"},{"price":"0.901","size":"3333"},{"price":"0.905","size":"1050"},{"price":"0.906","size":"295.71"},{"price":"0.914","size":"256.69"},{"price":"0.915","size":"50"},{"price":"0.92","size":"61"},{"price":"0.923","size":"210.6"},{"price":"0.928","size":"2500"},{"price":"0.929","size":"3000"},{"price":"0.93","size":"100"},{"price":"0.934","size":"175"},{"price":"0.935","size":"1206.23"},{"price":"0.936","size":"11172"},{"price":"0.938","size":"3400"},{"price":"0.939","size":"2500"},{"price":"0.94","size":"22322"},{"price":"0.95","size":"16311"},{"price":"0.952","size":"3000"},{"price":"0.955","size":"10"},{"price":"0.956","size":"2505"},{"price":"0.957","size":"2850"},{"price":"0.958","size":"1400"},{"price":"0.959","size":"2400"},{"price":"0.96","size":"910"},{"price":"0.961","size":"6200"},{"price":"0.962","size":"800"},{"price":"0.963","size":"200"},{"price":"0.964","size":"14600"},{"price":"0.965","size":"14510"},{"price":"0.966","size":"11200"},{"price":"0.967","size":"10722"},{"price":"0.968","size":"8333"},{"price":"0.969","size":"16388"},{"price":"0.97","size":"47100"},{"price":"0.971","size":"6510"},{"price":"0.972","size":"6009.99"},{"price":"0.973","size":"15583.58"},{"price":"0.974","size":"32010"},{"price":"0.975","size":"46353"},{"price":"0.976","size":"44822.1"},{"price":"0.977","size":"15000"},{"price":"0.978","size":"28454.71"},{"price":"0.979","size":"45907"},{"price":"0.98","size":"70719"},{"price":"0.981","size":"33400"},{"price":"0.982","size":"26322"},{"price":"0.983","size":"48033.02"},{"price":"0.984","size":"23477.13"},{"price":"0.985","size":"63206.8"},{"price":"0.986","size":"36936.46"},{"price":"0.987","size":"19881.09"},{"price":"0.988","size":"37421.69"}],"asks":[{"price":"0.999","size":"2101745.21"},{"price":"0.998","size":"1705957.87"},{"price":"0.997","size":"478684.94"},{"price":"0.996","size":"89355.97"},{"price":"0.995","size":"126301.07"},{"price":"0.994","size":"72260"},{"price":"0.993","size":"55076.02"},{"price":"0.992","size":"62180"},{"price":"0.991","size":"79645.67"},{"price":"0.99","size":"162123.15"},{"price":"0.989","size":"13868.74"}],"tick_size":"0.001","event_type":"book","last_trade_price":"0.989"},{"market":"0x8530b96422523df2024c4242021b58da538c5e94ba525e8f9893c3fc2f469160","asset_id":"90341073610328513874226762002064133262679100936760740635957635490606188341771","timestamp":"1779223894555","hash":"6aba60641194fe9c82eb4fdd36e72d0cf283b817","bids":[{"price":"0.01","size":"2262149.61"},{"price":"0.02","size":"118704.83"},{"price":"0.03","size":"4783.32"},{"price":"0.04","size":"39831.68"},{"price":"0.05","size":"655"},{"price":"0.07","size":"25863.6"},{"price":"0.08","size":"358.32"},{"price":"0.09","size":"2370"},{"price":"0.1","size":"500"},{"price":"0.11","size":"5.32"},{"price":"0.14","size":"5348.18"},{"price":"0.15","size":"807.48"},{"price":"0.16","size":"268.73"},{"price":"0.18","size":"2025"},{"price":"0.19","size":"384"},{"price":"0.2","size":"607"},{"price":"0.21","size":"394.06"},{"price":"0.22","size":"299.07"},{"price":"0.23","size":"86.07"},{"price":"0.24","size":"162.38"},{"price":"0.28","size":"369.43"},{"price":"0.29","size":"165.07"},{"price":"0.3","size":"3024"},{"price":"0.31","size":"383.17"},{"price":"0.32","size":"31.25"},{"price":"0.34","size":"1054.65"},{"price":"0.35","size":"437.12"},{"price":"0.36","size":"76.5"},{"price":"0.38","size":"80.62"},{"price":"0.39","size":"184.88"},{"price":"0.4","size":"36.12"},{"price":"0.45","size":"11205.68"},{"price":"0.46","size":"500"},{"price":"0.49","size":"75"},{"price":"0.5","size":"496.89"},{"price":"0.51","size":"905"},{"price":"0.52","size":"50"},{"price":"0.53","size":"400"},{"price":"0.54","size":"28.19"},{"price":"0.55","size":"50"},{"price":"0.56","size":"10"},{"price":"0.58","size":"300"},{"price":"0.59","size":"100"},{"price":"0.6","size":"400"},{"price":"0.61","size":"300"},{"price":"0.62","size":"1917"},{"price":"0.63","size":"1734"},{"price":"0.64","size":"2132"},{"price":"0.65","size":"113955.21"},{"price":"0.66","size":"128239.41"},{"price":"0.67","size":"1028231.2"},{"price":"0.68","size":"69280.07"}],"asks":[{"price":"0.99","size":"2098092.38"},{"price":"0.98","size":"8706.42"},{"price":"0.97","size":"1992.84"},{"price":"0.96","size":"2383.26"},{"price":"0.95","size":"505"},{"price":"0.94","size":"1019.64"},{"price":"0.93","size":"1144.58"},{"price":"0.92","size":"7.24"},{"price":"0.91","size":"1406.34"},{"price":"0.9","size":"3769.22"},{"price":"0.89","size":"712"},{"price":"0.88","size":"849.7"},{"price":"0.87","size":"742.95"},{"price":"0.86","size":"163.93"},{"price":"0.85","size":"1748.71"},{"price":"0.84","size":"724.37"},{"price":"0.83","size":"562"},{"price":"0.81","size":"150"},{"price":"0.8","size":"123.78"},{"price":"0.79","size":"1062"},{"price":"0.78","size":"100"},{"price":"0.77","size":"100"},{"price":"0.76","size":"5"},{"price":"0.75","size":"420"},{"price":"0.74","size":"12845.24"},{"price":"0.73","size":"104265.08"},{"price":"0.72","size":"22960.27"},{"price":"0.71","size":"726274.54"},{"price":"0.7","size":"1513157.93"},{"price":"0.69","size":"3286086.85"}],"tick_size":"0.01","event_type":"book","last_trade_price":"0.680"},{"market":"0xb99047b9bdf8132c367cf327936676a1186a6eb57b86a742fdfe812f86b2e3b9","asset_id":"76150632180345500942617667303892128055275310542626568919906405357352468359168","timestamp":"1779223899106","hash":"ac6041df61a4f67fc90ffd4d23dda4c3e6703fb3","bids":[{"price":"0.01","size":"28603.48"},{"price":"0.02","size":"7.91"},{"price":"0.03","size":"1157.97"},{"price":"0.04","size":"1825"},{"price":"0.05","size":"5.54"},{"price":"0.06","size":"21.86"},{"price":"0.07","size":"5.4"},{"price":"0.08","size":"40"},{"price":"0.09","size":"829.14"},{"price":"0.1","size":"8.21"},{"price":"0.11","size":"38.86"},{"price":"0.12","size":"45.25"},{"price":"0.13","size":"119"},{"price":"0.14","size":"740"},{"price":"0.15","size":"17805.94"},{"price":"0.16","size":"3616.39"},{"price":"0.17","size":"2407"},{"price":"0.18","size":"6196"},{"price":"0.19","size":"34.91"}],"asks":[{"price":"0.99","size":"297933.95"},{"price":"0.98","size":"162709.35"},{"price":"0.97","size":"7500"},{"price":"0.96","size":"500"},{"price":"0.95","size":"10910"},{"price":"0.94","size":"29932"},{"price":"0.93","size":"78051.24"},{"price":"0.92","size":"51937.23"},{"price":"0.91","size":"3711"},{"price":"0.88","size":"12529.15"},{"price":"0.87","size":"5952"},{"price":"0.86","size":"8289.15"},{"price":"0.81","size":"1760"},{"price":"0.75","size":"40"},{"price":"0.69","size":"26"},{"price":"0.6","size":"20"},{"price":"0.59","size":"11.78"},{"price":"0.54","size":"35"},{"price":"0.52","size":"525"},{"price":"0.5","size":"505"},{"price":"0.49","size":"50"},{"price":"0.48","size":"535"},{"price":"0.46","size":"515"},{"price":"0.45","size":"9.09"},{"price":"0.44","size":"505"},{"price":"0.43","size":"266.03"},{"price":"0.42","size":"580"},{"price":"0.4","size":"540"},{"price":"0.38","size":"500"},{"price":"0.37","size":"40"},{"price":"0.36","size":"560"},{"price":"0.34","size":"530"},{"price":"0.32","size":"21.27"},{"price":"0.31","size":"285"},{"price":"0.3","size":"883.56"},{"price":"0.29","size":"11.17"},{"price":"0.28","size":"19.22"},{"price":"0.27","size":"10.85"},{"price":"0.26","size":"28.75"},{"price":"0.25","size":"814"},{"price":"0.24","size":"15450.06"},{"price":"0.23","size":"1736.17"},{"price":"0.22","size":"6064.17"},{"price":"0.21","size":"30981.55"},{"price":"0.2","size":"10538.17"}],"tick_size":"0.01","event_type":"book","last_trade_price":"0.810"},{"market":"0x865ac5b1fdc1706ca8cf0f25cc63544b5abcbb6819e25d52d9ac3ee4b3446726","asset_id":"35897145766259317849531537649732979331853484456543966713822507439506839868603","timestamp":"1779223899141","hash":"a4100c381f4af7c2d3a27b35778df8680a28151c","bids":[{"price":"0.01","size":"196050"},{"price":"0.02","size":"111220"},{"price":"0.03","size":"13800"},{"price":"0.04","size":"650"},{"price":"0.05","size":"650"},{"price":"0.06","size":"22252"},{"price":"0.07","size":"6000"},{"price":"0.08","size":"1700"},{"price":"0.11","size":"3030"},{"price":"0.12","size":"500"},{"price":"0.13","size":"302"},{"price":"0.14","size":"150"},{"price":"0.2","size":"1760"},{"price":"0.22","size":"277.77"},{"price":"0.26","size":"445"},{"price":"0.28","size":"300"},{"price":"0.3","size":"300"},{"price":"0.31","size":"46.52"},{"price":"0.32","size":"360"},{"price":"0.33","size":"2395"},{"price":"0.34","size":"300"},{"price":"0.36","size":"300"},{"price":"0.37","size":"24.32"},{"price":"0.38","size":"300"},{"price":"0.39","size":"30"},{"price":"0.4","size":"305"},{"price":"0.42","size":"341.9"},{"price":"0.43","size":"2000"},{"price":"0.44","size":"300"},{"price":"0.45","size":"65"},{"price":"0.46","size":"144"},{"price":"0.47","size":"164"},{"price":"0.48","size":"938"},{"price":"0.49","size":"22"},{"price":"0.5","size":"106.07"},{"price":"0.51","size":"326.81"},{"price":"0.52","size":"1385"}],"asks":[{"price":"0.99","size":"191070"},{"price":"0.98","size":"30650"},{"price":"0.97","size":"476882.92"},{"price":"0.96","size":"650"},{"price":"0.95","size":"14470"},{"price":"0.93","size":"550"},{"price":"0.91","size":"2600"},{"price":"0.9","size":"5900"},{"price":"0.89","size":"650"},{"price":"0.84","size":"292"},{"price":"0.8","size":"303.59"},{"price":"0.79","size":"3879.15"},{"price":"0.78","size":"300"},{"price":"0.76","size":"360"},{"price":"0.75","size":"1135.21"},{"price":"0.74","size":"215"},{"price":"0.72","size":"300"},{"price":"0.71","size":"99.99"},{"price":"0.7","size":"305.66"},{"price":"0.69","size":"47.09"},{"price":"0.68","size":"50"},{"price":"0.67","size":"6.06"},{"price":"0.66","size":"300"},{"price":"0.64","size":"2003"},{"price":"0.62","size":"303"},{"price":"0.61","size":"27.17"},{"price":"0.6","size":"196"},{"price":"0.59","size":"1347"},{"price":"0.58","size":"109"},{"price":"0.57","size":"484"},{"price":"0.56","size":"2014.27"},{"price":"0.55","size":"485"},{"price":"0.54","size":"325.35"}],"tick_size":"0.01","event_type":"book","last_trade_price":"0.530"},{"market":"0xbb4f0756c168d3cf10572e400ad21ae19d944330b38deb376eb0ab0b03bd9541","asset_id":"15440616929260688210891508735273449757917680268858577955483554234534638706061","timestamp":"1779223896424","hash":"a693e4791aaa82d5beec75fab807973662f53e6a","bids":[{"price":"0.001","size":"100099"},{"price":"0.002","size":"5000"},{"price":"0.006","size":"25000"},{"price":"0.01","size":"7169.98"},{"price":"0.012","size":"15000"},{"price":"0.013","size":"55555"},{"price":"0.02","size":"20000"},{"price":"0.021","size":"1000"},{"price":"0.03","size":"396.07"},{"price":"0.04","size":"200"},{"price":"0.051","size":"5000"},{"price":"0.052","size":"33333"},{"price":"0.106","size":"200"},{"price":"0.108","size":"6000"},{"price":"0.111","size":"5000"},{"price":"0.12","size":"3100"},{"price":"0.121","size":"10000"},{"price":"0.151","size":"1500"},{"price":"0.18","size":"64"},{"price":"0.19","size":"3711"},{"price":"0.22","size":"100"},{"price":"0.221","size":"100"},{"price":"0.23","size":"600"},{"price":"0.231","size":"3486"},{"price":"0.232","size":"8000"},{"price":"0.42","size":"63"},{"price":"0.48","size":"30"},{"price":"0.499","size":"100"},{"price":"0.5","size":"5"},{"price":"0.501","size":"500"},{"price":"0.502","size":"1500"},{"price":"0.51","size":"454.75"},{"price":"0.75","size":"60"},{"price":"0.767","size":"60"},{"price":"0.768","size":"400"},{"price":"0.769","size":"60"},{"price":"0.77","size":"60"},{"price":"0.78","size":"3711"},{"price":"0.8","size":"30"},{"price":"0.88","size":"113.62"},{"price":"0.92","size":"5"},{"price":"0.95","size":"109"},{"price":"0.99","size":"43659.72"},{"price":"0.991","size":"1277"},{"price":"0.992","size":"10"},{"price":"0.993","size":"10"},{"price":"0.994","size":"10"},{"price":"0.995","size":"10"},{"price":"0.997","size":"6.83"},{"price":"0.999","size":"675905.49"}],"asks":[],"tick_size":"0.001","event_type":"book","last_trade_price":"0.999"},{"market":"0x37a6de1b21803e5f3fb1965116218215d79963af4f7e51659696366267a63a03","asset_id":"64291832879722161879651094688874074984529456778901604558632306686248535158725","timestamp":"1779223882222","hash":"f1ffbc73547883995bdef559432dd65f873001f7","bids":[{"price":"0.001","size":"6705"},{"price":"0.002","size":"116.73"},{"price":"0.05","size":"20"},{"price":"0.051","size":"11.52"},{"price":"0.1","size":"1700"},{"price":"0.2","size":"750"},{"price":"0.201","size":"5.84"},{"price":"0.246","size":"121.95"},{"price":"0.3","size":"627.11"},{"price":"0.4","size":"34375"},{"price":"0.401","size":"1496"},{"price":"0.5","size":"26682.99"},{"price":"0.51","size":"62.5"},{"price":"0.53","size":"175536.88"},{"price":"0.531","size":"1099.34"},{"price":"0.6","size":"54833.33"},{"price":"0.65","size":"15384.62"},{"price":"0.654","size":"1500"},{"price":"0.66","size":"4000"},{"price":"0.72","size":"4600"},{"price":"0.75","size":"600"},{"price":"0.78","size":"4600"},{"price":"0.8","size":"7599.9"},{"price":"0.801","size":"5000"},{"price":"0.81","size":"600"},{"price":"0.825","size":"3199.97"},{"price":"0.838","size":"100"},{"price":"0.84","size":"5600"},{"price":"0.85","size":"7499.9"},{"price":"0.852","size":"3484.72"},{"price":"0.859","size":"100"},{"price":"0.861","size":"5000"},{"price":"0.865","size":"4310"},{"price":"0.87","size":"600"},{"price":"0.872","size":"3125"},{"price":"0.88","size":"300"},{"price":"0.89","size":"600"},{"price":"0.9","size":"13468.82"},{"price":"0.901","size":"4100"},{"price":"0.903","size":"5000"},{"price":"0.905","size":"3200"},{"price":"0.91","size":"24067.5"},{"price":"0.911","size":"62484.66"},{"price":"0.913","size":"4000"},{"price":"0.916","size":"30"},{"price":"0.92","size":"9400"},{"price":"0.921","size":"5000"},{"price":"0.922","size":"100"},{"price":"0.923","size":"100"},{"price":"0.926","size":"4000"},{"price":"0.931","size":"4600"},{"price":"0.932","size":"1500"},{"price":"0.933","size":"5000"},{"price":"0.935","size":"3200"},{"price":"0.936","size":"3125"},{"price":"0.94","size":"4200"},{"price":"0.941","size":"4600"},{"price":"0.943","size":"100"},{"price":"0.945","size":"5000"},{"price":"0.949","size":"59"},{"price":"0.95","size":"12352.65"},{"price":"0.951","size":"5882"},{"price":"0.954","size":"1550"},{"price":"0.955","size":"4000"},{"price":"0.956","size":"5007.22"},{"price":"0.96","size":"6530.1"},{"price":"0.961","size":"4000"},{"price":"0.962","size":"4052.63"},{"price":"0.963","size":"1953.02"},{"price":"0.964","size":"1500"},{"price":"0.965","size":"4835.66"},{"price":"0.966","size":"7118"},{"price":"0.967","size":"2123.78"},{"price":"0.968","size":"16812.5"},{"price":"0.969","size":"3875.93"},{"price":"0.97","size":"7633.29"},{"price":"0.971","size":"5000"},{"price":"0.972","size":"11559.05"},{"price":"0.973","size":"4186.25"},{"price":"0.974","size":"9020"},{"price":"0.975","size":"1730"},{"price":"0.976","size":"6361.8"},{"price":"0.978","size":"6130.27"},{"price":"0.979","size":"21830.56"},{"price":"0.98","size":"69078.32"},{"price":"0.981","size":"1224.93"},{"price":"0.982","size":"26940"},{"price":"0.983","size":"3180.61"},{"price":"0.984","size":"2054127.47"}],"asks":[{"price":"0.999","size":"2034238"},{"price":"0.998","size":"1210090"},{"price":"0.997","size":"11000"},{"price":"0.995","size":"500"},{"price":"0.994","size":"20"},{"price":"0.993","size":"500"},{"price":"0.991","size":"120"},{"price":"0.99","size":"8199.91"},{"price":"0.989","size":"15074.93"},{"price":"0.988","size":"15483.26"},{"price":"0.987","size":"569468.36"},{"price":"0.986","size":"588462.84"},{"price":"0.985","size":"336766.55"}],"tick_size":"0.001","event_type":"book","last_trade_price":"0.015"},{"market":"0x9a0da0f25f94fce088c88803b296d48dd19717370dbafa97484f3ddac70ee4dc","asset_id":"52263517794885987721295730397921579339326307520815595834678501811222224358828","timestamp":"1779223895420","hash":"233f54be48d094d98a744f59a05305c2fe40adc0","bids":[{"price":"0.01","size":"2001209"},{"price":"0.02","size":"4729.47"},{"price":"0.03","size":"400133.32"},{"price":"0.04","size":"3653"},{"price":"0.05","size":"1349.54"},{"price":"0.06","size":"3737.55"},{"price":"0.07","size":"1590.34"},{"price":"0.08","size":"1678.68"},{"price":"0.09","size":"1208.76"},{"price":"0.1","size":"2514"},{"price":"0.11","size":"1349.37"},{"price":"0.12","size":"3668.68"},{"price":"0.13","size":"1038.11"},{"price":"0.14","size":"1526.91"},{"price":"0.16","size":"980.32"},{"price":"0.17","size":"1787.34"},{"price":"0.18","size":"908.76"},{"price":"0.19","size":"732.98"},{"price":"0.2","size":"1302.28"},{"price":"0.21","size":"300"},{"price":"0.22","size":"996"},{"price":"0.23","size":"500"},{"price":"0.24","size":"500"},{"price":"0.25","size":"652"},{"price":"0.26","size":"700"},{"price":"0.27","size":"2958.55"},{"price":"0.28","size":"571.43"},{"price":"0.29","size":"7584.34"},{"price":"0.3","size":"43853.31"},{"price":"0.31","size":"44975.72"},{"price":"0.32","size":"392785.24"}],"asks":[{"price":"0.99","size":"2001410"},{"price":"0.98","size":"1750"},{"price":"0.97","size":"400133.32"},{"price":"0.94","size":"1084.6"},{"price":"0.93","size":"1134.41"},{"price":"0.92","size":"1711.95"},{"price":"0.86","size":"798.05"},{"price":"0.85","size":"1369.55"},{"price":"0.84","size":"682"},{"price":"0.82","size":"723.07"},{"price":"0.8","size":"148.09"},{"price":"0.79","size":"437.53"},{"price":"0.78","size":"839.44"},{"price":"0.76","size":"677.88"},{"price":"0.74","size":"36.8"},{"price":"0.73","size":"51.69"},{"price":"0.72","size":"33.82"},{"price":"0.71","size":"589.8"},{"price":"0.7","size":"3258.93"},{"price":"0.68","size":"1035.88"},{"price":"0.67","size":"50.75"},{"price":"0.66","size":"543.67"},{"price":"0.65","size":"100"},{"price":"0.64","size":"769.49"},{"price":"0.6","size":"40"},{"price":"0.58","size":"1100"},{"price":"0.57","size":"500"},{"price":"0.52","size":"16.06"},{"price":"0.5","size":"48.3"},{"price":"0.49","size":"6.89"},{"price":"0.48","size":"19.23"},{"price":"0.47","size":"800"},{"price":"0.45","size":"60"},{"price":"0.44","size":"15.15"},{"price":"0.43","size":"1296"},{"price":"0.42","size":"500"},{"price":"0.41","size":"500"},{"price":"0.4","size":"515.15"},{"price":"0.39","size":"714.99"},{"price":"0.38","size":"403"},{"price":"0.37","size":"8205"},{"price":"0.36","size":"14041.86"},{"price":"0.35","size":"17701.6"},{"price":"0.34","size":"99962.9"},{"price":"0.33","size":"184439.84"}],"tick_size":"0.01","event_type":"book","last_trade_price":"0.320"},{"market":"0x8530b96422523df2024c4242021b58da538c5e94ba525e8f9893c3fc2f469160","asset_id":"91811271690939763569588501717168303099799014127066745654294854264052726562982","timestamp":"1779223894555","hash":"3957e3f3abc463933ee87705582f68a44b9660ec","bids":[{"price":"0.01","size":"2098092.38"},{"price":"0.02","size":"8706.42"},{"price":"0.03","size":"1992.84"},{"price":"0.04","size":"2383.26"},{"price":"0.05","size":"505"},{"price":"0.06","size":"1019.64"},{"price":"0.07","size":"1144.58"},{"price":"0.08","size":"7.24"},{"price":"0.09","size":"1406.34"},{"price":"0.1","size":"3769.22"},{"price":"0.11","size":"712"},{"price":"0.12","size":"849.7"},{"price":"0.13","size":"742.95"},{"price":"0.14","size":"163.93"},{"price":"0.15","size":"1748.71"},{"price":"0.16","size":"724.37"},{"price":"0.17","size":"562"},{"price":"0.19","size":"150"},{"price":"0.2","size":"123.78"},{"price":"0.21","size":"1062"},{"price":"0.22","size":"100"},{"price":"0.23","size":"100"},{"price":"0.24","size":"5"},{"price":"0.25","size":"420"},{"price":"0.26","size":"12845.24"},{"price":"0.27","size":"104265.08"},{"price":"0.28","size":"22960.27"},{"price":"0.29","size":"726274.54"},{"price":"0.3","size":"1513157.93"},{"price":"0.31","size":"3286086.85"}],"asks":[{"price":"0.99","size":"2262149.61"},{"price":"0.98","size":"118704.83"},{"price":"0.97","size":"4783.32"},{"price":"0.96","size":"39831.68"},{"price":"0.95","size":"655"},{"price":"0.93","size":"25863.6"},{"price":"0.92","size":"358.32"},{"price":"0.91","size":"2370"},{"price":"0.9","size":"500"},{"price":"0.89","size":"5.32"},{"price":"0.86","size":"5348.18"},{"price":"0.85","size":"807.48"},{"price":"0.84","size":"268.73"},{"price":"0.82","size":"2025"},{"price":"0.81","size":"384"},{"price":"0.8","size":"607"},{"price":"0.79","size":"394.06"},{"price":"0.78","size":"299.07"},{"price":"0.77","size":"86.07"},{"price":"0.76","size":"162.38"},{"price":"0.72","size":"369.43"},{"price":"0.71","size":"165.07"},{"price":"0.7","size":"3024"},{"price":"0.69","size":"383.17"},{"price":"0.68","size":"31.25"},{"price":"0.66","size":"1054.65"},{"price":"0.65","size":"437.12"},{"price":"0.64","size":"76.5"},{"price":"0.62","size":"80.62"},{"price":"0.61","size":"184.88"},{"price":"0.6","size":"36.12"},{"price":"0.55","size":"11205.68"},{"price":"0.54","size":"500"},{"price":"0.51","size":"75"},{"price":"0.5","size":"496.89"},{"price":"0.49","size":"905"},{"price":"0.48","size":"50"},{"price":"0.47","size":"400"},{"price":"0.46","size":"28.19"},{"price":"0.45","size":"50"},{"price":"0.44","size":"10"},{"price":"0.42","size":"300"},{"price":"0.41","size":"100"},{"price":"0.4","size":"400"},{"price":"0.39","size":"300"},{"price":"0.38","size":"1917"},{"price":"0.37","size":"1734"},{"price":"0.36","size":"2132"},{"price":"0.35","size":"113955.21"},{"price":"0.34","size":"128239.41"},{"price":"0.33","size":"1028231.2"},{"price":"0.32","size":"69280.07"}],"tick_size":"0.01","event_type":"book","last_trade_price":"0.680"},{"market":"0x9a0da0f25f94fce088c88803b296d48dd19717370dbafa97484f3ddac70ee4dc","asset_id":"115707715167373261399734260542020796347329928638142033825445370749810433822651","timestamp":"1779223895420","hash":"763a48192e1b67bb49d7552f4f34bf2ff3e30c6c","bids":[{"price":"0.01","size":"2001410"},{"price":"0.02","size":"1750"},{"price":"0.03","size":"400133.32"},{"price":"0.06","size":"1084.6"},{"price":"0.07","size":"1134.41"},{"price":"0.08","size":"1711.95"},{"price":"0.14","size":"798.05"},{"price":"0.15","size":"1369.55"},{"price":"0.16","size":"682"},{"price":"0.18","size":"723.07"},{"price":"0.2","size":"148.09"},{"price":"0.21","size":"437.53"},{"price":"0.22","size":"839.44"},{"price":"0.24","size":"677.88"},{"price":"0.26","size":"36.8"},{"price":"0.27","size":"51.69"},{"price":"0.28","size":"33.82"},{"price":"0.29","size":"589.8"},{"price":"0.3","size":"3258.93"},{"price":"0.32","size":"1035.88"},{"price":"0.33","size":"50.75"},{"price":"0.34","size":"543.67"},{"price":"0.35","size":"100"},{"price":"0.36","size":"769.49"},{"price":"0.4","size":"40"},{"price":"0.42","size":"1100"},{"price":"0.43","size":"500"},{"price":"0.48","size":"16.06"},{"price":"0.5","size":"48.3"},{"price":"0.51","size":"6.89"},{"price":"0.52","size":"19.23"},{"price":"0.53","size":"800"},{"price":"0.55","size":"60"},{"price":"0.56","size":"15.15"},{"price":"0.57","size":"1296"},{"price":"0.58","size":"500"},{"price":"0.59","size":"500"},{"price":"0.6","size":"515.15"},{"price":"0.61","size":"714.99"},{"price":"0.62","size":"403"},{"price":"0.63","size":"8205"},{"price":"0.64","size":"14041.86"},{"price":"0.65","size":"17701.6"},{"price":"0.66","size":"99962.9"},{"price":"0.67","size":"184439.84"}],"asks":[{"price":"0.99","size":"2001209"},{"price":"0.98","size":"4729.47"},{"price":"0.97","size":"400133.32"},{"price":"0.96","size":"3653"},{"price":"0.95","size":"1349.54"},{"price":"0.94","size":"3737.55"},{"price":"0.93","size":"1590.34"},{"price":"0.92","size":"1678.68"},{"price":"0.91","size":"1208.76"},{"price":"0.9","size":"2514"},{"price":"0.89","size":"1349.37"},{"price":"0.88","size":"3668.68"},{"price":"0.87","size":"1038.11"},{"price":"0.86","size":"1526.91"},{"price":"0.84","size":"980.32"},{"price":"0.83","size":"1787.34"},{"price":"0.82","size":"908.76"},{"price":"0.81","size":"732.98"},{"price":"0.8","size":"1302.28"},{"price":"0.79","size":"300"},{"price":"0.78","size":"996"},{"price":"0.77","size":"500"},{"price":"0.76","size":"500"},{"price":"0.75","size":"652"},{"price":"0.74","size":"700"},{"price":"0.73","size":"2958.55"},{"price":"0.72","size":"571.43"},{"price":"0.71","size":"7584.34"},{"price":"0.7","size":"43853.31"},{"price":"0.69","size":"44975.72"},{"price":"0.68","size":"392785.24"}],"tick_size":"0.01","event_type":"book","last_trade_price":"0.320"},{"market":"0x098afead2c41677b0f09ae9d0013ca520eacdb3f0d7c8985c6581de7a0e9ac37","asset_id":"25765184634765339363827807992411986670067641678875992164214223288175352348465","timestamp":"1779223898217","hash":"56d6160e0c3447297ee4bb1ea65a789bd1292bfa","bids":[{"price":"0.01","size":"113788.23"},{"price":"0.02","size":"52275.29"},{"price":"0.03","size":"28358.54"},{"price":"0.04","size":"10358.76"},{"price":"0.05","size":"19353.45"},{"price":"0.06","size":"11459.99"},{"price":"0.07","size":"3617.38"},{"price":"0.08","size":"2500.06"},{"price":"0.09","size":"200.01"},{"price":"0.1","size":"13862.13"},{"price":"0.11","size":"32800"},{"price":"0.12","size":"942.75"},{"price":"0.13","size":"2414.85"},{"price":"0.14","size":"20485.95"},{"price":"0.15","size":"8727.27"},{"price":"0.16","size":"3307.62"},{"price":"0.17","size":"1488.91"}],"asks":[{"price":"0.99","size":"39222.97"},{"price":"0.98","size":"2048"},{"price":"0.97","size":"10.41"},{"price":"0.96","size":"39724"},{"price":"0.95","size":"232.5"},{"price":"0.92","size":"14556"},{"price":"0.91","size":"4833"},{"price":"0.9","size":"2250"},{"price":"0.89","size":"5.34"},{"price":"0.87","size":"9736.53"},{"price":"0.86","size":"2002"},{"price":"0.85","size":"2973.03"},{"price":"0.84","size":"128"},{"price":"0.83","size":"6438.23"},{"price":"0.81","size":"450"},{"price":"0.8","size":"300"},{"price":"0.79","size":"5472.85"},{"price":"0.78","size":"2200"},{"price":"0.77","size":"1652"},{"price":"0.75","size":"3050"},{"price":"0.74","size":"3000"},{"price":"0.71","size":"3201.96"},{"price":"0.69","size":"3936"},{"price":"0.68","size":"2907"},{"price":"0.66","size":"1411.76"},{"price":"0.65","size":"1200"},{"price":"0.6","size":"850"},{"price":"0.5","size":"230.95"},{"price":"0.48","size":"21"},{"price":"0.45","size":"200"},{"price":"0.44","size":"400"},{"price":"0.43","size":"4525.58"},{"price":"0.42","size":"519"},{"price":"0.41","size":"200"},{"price":"0.4","size":"2857.81"},{"price":"0.39","size":"365"},{"price":"0.38","size":"300"},{"price":"0.37","size":"50"},{"price":"0.35","size":"400"},{"price":"0.34","size":"200"},{"price":"0.33","size":"1200"},{"price":"0.31","size":"7.29"},{"price":"0.3","size":"25.25"},{"price":"0.29","size":"179.22"},{"price":"0.28","size":"506.35"},{"price":"0.27","size":"205"},{"price":"0.26","size":"1506.16"},{"price":"0.25","size":"105"},{"price":"0.24","size":"610.66"},{"price":"0.23","size":"467.08"},{"price":"0.22","size":"8244.26"},{"price":"0.21","size":"4790.98"},{"price":"0.2","size":"12499.32"},{"price":"0.19","size":"7129.01"},{"price":"0.18","size":"785.06"}],"tick_size":"0.01","event_type":"book","last_trade_price":"0.830"},{"market":"0x865ac5b1fdc1706ca8cf0f25cc63544b5abcbb6819e25d52d9ac3ee4b3446726","asset_id":"18124776046378286261632296176797913974857552946923528818498431780145315271239","timestamp":"1779223899141","hash":"1dadc3cd528615e38d1bac3c5e4c92942c1e09ae","bids":[{"price":"0.01","size":"191070"},{"price":"0.02","size":"30650"},{"price":"0.03","size":"476882.92"},{"price":"0.04","size":"650"},{"price":"0.05","size":"14470"},{"price":"0.07","size":"550"},{"price":"0.09","size":"2600"},{"price":"0.1","size":"5900"},{"price":"0.11","size":"650"},{"price":"0.16","size":"292"},{"price":"0.2","size":"303.59"},{"price":"0.21","size":"3879.15"},{"price":"0.22","size":"300"},{"price":"0.24","size":"360"},{"price":"0.25","size":"1135.21"},{"price":"0.26","size":"215"},{"price":"0.28","size":"300"},{"price":"0.29","size":"99.99"},{"price":"0.3","size":"305.66"},{"price":"0.31","size":"47.09"},{"price":"0.32","size":"50"},{"price":"0.33","size":"6.06"},{"price":"0.34","size":"300"},{"price":"0.36","size":"2003"},{"price":"0.38","size":"303"},{"price":"0.39","size":"27.17"},{"price":"0.4","size":"196"},{"price":"0.41","size":"1347"},{"price":"0.42","size":"109"},{"price":"0.43","size":"484"},{"price":"0.44","size":"2014.27"},{"price":"0.45","size":"485"},{"price":"0.46","size":"325.35"}],"asks":[{"price":"0.99","size":"196050"},{"price":"0.98","size":"111220"},{"price":"0.97","size":"13800"},{"price":"0.96","size":"650"},{"price":"0.95","size":"650"},{"price":"0.94","size":"22252"},{"price":"0.93","size":"6000"},{"price":"0.92","size":"1700"},{"price":"0.89","size":"3030"},{"price":"0.88","size":"500"},{"price":"0.87","size":"302"},{"price":"0.86","size":"150"},{"price":"0.8","size":"1760"},{"price":"0.78","size":"277.77"},{"price":"0.74","size":"445"},{"price":"0.72","size":"300"},{"price":"0.7","size":"300"},{"price":"0.69","size":"46.52"},{"price":"0.68","size":"360"},{"price":"0.67","size":"2395"},{"price":"0.66","size":"300"},{"price":"0.64","size":"300"},{"price":"0.63","size":"24.32"},{"price":"0.62","size":"300"},{"price":"0.61","size":"30"},{"price":"0.6","size":"305"},{"price":"0.58","size":"341.9"},{"price":"0.57","size":"2000"},{"price":"0.56","size":"300"},{"price":"0.55","size":"65"},{"price":"0.54","size":"144"},{"price":"0.53","size":"164"},{"price":"0.52","size":"938"},{"price":"0.51","size":"22"},{"price":"0.5","size":"106.07"},{"price":"0.49","size":"326.81"},{"price":"0.48","size":"1385"}],"tick_size":"0.01","event_type":"book","last_trade_price":"0.530"},{"market":"0x0e4a0c937b8934c2475613b6322b3f8edc8dedc24762e01e42b0e6f87424a089","asset_id":"42918220085288219341491829385501246298233444593663440094436147850542032590016","timestamp":"1779223898172","hash":"b803e0ed27a9d792ac33d70e3666055ebee06bd6","bids":[{"price":"0.01","size":"39100.91"},{"price":"0.02","size":"12927.6"},{"price":"0.03","size":"7346.44"},{"price":"0.04","size":"1055.52"},{"price":"0.05","size":"60247"},{"price":"0.07","size":"64999.99"},{"price":"0.08","size":"268.5"},{"price":"0.09","size":"10133.33"},{"price":"0.1","size":"5900.7"},{"price":"0.11","size":"4705.4"},{"price":"0.12","size":"2282.33"},{"price":"0.13","size":"2323.46"},{"price":"0.14","size":"10603.37"},{"price":"0.15","size":"222"},{"price":"0.16","size":"34841.5"},{"price":"0.17","size":"2288.34"},{"price":"0.18","size":"7082.33"},{"price":"0.19","size":"547.36"},{"price":"0.2","size":"3045.11"},{"price":"0.21","size":"17830"},{"price":"0.22","size":"473.36"},{"price":"0.23","size":"5099.91"},{"price":"0.24","size":"283"},{"price":"0.25","size":"400"},{"price":"0.26","size":"64"},{"price":"0.27","size":"4168.18"},{"price":"0.28","size":"208"},{"price":"0.3","size":"1787.41"},{"price":"0.32","size":"3700"},{"price":"0.33","size":"549"},{"price":"0.34","size":"20"},{"price":"0.36","size":"1365.33"},{"price":"0.38","size":"1111"},{"price":"0.4","size":"2681.31"},{"price":"0.41","size":"108"},{"price":"0.42","size":"1428"},{"price":"0.45","size":"586.95"},{"price":"0.47","size":"200"},{"price":"0.48","size":"25"},{"price":"0.5","size":"10369.25"},{"price":"0.52","size":"3343"},{"price":"0.53","size":"1110.58"},{"price":"0.54","size":"13.47"},{"price":"0.55","size":"282.66"},{"price":"0.56","size":"4449"},{"price":"0.57","size":"510"},{"price":"0.58","size":"8.28"},{"price":"0.59","size":"30"},{"price":"0.6","size":"558.62"},{"price":"0.61","size":"220"},{"price":"0.62","size":"360"},{"price":"0.63","size":"115.18"},{"price":"0.64","size":"409.52"},{"price":"0.65","size":"487.17"},{"price":"0.66","size":"25296.18"},{"price":"0.67","size":"540.18"},{"price":"0.68","size":"165.18"},{"price":"0.69","size":"4719.18"},{"price":"0.7","size":"10232.29"},{"price":"0.71","size":"501.32"},{"price":"0.72","size":"26506.15"},{"price":"0.73","size":"757.9"},{"price":"0.74","size":"6203.2"},{"price":"0.75","size":"29517.55"},{"price":"0.76","size":"3514.6"},{"price":"0.77","size":"26613.61"},{"price":"0.78","size":"25755.18"},{"price":"0.79","size":"5345.18"},{"price":"0.8","size":"12749.84"},{"price":"0.81","size":"2513.91"},{"price":"0.82","size":"3730.83"},{"price":"0.83","size":"46540.16"},{"price":"0.84","size":"23384.56"},{"price":"0.85","size":"14289.8"},{"price":"0.86","size":"16643.64"},{"price":"0.87","size":"7174.2"},{"price":"0.88","size":"17389.87"},{"price":"0.89","size":"63508.87"},{"price":"0.9","size":"24537.31"}],"asks":[{"price":"0.99","size":"2167537.32"},{"price":"0.98","size":"174837.43"},{"price":"0.97","size":"423571.22"},{"price":"0.96","size":"131645.91"},{"price":"0.95","size":"50992.48"},{"price":"0.94","size":"69038.91"},{"price":"0.93","size":"120756"},{"price":"0.92","size":"254773.38"},{"price":"0.91","size":"82636.6"}],"tick_size":"0.01","event_type":"book","last_trade_price":"0.100"},{"market":"0x098afead2c41677b0f09ae9d0013ca520eacdb3f0d7c8985c6581de7a0e9ac37","asset_id":"112135611227049632102833296892649508522129989874688677403193353750752980311218","timestamp":"1779223898217","hash":"6e36bbee057086bb2b8f268eea962747619cb36d","bids":[{"price":"0.01","size":"39222.97"},{"price":"0.02","size":"2048"},{"price":"0.03","size":"10.41"},{"price":"0.04","size":"39724"},{"price":"0.05","size":"232.5"},{"price":"0.08","size":"14556"},{"price":"0.09","size":"4833"},{"price":"0.1","size":"2250"},{"price":"0.11","size":"5.34"},{"price":"0.13","size":"9736.53"},{"price":"0.14","size":"2002"},{"price":"0.15","size":"2973.03"},{"price":"0.16","size":"128"},{"price":"0.17","size":"6438.23"},{"price":"0.19","size":"450"},{"price":"0.2","size":"300"},{"price":"0.21","size":"5472.85"},{"price":"0.22","size":"2200"},{"price":"0.23","size":"1652"},{"price":"0.25","size":"3050"},{"price":"0.26","size":"3000"},{"price":"0.29","size":"3201.96"},{"price":"0.31","size":"3936"},{"price":"0.32","size":"2907"},{"price":"0.34","size":"1411.76"},{"price":"0.35","size":"1200"},{"price":"0.4","size":"850"},{"price":"0.5","size":"230.95"},{"price":"0.52","size":"21"},{"price":"0.55","size":"200"},{"price":"0.56","size":"400"},{"price":"0.57","size":"4525.58"},{"price":"0.58","size":"519"},{"price":"0.59","size":"200"},{"price":"0.6","size":"2857.81"},{"price":"0.61","size":"365"},{"price":"0.62","size":"300"},{"price":"0.63","size":"50"},{"price":"0.65","size":"400"},{"price":"0.66","size":"200"},{"price":"0.67","size":"1200"},{"price":"0.69","size":"7.29"},{"price":"0.7","size":"25.25"},{"price":"0.71","size":"179.22"},{"price":"0.72","size":"506.35"},{"price":"0.73","size":"205"},{"price":"0.74","size":"1506.16"},{"price":"0.75","size":"105"},{"price":"0.76","size":"610.66"},{"price":"0.77","size":"467.08"},{"price":"0.78","size":"8244.26"},{"price":"0.79","size":"4790.98"},{"price":"0.8","size":"12499.32"},{"price":"0.81","size":"7129.01"},{"price":"0.82","size":"785.06"}],"asks":[{"price":"0.99","size":"113788.23"},{"price":"0.98","size":"52275.29"},{"price":"0.97","size":"28358.54"},{"price":"0.96","size":"10358.76"},{"price":"0.95","size":"19353.45"},{"price":"0.94","size":"11459.99"},{"price":"0.93","size":"3617.38"},{"price":"0.92","size":"2500.06"},{"price":"0.91","size":"200.01"},{"price":"0.9","size":"13862.13"},{"price":"0.89","size":"32800"},{"price":"0.88","size":"942.75"},{"price":"0.87","size":"2414.85"},{"price":"0.86","size":"20485.95"},{"price":"0.85","size":"8727.27"},{"price":"0.84","size":"3307.62"},{"price":"0.83","size":"1488.91"}],"tick_size":"0.01","event_type":"book","last_trade_price":"0.830"},{"market":"0x053f95738ace6c99e1571e0461feed7392fb646efa0d37ec775237e14152ecc6","asset_id":"99569156108398980363100881959946272812368919094152389618505020290436760462827","timestamp":"1779223862955","hash":"3658eef097a5596070ae2e89f56ded6ef5010cd0","bids":[{"price":"0.001","size":"99999"},{"price":"0.002","size":"5000"},{"price":"0.006","size":"25000"},{"price":"0.01","size":"12043.49"},{"price":"0.012","size":"15000"},{"price":"0.013","size":"55555"},{"price":"0.02","size":"25000"},{"price":"0.021","size":"1000"},{"price":"0.03","size":"5300"},{"price":"0.04","size":"5233.12"},{"price":"0.05","size":"5000"},{"price":"0.051","size":"5000"},{"price":"0.06","size":"4000"},{"price":"0.061","size":"33333"},{"price":"0.09","size":"3500"},{"price":"0.1","size":"5"},{"price":"0.106","size":"200"},{"price":"0.108","size":"6000"},{"price":"0.11","size":"3000"},{"price":"0.111","size":"5000"},{"price":"0.12","size":"3100"},{"price":"0.121","size":"10000"},{"price":"0.13","size":"2500"},{"price":"0.14","size":"2000"},{"price":"0.15","size":"260.83"},{"price":"0.151","size":"1500"},{"price":"0.16","size":"1500"},{"price":"0.19","size":"1000"},{"price":"0.22","size":"100"},{"price":"0.221","size":"100"},{"price":"0.23","size":"600"},{"price":"0.231","size":"3011"},{"price":"0.232","size":"8000"},{"price":"0.27","size":"1000"},{"price":"0.32","size":"900"},{"price":"0.4","size":"10"},{"price":"0.42","size":"5"},{"price":"0.43","size":"5"},{"price":"0.48","size":"835"},{"price":"0.49","size":"3711"},{"price":"0.499","size":"100"},{"price":"0.5","size":"5"},{"price":"0.501","size":"500"},{"price":"0.502","size":"1500"},{"price":"0.51","size":"414.26"},{"price":"0.57","size":"700"},{"price":"0.65","size":"100"},{"price":"0.68","size":"600"},{"price":"0.7","size":"540.71"},{"price":"0.74","size":"6.66"},{"price":"0.75","size":"947.39"},{"price":"0.767","size":"60"},{"price":"0.768","size":"777"},{"price":"0.769","size":"60"},{"price":"0.77","size":"60"},{"price":"0.79","size":"115.68"},{"price":"0.8","size":"3741"},{"price":"0.82","size":"400"},{"price":"0.913","size":"10"},{"price":"0.92","size":"5"},{"price":"0.94","size":"309"},{"price":"0.95","size":"625"},{"price":"0.99","size":"22304.55"},{"price":"0.991","size":"2447.2"},{"price":"0.992","size":"217.25"},{"price":"0.993","size":"10"},{"price":"0.994","size":"10"},{"price":"0.995","size":"10"},{"price":"0.998","size":"6"},{"price":"0.999","size":"1601832.7"}],"asks":[],"tick_size":"0.001","event_type":"book","last_trade_price":"0.999"},{"market":"0xa0f4c4924ea1a8b410b4ce821c2a9955fad21a1b19bdcfde90816732278b3dd5","asset_id":"13290642914521189871602119663452054126359842904805799115978921503195267156991","timestamp":"1779223838867","hash":"df3cd432379cc6ea426b8331536da63cf058259f","bids":[{"price":"0.001","size":"3140044.61"},{"price":"0.002","size":"200000"},{"price":"0.003","size":"90000"},{"price":"0.01","size":"1055"},{"price":"0.05","size":"20"},{"price":"0.055","size":"1000"},{"price":"0.08","size":"5"},{"price":"0.1","size":"1835"},{"price":"0.2","size":"66380"},{"price":"0.201","size":"12000"},{"price":"0.21","size":"952"},{"price":"0.38","size":"115.89"},{"price":"0.4","size":"30468.75"},{"price":"0.401","size":"5000"},{"price":"0.41","size":"195"},{"price":"0.48","size":"200"},{"price":"0.481","size":"1246"},{"price":"0.5","size":"21617.13"},{"price":"0.501","size":"10097"},{"price":"0.55","size":"51"},{"price":"0.6","size":"15625"},{"price":"0.601","size":"6200"},{"price":"0.602","size":"5.48"},{"price":"0.665","size":"5.48"},{"price":"0.666","size":"1103.99"},{"price":"0.729","size":"5.49"},{"price":"0.791","size":"100"},{"price":"0.793","size":"5.49"},{"price":"0.84","size":"1750"},{"price":"0.857","size":"5.49"},{"price":"0.883","size":"100"},{"price":"0.89","size":"268.53"},{"price":"0.9","size":"1163.23"},{"price":"0.91","size":"1834.67"},{"price":"0.916","size":"100"},{"price":"0.921","size":"5.49"},{"price":"0.924","size":"107"},{"price":"0.95","size":"3354.6"},{"price":"0.953","size":"3000"},{"price":"0.958","size":"200"},{"price":"0.96","size":"895.53"},{"price":"0.967","size":"75"},{"price":"0.971","size":"1500"},{"price":"0.972","size":"27"},{"price":"0.977","size":"1000"},{"price":"0.98","size":"1320.02"},{"price":"0.984","size":"200"},{"price":"0.985","size":"5510"},{"price":"0.986","size":"1768.66"},{"price":"0.987","size":"105"},{"price":"0.988","size":"99"},{"price":"0.989","size":"905.44"},{"price":"0.99","size":"8692.09"},{"price":"0.991","size":"4071.45"}],"asks":[{"price":"0.999","size":"1237029"},{"price":"0.998","size":"532182"},{"price":"0.997","size":"134357.59"},{"price":"0.996","size":"16095.14"},{"price":"0.995","size":"11530.91"},{"price":"0.994","size":"13331.3"},{"price":"0.993","size":"26847.07"},{"price":"0.992","size":"1042.73"}],"tick_size":"0.001","event_type":"book","last_trade_price":"0.009"},{"market":"0x0e4a0c937b8934c2475613b6322b3f8edc8dedc24762e01e42b0e6f87424a089","asset_id":"72094069823942324362885404801938332659316240217382754851102758232469673300092","timestamp":"1779223898172","hash":"649cb3797e8d63ca0b75267487f3c8a13907a651","bids":[{"price":"0.01","size":"2167537.32"},{"price":"0.02","size":"174837.43"},{"price":"0.03","size":"423571.22"},{"price":"0.04","size":"131645.91"},{"price":"0.05","size":"50992.48"},{"price":"0.06","size":"69038.91"},{"price":"0.07","size":"120756"},{"price":"0.08","size":"254773.38"},{"price":"0.09","size":"82636.6"}],"asks":[{"price":"0.99","size":"39100.91"},{"price":"0.98","size":"12927.6"},{"price":"0.97","size":"7346.44"},{"price":"0.96","size":"1055.52"},{"price":"0.95","size":"60247"},{"price":"0.93","size":"64999.99"},{"price":"0.92","size":"268.5"},{"price":"0.91","size":"10133.33"},{"price":"0.9","size":"5900.7"},{"price":"0.89","size":"4705.4"},{"price":"0.88","size":"2282.33"},{"price":"0.87","size":"2323.46"},{"price":"0.86","size":"10603.37"},{"price":"0.85","size":"222"},{"price":"0.84","size":"34841.5"},{"price":"0.83","size":"2288.34"},{"price":"0.82","size":"7082.33"},{"price":"0.81","size":"547.36"},{"price":"0.8","size":"3045.11"},{"price":"0.79","size":"17830"},{"price":"0.78","size":"473.36"},{"price":"0.77","size":"5099.91"},{"price":"0.76","size":"283"},{"price":"0.75","size":"400"},{"price":"0.74","size":"64"},{"price":"0.73","size":"4168.18"},{"price":"0.72","size":"208"},{"price":"0.7","size":"1787.41"},{"price":"0.68","size":"3700"},{"price":"0.67","size":"549"},{"price":"0.66","size":"20"},{"price":"0.64","size":"1365.33"},{"price":"0.62","size":"1111"},{"price":"0.6","size":"2681.31"},{"price":"0.59","size":"108"},{"price":"0.58","size":"1428"},{"price":"0.55","size":"586.95"},{"price":"0.53","size":"200"},{"price":"0.52","size":"25"},{"price":"0.5","size":"10369.25"},{"price":"0.48","size":"3343"},{"price":"0.47","size":"1110.58"},{"price":"0.46","size":"13.47"},{"price":"0.45","size":"282.66"},{"price":"0.44","size":"4449"},{"price":"0.43","size":"510"},{"price":"0.42","size":"8.28"},{"price":"0.41","size":"30"},{"price":"0.4","size":"558.62"},{"price":"0.39","size":"220"},{"price":"0.38","size":"360"},{"price":"0.37","size":"115.18"},{"price":"0.36","size":"409.52"},{"price":"0.35","size":"487.17"},{"price":"0.34","size":"25296.18"},{"price":"0.33","size":"540.18"},{"price":"0.32","size":"165.18"},{"price":"0.31","size":"4719.18"},{"price":"0.3","size":"10232.29"},{"price":"0.29","size":"501.32"},{"price":"0.28","size":"26506.15"},{"price":"0.27","size":"757.9"},{"price":"0.26","size":"6203.2"},{"price":"0.25","size":"29517.55"},{"price":"0.24","size":"3514.6"},{"price":"0.23","size":"26613.61"},{"price":"0.22","size":"25755.18"},{"price":"0.21","size":"5345.18"},{"price":"0.2","size":"12749.84"},{"price":"0.19","size":"2513.91"},{"price":"0.18","size":"3730.83"},{"price":"0.17","size":"46540.16"},{"price":"0.16","size":"23384.56"},{"price":"0.15","size":"14289.8"},{"price":"0.14","size":"16643.64"},{"price":"0.13","size":"7174.2"},{"price":"0.12","size":"17389.87"},{"price":"0.11","size":"63508.87"},{"price":"0.1","size":"24537.31"}],"tick_size":"0.01","event_type":"book","last_trade_price":"0.100"},{"market":"0xb99047b9bdf8132c367cf327936676a1186a6eb57b86a742fdfe812f86b2e3b9","asset_id":"101407360275578242025559123794924815546227269981219987932032932255334246314286","timestamp":"1779223899106","hash":"b894dad6128a4ba666edf58ed2ef9160ecfc34e3","bids":[{"price":"0.01","size":"297933.95"},{"price":"0.02","size":"162709.35"},{"price":"0.03","size":"7500"},{"price":"0.04","size":"500"},{"price":"0.05","size":"10910"},{"price":"0.06","size":"29932"},{"price":"0.07","size":"78051.24"},{"price":"0.08","size":"51937.23"},{"price":"0.09","size":"3711"},{"price":"0.12","size":"12529.15"},{"price":"0.13","size":"5952"},{"price":"0.14","size":"8289.15"},{"price":"0.19","size":"1760"},{"price":"0.25","size":"40"},{"price":"0.31","size":"26"},{"price":"0.4","size":"20"},{"price":"0.41","size":"11.78"},{"price":"0.46","size":"35"},{"price":"0.48","size":"525"},{"price":"0.5","size":"505"},{"price":"0.51","size":"50"},{"price":"0.52","size":"535"},{"price":"0.54","size":"515"},{"price":"0.55","size":"9.09"},{"price":"0.56","size":"505"},{"price":"0.57","size":"266.03"},{"price":"0.58","size":"580"},{"price":"0.6","size":"540"},{"price":"0.62","size":"500"},{"price":"0.63","size":"40"},{"price":"0.64","size":"560"},{"price":"0.66","size":"530"},{"price":"0.68","size":"21.27"},{"price":"0.69","size":"285"},{"price":"0.7","size":"883.56"},{"price":"0.71","size":"11.17"},{"price":"0.72","size":"19.22"},{"price":"0.73","size":"10.85"},{"price":"0.74","size":"28.75"},{"price":"0.75","size":"814"},{"price":"0.76","size":"15450.06"},{"price":"0.77","size":"1736.17"},{"price":"0.78","size":"6064.17"},{"price":"0.79","size":"30981.55"},{"price":"0.8","size":"10538.17"}],"asks":[{"price":"0.99","size":"28603.48"},{"price":"0.98","size":"7.91"},{"price":"0.97","size":"1157.97"},{"price":"0.96","size":"1825"},{"price":"0.95","size":"5.54"},{"price":"0.94","size":"21.86"},{"price":"0.93","size":"5.4"},{"price":"0.92","size":"40"},{"price":"0.91","size":"829.14"},{"price":"0.9","size":"8.21"},{"price":"0.89","size":"38.86"},{"price":"0.88","size":"45.25"},{"price":"0.87","size":"119"},{"price":"0.86","size":"740"},{"price":"0.85","size":"17805.94"},{"price":"0.84","size":"3616.39"},{"price":"0.83","size":"2407"},{"price":"0.82","size":"6196"},{"price":"0.81","size":"34.91"}],"tick_size":"0.01","event_type":"book","last_trade_price":"0.810"},{"market":"0x053f95738ace6c99e1571e0461feed7392fb646efa0d37ec775237e14152ecc6","asset_id":"8199493545872276685007649098855627956832512958032108818142031783023965647133","timestamp":"1779223862955","hash":"b2be1adb41abaa28dee1b484baa23f76b49ef470","bids":[],"asks":[{"price":"0.999","size":"99999"},{"price":"0.998","size":"5000"},{"price":"0.994","size":"25000"},{"price":"0.99","size":"12043.49"},{"price":"0.988","size":"15000"},{"price":"0.987","size":"55555"},{"price":"0.98","size":"25000"},{"price":"0.979","size":"1000"},{"price":"0.97","size":"5300"},{"price":"0.96","size":"5233.12"},{"price":"0.95","size":"5000"},{"price":"0.949","size":"5000"},{"price":"0.94","size":"4000"},{"price":"0.939","size":"33333"},{"price":"0.91","size":"3500"},{"price":"0.9","size":"5"},{"price":"0.894","size":"200"},{"price":"0.892","size":"6000"},{"price":"0.89","size":"3000"},{"price":"0.889","size":"5000"},{"price":"0.88","size":"3100"},{"price":"0.879","size":"10000"},{"price":"0.87","size":"2500"},{"price":"0.86","size":"2000"},{"price":"0.85","size":"260.83"},{"price":"0.849","size":"1500"},{"price":"0.84","size":"1500"},{"price":"0.81","size":"1000"},{"price":"0.78","size":"100"},{"price":"0.779","size":"100"},{"price":"0.77","size":"600"},{"price":"0.769","size":"3011"},{"price":"0.768","size":"8000"},{"price":"0.73","size":"1000"},{"price":"0.68","size":"900"},{"price":"0.6","size":"10"},{"price":"0.58","size":"5"},{"price":"0.57","size":"5"},{"price":"0.52","size":"835"},{"price":"0.51","size":"3711"},{"price":"0.501","size":"100"},{"price":"0.5","size":"5"},{"price":"0.499","size":"500"},{"price":"0.498","size":"1500"},{"price":"0.49","size":"414.26"},{"price":"0.43","size":"700"},{"price":"0.35","size":"100"},{"price":"0.32","size":"600"},{"price":"0.3","size":"540.71"},{"price":"0.26","size":"6.66"},{"price":"0.25","size":"947.39"},{"price":"0.233","size":"60"},{"price":"0.232","size":"777"},{"price":"0.231","size":"60"},{"price":"0.23","size":"60"},{"price":"0.21","size":"115.68"},{"price":"0.2","size":"3741"},{"price":"0.18","size":"400"},{"price":"0.087","size":"10"},{"price":"0.08","size":"5"},{"price":"0.06","size":"309"},{"price":"0.05","size":"625"},{"price":"0.01","size":"22304.55"},{"price":"0.009","size":"2447.2"},{"price":"0.008","size":"217.25"},{"price":"0.007","size":"10"},{"price":"0.006","size":"10"},{"price":"0.005","size":"10"},{"price":"0.002","size":"6"},{"price":"0.001","size":"1601832.7"}],"tick_size":"0.001","event_type":"book","last_trade_price":"0.999"},{"market":"0xaa145cf5714455f546afe53037b8712df749ba96c04820c2d41f37f877f29697","asset_id":"3186812161617275136941873065600103851370007880588093249814268822949706568368","timestamp":"1779223820968","hash":"dbf6895a263c9ea6fd643f0c40f2eaa3be3c9e6a","bids":[{"price":"0.001","size":"2101745.21"},{"price":"0.002","size":"1705957.87"},{"price":"0.003","size":"478684.94"},{"price":"0.004","size":"89355.97"},{"price":"0.005","size":"126301.07"},{"price":"0.006","size":"72260"},{"price":"0.007","size":"55076.02"},{"price":"0.008","size":"62180"},{"price":"0.009","size":"79645.67"},{"price":"0.01","size":"162123.15"},{"price":"0.011","size":"13868.74"}],"asks":[{"price":"0.999","size":"106142.87"},{"price":"0.998","size":"15621.03"},{"price":"0.997","size":"6000"},{"price":"0.996","size":"2500"},{"price":"0.995","size":"1000"},{"price":"0.993","size":"1765.63"},{"price":"0.99","size":"131795.39"},{"price":"0.989","size":"5000"},{"price":"0.98","size":"28642.74"},{"price":"0.979","size":"2513.88"},{"price":"0.978","size":"5000"},{"price":"0.977","size":"500"},{"price":"0.975","size":"30561.75"},{"price":"0.97","size":"30025.9"},{"price":"0.96","size":"65080.66"},{"price":"0.95","size":"7370"},{"price":"0.947","size":"500"},{"price":"0.925","size":"4065.33"},{"price":"0.9","size":"21764.74"},{"price":"0.899","size":"3739.67"},{"price":"0.87","size":"100"},{"price":"0.85","size":"15205.95"},{"price":"0.849","size":"6082.38"},{"price":"0.82","size":"200"},{"price":"0.8","size":"950"},{"price":"0.713","size":"129.99"},{"price":"0.7","size":"934.1"},{"price":"0.65","size":"1691.83"},{"price":"0.649","size":"2500"},{"price":"0.6","size":"200"},{"price":"0.52","size":"12097.73"},{"price":"0.519","size":"311"},{"price":"0.499","size":"300"},{"price":"0.49","size":"1254.57"},{"price":"0.4","size":"63.99"},{"price":"0.399","size":"25"},{"price":"0.3","size":"200"},{"price":"0.222","size":"10000"},{"price":"0.2","size":"12.5"},{"price":"0.14","size":"484.88"},{"price":"0.132","size":"454.33"},{"price":"0.127","size":"100"},{"price":"0.126","size":"413.15"},{"price":"0.119","size":"385.56"},{"price":"0.111","size":"351.67"},{"price":"0.11","size":"7746.79"},{"price":"0.106","size":"50"},{"price":"0.103","size":"317.55"},{"price":"0.099","size":"3333"},{"price":"0.095","size":"1050"},{"price":"0.094","size":"295.71"},{"price":"0.086","size":"256.69"},{"price":"0.085","size":"50"},{"price":"0.08","size":"61"},{"price":"0.077","size":"210.6"},{"price":"0.072","size":"2500"},{"price":"0.071","size":"3000"},{"price":"0.07","size":"100"},{"price":"0.066","size":"175"},{"price":"0.065","size":"1206.23"},{"price":"0.064","size":"11172"},{"price":"0.062","size":"3400"},{"price":"0.061","size":"2500"},{"price":"0.06","size":"22322"},{"price":"0.05","size":"16311"},{"price":"0.048","size":"3000"},{"price":"0.045","size":"10"},{"price":"0.044","size":"2505"},{"price":"0.043","size":"2850"},{"price":"0.042","size":"1400"},{"price":"0.041","size":"2400"},{"price":"0.04","size":"910"},{"price":"0.039","size":"6200"},{"price":"0.038","size":"800"},{"price":"0.037","size":"200"},{"price":"0.036","size":"14600"},{"price":"0.035","size":"14510"},{"price":"0.034","size":"11200"},{"price":"0.033","size":"10722"},{"price":"0.032","size":"8333"},{"price":"0.031","size":"16388"},{"price":"0.03","size":"47100"},{"price":"0.029","size":"6510"},{"price":"0.028","size":"6009.99"},{"price":"0.027","size":"15583.58"},{"price":"0.026","size":"32010"},{"price":"0.025","size":"46353"},{"price":"0.024","size":"44822.1"},{"price":"0.023","size":"15000"},{"price":"0.022","size":"28454.71"},{"price":"0.021","size":"45907"},{"price":"0.02","size":"70719"},{"price":"0.019","size":"33400"},{"price":"0.018","size":"26322"},{"price":"0.017","size":"48033.02"},{"price":"0.016","size":"23477.13"},{"price":"0.015","size":"63206.8"},{"price":"0.014","size":"36936.46"},{"price":"0.013","size":"19881.09"},{"price":"0.012","size":"37421.69"}],"tick_size":"0.001","event_type":"book","last_trade_price":"0.989"},{"market":"0xbb4f0756c168d3cf10572e400ad21ae19d944330b38deb376eb0ab0b03bd9541","asset_id":"45063534477558296611827480043433033833511421473669672573422588341426436005863","timestamp":"1779223896424","hash":"3d0c6fb17c9ec4c9f63812a2d5b6711a796ec8db","bids":[],"asks":[{"price":"0.999","size":"100099"},{"price":"0.998","size":"5000"},{"price":"0.994","size":"25000"},{"price":"0.99","size":"7169.98"},{"price":"0.988","size":"15000"},{"price":"0.987","size":"55555"},{"price":"0.98","size":"20000"},{"price":"0.979","size":"1000"},{"price":"0.97","size":"396.07"},{"price":"0.96","size":"200"},{"price":"0.949","size":"5000"},{"price":"0.948","size":"33333"},{"price":"0.894","size":"200"},{"price":"0.892","size":"6000"},{"price":"0.889","size":"5000"},{"price":"0.88","size":"3100"},{"price":"0.879","size":"10000"},{"price":"0.849","size":"1500"},{"price":"0.82","size":"64"},{"price":"0.81","size":"3711"},{"price":"0.78","size":"100"},{"price":"0.779","size":"100"},{"price":"0.77","size":"600"},{"price":"0.769","size":"3486"},{"price":"0.768","size":"8000"},{"price":"0.58","size":"63"},{"price":"0.52","size":"30"},{"price":"0.501","size":"100"},{"price":"0.5","size":"5"},{"price":"0.499","size":"500"},{"price":"0.498","size":"1500"},{"price":"0.49","size":"454.75"},{"price":"0.25","size":"60"},{"price":"0.233","size":"60"},{"price":"0.232","size":"400"},{"price":"0.231","size":"60"},{"price":"0.23","size":"60"},{"price":"0.22","size":"3711"},{"price":"0.2","size":"30"},{"price":"0.12","size":"113.62"},{"price":"0.08","size":"5"},{"price":"0.05","size":"109"},{"price":"0.01","size":"43659.72"},{"price":"0.009","size":"1277"},{"price":"0.008","size":"10"},{"price":"0.007","size":"10"},{"price":"0.006","size":"10"},{"price":"0.005","size":"10"},{"price":"0.003","size":"6.83"},{"price":"0.001","size":"675905.49"}],"tick_size":"0.001","event_type":"book","last_trade_price":"0.999"},{"market":"0xa0f4c4924ea1a8b410b4ce821c2a9955fad21a1b19bdcfde90816732278b3dd5","asset_id":"13915689317269078219168496739008737517740566192006337297676041270492637394586","timestamp":"1779223838867","hash":"6f8d0201714203adc536d2d9201f7d217a11c7e6","bids":[{"price":"0.001","size":"1237029"},{"price":"0.002","size":"532182"},{"price":"0.003","size":"134357.59"},{"price":"0.004","size":"16095.14"},{"price":"0.005","size":"11530.91"},{"price":"0.006","size":"13331.3"},{"price":"0.007","size":"26847.07"},{"price":"0.008","size":"1042.73"}],"asks":[{"price":"0.999","size":"3140044.61"},{"price":"0.998","size":"200000"},{"price":"0.997","size":"90000"},{"price":"0.99","size":"1055"},{"price":"0.95","size":"20"},{"price":"0.945","size":"1000"},{"price":"0.92","size":"5"},{"price":"0.9","size":"1835"},{"price":"0.8","size":"66380"},{"price":"0.799","size":"12000"},{"price":"0.79","size":"952"},{"price":"0.62","size":"115.89"},{"price":"0.6","size":"30468.75"},{"price":"0.599","size":"5000"},{"price":"0.59","size":"195"},{"price":"0.52","size":"200"},{"price":"0.519","size":"1246"},{"price":"0.5","size":"21617.13"},{"price":"0.499","size":"10097"},{"price":"0.45","size":"51"},{"price":"0.4","size":"15625"},{"price":"0.399","size":"6200"},{"price":"0.398","size":"5.48"},{"price":"0.335","size":"5.48"},{"price":"0.334","size":"1103.99"},{"price":"0.271","size":"5.49"},{"price":"0.209","size":"100"},{"price":"0.207","size":"5.49"},{"price":"0.16","size":"1750"},{"price":"0.143","size":"5.49"},{"price":"0.117","size":"100"},{"price":"0.11","size":"268.53"},{"price":"0.1","size":"1163.23"},{"price":"0.09","size":"1834.67"},{"price":"0.084","size":"100"},{"price":"0.079","size":"5.49"},{"price":"0.076","size":"107"},{"price":"0.05","size":"3354.6"},{"price":"0.047","size":"3000"},{"price":"0.042","size":"200"},{"price":"0.04","size":"895.53"},{"price":"0.033","size":"75"},{"price":"0.029","size":"1500"},{"price":"0.028","size":"27"},{"price":"0.023","size":"1000"},{"price":"0.02","size":"1320.02"},{"price":"0.016","size":"200"},{"price":"0.015","size":"5510"},{"price":"0.014","size":"1768.66"},{"price":"0.013","size":"105"},{"price":"0.012","size":"99"},{"price":"0.011","size":"905.44"},{"price":"0.01","size":"8692.09"},{"price":"0.009","size":"4071.45"}],"tick_size":"0.001","event_type":"book","last_trade_price":"0.009"},{"market":"0x789c947a9415600d30d56a4aae88d4111996679b0caed166d0c96242fdce92a2","asset_id":"57360053771630303266236723124451177814047338705194149193939656360140487569996","timestamp":"1779223890459","hash":"fbdf805823f45d2d4e78b93b1b2bf83de1bda419","bids":[{"price":"0.001","size":"1143673.7"},{"price":"0.002","size":"303119.26"},{"price":"0.003","size":"143440.59"},{"price":"0.004","size":"117486.95"},{"price":"0.005","size":"250508.62"},{"price":"0.006","size":"107014.32"},{"price":"0.007","size":"61036.54"},{"price":"0.008","size":"70715.1"},{"price":"0.009","size":"45374.22"},{"price":"0.01","size":"455.99"}],"asks":[{"price":"0.999","size":"408349"},{"price":"0.998","size":"65536"},{"price":"0.997","size":"10000"},{"price":"0.996","size":"32768"},{"price":"0.995","size":"30000"},{"price":"0.992","size":"241192"},{"price":"0.991","size":"120000"},{"price":"0.99","size":"181.42"},{"price":"0.989","size":"10000"},{"price":"0.984","size":"4096"},{"price":"0.983","size":"109800"},{"price":"0.98","size":"10075"},{"price":"0.968","size":"2048"},{"price":"0.95","size":"107044.4"},{"price":"0.949","size":"10000"},{"price":"0.936","size":"1024"},{"price":"0.93","size":"55200.67"},{"price":"0.92","size":"2391.43"},{"price":"0.9","size":"12125"},{"price":"0.89","size":"2698"},{"price":"0.88","size":"140.62"},{"price":"0.872","size":"256"},{"price":"0.87","size":"625"},{"price":"0.82","size":"46.87"},{"price":"0.8","size":"70787.5"},{"price":"0.799","size":"500"},{"price":"0.792","size":"499.99"},{"price":"0.79","size":"921"},{"price":"0.78","size":"62.5"},{"price":"0.753","size":"121.45"},{"price":"0.75","size":"650"},{"price":"0.744","size":"128"},{"price":"0.707","size":"518.77"},{"price":"0.7","size":"33982"},{"price":"0.699","size":"500"},{"price":"0.69","size":"373"},{"price":"0.643","size":"425.77"},{"price":"0.6","size":"23725"},{"price":"0.599","size":"20000"},{"price":"0.598","size":"1000"},{"price":"0.564","size":"275.22"},{"price":"0.55","size":"75806.63"},{"price":"0.549","size":"500"},{"price":"0.548","size":"502.3"},{"price":"0.54","size":"1519"},{"price":"0.539","size":"1300"},{"price":"0.5","size":"14787.03"},{"price":"0.49","size":"15475.64"},{"price":"0.488","size":"64"},{"price":"0.4","size":"27722.04"},{"price":"0.399","size":"2000"},{"price":"0.37","size":"8595"},{"price":"0.32","size":"171.43"},{"price":"0.31","size":"168"},{"price":"0.3","size":"9537.29"},{"price":"0.299","size":"1099.34"},{"price":"0.25","size":"150"},{"price":"0.24","size":"100"},{"price":"0.2","size":"7825.47"},{"price":"0.199","size":"11220"},{"price":"0.18","size":"385.13"},{"price":"0.16","size":"800"},{"price":"0.15","size":"5000"},{"price":"0.136","size":"30"},{"price":"0.12","size":"123036.39"},{"price":"0.119","size":"22493.21"},{"price":"0.101","size":"20000"},{"price":"0.1","size":"10338.72"},{"price":"0.094","size":"13000"},{"price":"0.092","size":"10000"},{"price":"0.09","size":"1700"},{"price":"0.084","size":"10000"},{"price":"0.08","size":"7297.85"},{"price":"0.079","size":"10000"},{"price":"0.074","size":"47.61"},{"price":"0.073","size":"87"},{"price":"0.071","size":"383.46"},{"price":"0.07","size":"1433.33"},{"price":"0.068","size":"10000"},{"price":"0.065","size":"825"},{"price":"0.064","size":"48"},{"price":"0.06","size":"29909.35"},{"price":"0.059","size":"3924.45"},{"price":"0.055","size":"400"},{"price":"0.053","size":"2222"},{"price":"0.051","size":"145"},{"price":"0.05","size":"5842.47"},{"price":"0.049","size":"500"},{"price":"0.048","size":"62"},{"price":"0.045","size":"6075.16"},{"price":"0.043","size":"300"},{"price":"0.04","size":"18121.22"},{"price":"0.039","size":"9840.45"},{"price":"0.037","size":"2222"},{"price":"0.036","size":"6200"},{"price":"0.035","size":"109"},{"price":"0.034","size":"5735.96"},{"price":"0.032","size":"12105"},{"price":"0.031","size":"10638.81"},{"price":"0.03","size":"10873.18"},{"price":"0.029","size":"22026.71"},{"price":"0.028","size":"1760.43"},{"price":"0.027","size":"200"},{"price":"0.026","size":"1006"},{"price":"0.025","size":"5881.98"},{"price":"0.024","size":"11679.33"},{"price":"0.023","size":"465"},{"price":"0.022","size":"16023"},{"price":"0.021","size":"460"},{"price":"0.02","size":"58282.31"},{"price":"0.019","size":"2167"},{"price":"0.018","size":"2171"},{"price":"0.017","size":"11286"},{"price":"0.016","size":"5879"},{"price":"0.015","size":"118529.11"},{"price":"0.014","size":"4302.4"},{"price":"0.013","size":"1400"},{"price":"0.012","size":"118274.67"},{"price":"0.011","size":"105151.84"}],"tick_size":"0.001","event_type":"book","last_trade_price":"0.989"},{"market":"0x789c947a9415600d30d56a4aae88d4111996679b0caed166d0c96242fdce92a2","asset_id":"24518145234935510389593655576204486088909794182728020215970587753906648618285","timestamp":"1779223890459","hash":"eb1df7367527101e516d73047d85362b1bc45930","bids":[{"price":"0.001","size":"408349"},{"price":"0.002","size":"65536"},{"price":"0.003","size":"10000"},{"price":"0.004","size":"32768"},{"price":"0.005","size":"30000"},{"price":"0.008","size":"241192"},{"price":"0.009","size":"120000"},{"price":"0.01","size":"181.42"},{"price":"0.011","size":"10000"},{"price":"0.016","size":"4096"},{"price":"0.017","size":"109800"},{"price":"0.02","size":"10075"},{"price":"0.032","size":"2048"},{"price":"0.05","size":"107044.4"},{"price":"0.051","size":"10000"},{"price":"0.064","size":"1024"},{"price":"0.07","size":"55200.67"},{"price":"0.08","size":"2391.43"},{"price":"0.1","size":"12125"},{"price":"0.11","size":"2698"},{"price":"0.12","size":"140.62"},{"price":"0.128","size":"256"},{"price":"0.13","size":"625"},{"price":"0.18","size":"46.87"},{"price":"0.2","size":"70787.5"},{"price":"0.201","size":"500"},{"price":"0.208","size":"499.99"},{"price":"0.21","size":"921"},{"price":"0.22","size":"62.5"},{"price":"0.247","size":"121.45"},{"price":"0.25","size":"650"},{"price":"0.256","size":"128"},{"price":"0.293","size":"518.77"},{"price":"0.3","size":"33982"},{"price":"0.301","size":"500"},{"price":"0.31","size":"373"},{"price":"0.357","size":"425.77"},{"price":"0.4","size":"23725"},{"price":"0.401","size":"20000"},{"price":"0.402","size":"1000"},{"price":"0.436","size":"275.22"},{"price":"0.45","size":"75806.63"},{"price":"0.451","size":"500"},{"price":"0.452","size":"502.3"},{"price":"0.46","size":"1519"},{"price":"0.461","size":"1300"},{"price":"0.5","size":"14787.03"},{"price":"0.51","size":"15475.64"},{"price":"0.512","size":"64"},{"price":"0.6","size":"27722.04"},{"price":"0.601","size":"2000"},{"price":"0.63","size":"8595"},{"price":"0.68","size":"171.43"},{"price":"0.69","size":"168"},{"price":"0.7","size":"9537.29"},{"price":"0.701","size":"1099.34"},{"price":"0.75","size":"150"},{"price":"0.76","size":"100"},{"price":"0.8","size":"7825.47"},{"price":"0.801","size":"11220"},{"price":"0.82","size":"385.13"},{"price":"0.84","size":"800"},{"price":"0.85","size":"5000"},{"price":"0.864","size":"30"},{"price":"0.88","size":"123036.39"},{"price":"0.881","size":"22493.21"},{"price":"0.899","size":"20000"},{"price":"0.9","size":"10338.72"},{"price":"0.906","size":"13000"},{"price":"0.908","size":"10000"},{"price":"0.91","size":"1700"},{"price":"0.916","size":"10000"},{"price":"0.92","size":"7297.85"},{"price":"0.921","size":"10000"},{"price":"0.926","size":"47.61"},{"price":"0.927","size":"87"},{"price":"0.929","size":"383.46"},{"price":"0.93","size":"1433.33"},{"price":"0.932","size":"10000"},{"price":"0.935","size":"825"},{"price":"0.936","size":"48"},{"price":"0.94","size":"29909.35"},{"price":"0.941","size":"3924.45"},{"price":"0.945","size":"400"},{"price":"0.947","size":"2222"},{"price":"0.949","size":"145"},{"price":"0.95","size":"5842.47"},{"price":"0.951","size":"500"},{"price":"0.952","size":"62"},{"price":"0.955","size":"6075.16"},{"price":"0.957","size":"300"},{"price":"0.96","size":"18121.22"},{"price":"0.961","size":"9840.45"},{"price":"0.963","size":"2222"},{"price":"0.964","size":"6200"},{"price":"0.965","size":"109"},{"price":"0.966","size":"5735.96"},{"price":"0.968","size":"12105"},{"price":"0.969","size":"10638.81"},{"price":"0.97","size":"10873.18"},{"price":"0.971","size":"22026.71"},{"price":"0.972","size":"1760.43"},{"price":"0.973","size":"200"},{"price":"0.974","size":"1006"},{"price":"0.975","size":"5881.98"},{"price":"0.976","size":"11679.33"},{"price":"0.977","size":"465"},{"price":"0.978","size":"16023"},{"price":"0.979","size":"460"},{"price":"0.98","size":"58282.31"},{"price":"0.981","size":"2167"},{"price":"0.982","size":"2171"},{"price":"0.983","size":"11286"},{"price":"0.984","size":"5879"},{"price":"0.985","size":"118529.11"},{"price":"0.986","size":"4302.4"},{"price":"0.987","size":"1400"},{"price":"0.988","size":"118274.67"},{"price":"0.989","size":"105151.84"}],"asks":[{"price":"0.999","size":"1143673.7"},{"price":"0.998","size":"303119.26"},{"price":"0.997","size":"143440.59"},{"price":"0.996","size":"117486.95"},{"price":"0.995","size":"250508.62"},{"price":"0.994","size":"107014.32"},{"price":"0.993","size":"61036.54"},{"price":"0.992","size":"70715.1"},{"price":"0.991","size":"45374.22"},{"price":"0.99","size":"455.99"}],"tick_size":"0.001","event_type":"book","last_trade_price":"0.989"}];;{"market":"0x865ac5b1fdc1706ca8cf0f25cc63544b5abcbb6819e25d52d9ac3ee4b3446726","price_changes":[{"asset_id":"35897145766259317849531537649732979331853484456543966713822507439506839868603","price":"0.5","size":"81.07","side":"BUY","hash":"764aa68dbe90b5cc7ff74258bb00b207c2420e4b","best_bid":"0.52","best_ask":"0.54"},{"asset_id":"18124776046378286261632296176797913974857552946923528818498431780145315271239","price":"0.5","size":"81.07","side":"SELL","hash":"c9766abb388fc1e4c8f30371031faa91a6eab910","best_bid":"0.46","best_ask":"0.48"}],"timestamp":"1779223899159","event_type":"price_change"};;{"market":"0x865ac5b1fdc1706ca8cf0f25cc63544b5abcbb6819e25d52d9ac3ee4b3446726","price_changes":[{"asset_id":"35897145766259317849531537649732979331853484456543966713822507439506839868603","price":"0.51","size":"310.81","side":"BUY","hash":"de9263920df43d5cab20f8b64fe0716a4d5de490","best_bid":"0.52","best_ask":"0.54"},{"asset_id":"18124776046378286261632296176797913974857552946923528818498431780145315271239","price":"0.49","size":"310.81","side":"SELL","hash":"a5c42956eaf856e9431a5b4a539df241619b75ac","best_bid":"0.46","best_ask":"0.48"}],"timestamp":"1779223899164","event_type":"price_change"};;{"market":"0x865ac5b1fdc1706ca8cf0f25cc63544b5abcbb6819e25d52d9ac3ee4b3446726","price_changes":[{"asset_id":"18124776046378286261632296176797913974857552946923528818498431780145315271239","price":"0.41","size":"1337","side":"BUY","hash":"0d87ca57428379d8a8b00a22ae7caad8cb4ce715","best_bid":"0.46","best_ask":"0.48"},{"asset_id":"35897145766259317849531537649732979331853484456543966713822507439506839868603","price":"0.59","size":"1337","side":"SELL","hash":"f0381e6b5f9dfa422703f6abb4b10ca5906a3d7a","best_bid":"0.52","best_ask":"0.54"}],"timestamp":"1779223899165","event_type":"price_change"};;{"market":"0x865ac5b1fdc1706ca8cf0f25cc63544b5abcbb6819e25d52d9ac3ee4b3446726","price_changes":[{"asset_id":"35897145766259317849531537649732979331853484456543966713822507439506839868603","price":"0.45","size":"15","side":"BUY","hash":"d11d2cddaa4951ca9eb6bffadef6c42ac082c924","best_bid":"0.52","best_ask":"0.54"},{"asset_id":"18124776046378286261632296176797913974857552946923528818498431780145315271239","price":"0.55","size":"15","side":"SELL","hash":"71fb26a4befc53a5344dcd24829d7802e63ca929","best_bid":"0.46","best_ask":"0.48"}],"timestamp":"1779223899165","event_type":"price_change"};;{"market":"0x865ac5b1fdc1706ca8cf0f25cc63544b5abcbb6819e25d52d9ac3ee4b3446726","price_changes":[{"asset_id":"18124776046378286261632296176797913974857552946923528818498431780145315271239","price":"0.4","size":"156","side":"BUY","hash":"d65ffc5b246fd14d120e8720e9816c9853000f7b","best_bid":"0.46","best_ask":"0.48"},{"asset_id":"35897145766259317849531537649732979331853484456543966713822507439506839868603","price":"0.6","size":"156","side":"SELL","hash":"93c81945f3c2838a5aff0ed63339b0a3867dc116","best_bid":"0.52","best_ask":"0.54"}],"timestamp":"1779223899166","event_type":"price_change"};;{"market":"0x865ac5b1fdc1706ca8cf0f25cc63544b5abcbb6819e25d52d9ac3ee4b3446726","price_changes":[{"asset_id":"18124776046378286261632296176797913974857552946923528818498431780145315271239","price":"0.41","size":"1377","side":"BUY","hash":"68e70e6bc6dd4a717bc3515122a707beff801aea","best_bid":"0.46","best_ask":"0.48"},{"asset_id":"35897145766259317849531537649732979331853484456543966713822507439506839868603","price":"0.59","size":"1377","side":"SELL","hash":"c5ff9408d9d8f0c241ebf4f35cb414cd3672e38f","best_bid":"0.52","best_ask":"0.54"}],"timestamp":"1779223899169","event_type":"price_change"};;{"market":"0x865ac5b1fdc1706ca8cf0f25cc63544b5abcbb6819e25d52d9ac3ee4b3446726","price_changes":[{"asset_id":"35897145766259317849531537649732979331853484456543966713822507439506839868603","price":"0.47","size":"194","side":"BUY","hash":"d7276d52b63a0020f88f0e1db98abd35b9bc2775","best_bid":"0.52","best_ask":"0.54"},{"asset_id":"18124776046378286261632296176797913974857552946923528818498431780145315271239","price":"0.53","size":"194","side":"SELL","hash":"9145cc4dd412292278b663eb201b0bd7c91854fa","best_bid":"0.46","best_ask":"0.48"}],"timestamp":"1779223899170","event_type":"price_change"};;{"market":"0x865ac5b1fdc1706ca8cf0f25cc63544b5abcbb6819e25d52d9ac3ee4b3446726","price_changes":[{"asset_id":"18124776046378286261632296176797913974857552946923528818498431780145315271239","price":"0.42","size":"119","side":"BUY","hash":"71f5d9e05ea941471069b6160c576c9db8291ef9","best_bid":"0.46","best_ask":"0.48"},{"asset_id":"35897145766259317849531537649732979331853484456543966713822507439506839868603","price":"0.58","size":"119","side":"SELL","hash":"f23b730b43d8c76120752791441db48e981ecb10","best_bid":"0.52","best_ask":"0.54"}],"timestamp":"1779223899174","event_type":"price_change"};;{"market":"0x865ac5b1fdc1706ca8cf0f25cc63544b5abcbb6819e25d52d9ac3ee4b3446726","asset_id":"35897145766259317849531537649732979331853484456543966713822507439506839868603","best_bid":"0.53","best_ask":"0.54","spread":"0.01","timestamp":"1779223899176","event_type":"best_bid_ask"};;{"market":"0x865ac5b1fdc1706ca8cf0f25cc63544b5abcbb6819e25d52d9ac3ee4b3446726","asset_id":"18124776046378286261632296176797913974857552946923528818498431780145315271239","best_bid":"0.46","best_ask":"0.47","spread":"0.01","timestamp":"1779223899176","event_type":"best_bid_ask"};;{"market":"0x865ac5b1fdc1706ca8cf0f25cc63544b5abcbb6819e25d52d9ac3ee4b3446726","price_changes":[{"asset_id":"35897145766259317849531537649732979331853484456543966713822507439506839868603","price":"0.53","size":"170","side":"BUY","hash":"87462de0ab32fe967c234a258fa06e2f624f4bde","best_bid":"0.53","best_ask":"0.54"},{"asset_id":"18124776046378286261632296176797913974857552946923528818498431780145315271239","price":"0.47","size":"170","side":"SELL","hash":"2889f8da64a6b12a0b688cb734b0e0834a71975d","best_bid":"0.46","best_ask":"0.47"}],"timestamp":"1779223899175","event_type":"price_change"};;{"market":"0x865ac5b1fdc1706ca8cf0f25cc63544b5abcbb6819e25d52d9ac3ee4b3446726","price_changes":[{"asset_id":"18124776046378286261632296176797913974857552946923528818498431780145315271239","price":"0.45","size":"402","side":"BUY","hash":"816aa65396063995ab295803ffe494dc94bf335e","best_bid":"0.46","best_ask":"0.47"},{"asset_id":"35897145766259317849531537649732979331853484456543966713822507439506839868603","price":"0.55","size":"402","side":"SELL","hash":"33195584acc6c629f6ca78f3e7e526e4923f492b","best_bid":"0.53","best_ask":"0.54"}],"timestamp":"1779223899177","event_type":"price_change"};;{"market":"0x0e4a0c937b8934c2475613b6322b3f8edc8dedc24762e01e42b0e6f87424a089","price_changes":[{"asset_id":"72094069823942324362885404801938332659316240217382754851102758232469673300092","price":"0.08","size":"254973.38","side":"BUY","hash":"c5f923c853a82fd7023dbf15336e182afabe88e2","best_bid":"0.09","best_ask":"0.1"},{"asset_id":"42918220085288219341491829385501246298233444593663440094436147850542032590016","price":"0.92","size":"254973.38","side":"SELL","hash":"d0b3117da56999e4f43ba33c068c5639c52065cd","best_bid":"0.9","best_ask":"0.91"}],"timestamp":"1779223899182","event_type":"price_change"};;{"market":"0x865ac5b1fdc1706ca8cf0f25cc63544b5abcbb6819e25d52d9ac3ee4b3446726","price_changes":[{"asset_id":"35897145766259317849531537649732979331853484456543966713822507439506839868603","price":"0.5","size":"69.07","side":"BUY","hash":"54d03ae152b856a472b8b3edc4415025c93608f3","best_bid":"0.53","best_ask":"0.54"},{"asset_id":"18124776046378286261632296176797913974857552946923528818498431780145315271239","price":"0.5","size":"69.07","side":"SELL","hash":"fb7853754bac285eb2348df9332b6d048fd69831","best_bid":"0.46","best_ask":"0.47"}],"timestamp":"1779223899191","event_type":"price_change"};;{"market":"0x865ac5b1fdc1706ca8cf0f25cc63544b5abcbb6819e25d52d9ac3ee4b3446726","price_changes":[{"asset_id":"35897145766259317849531537649732979331853484456543966713822507439506839868603","price":"0.51","size":"304.81","side":"BUY","hash":"a8b8d12145105fc0f9f7179e61521ec5db6b8691","best_bid":"0.53","best_ask":"0.54"},{"asset_id":"18124776046378286261632296176797913974857552946923528818498431780145315271239","price":"0.49","size":"304.81","side":"SELL","hash":"5149266f5937b9d17c12bc1420dd7b4b3817dede","best_bid":"0.46","best_ask":"0.47"}],"timestamp":"1779223899193","event_type":"price_change"};;{"market":"0x865ac5b1fdc1706ca8cf0f25cc63544b5abcbb6819e25d52d9ac3ee4b3446726","price_changes":[{"asset_id":"18124776046378286261632296176797913974857552946923528818498431780145315271239","price":"0.49","size":"251.81","side":"SELL","hash":"7ca3520bc64e1608f88db155b84efd879431ee6e","best_bid":"0.46","best_ask":"0.47"},{"asset_id":"35897145766259317849531537649732979331853484456543966713822507439506839868603","price":"0.51","size":"251.81","side":"BUY","hash":"5f2e3ad6358d53d27b6d3da94ddb74b9abcacf55","best_bid":"0.53","best_ask":"0.54"}],"timestamp":"1779223899193","event_type":"price_change"};;{"market":"0x865ac5b1fdc1706ca8cf0f25cc63544b5abcbb6819e25d52d9ac3ee4b3446726","price_changes":[{"asset_id":"35897145766259317849531537649732979331853484456543966713822507439506839868603","price":"0.48","size":"898","side":"BUY","hash":"193e2d71ae4e87de881bb5a464d9f9dfa6f7770b","best_bid":"0.53","best_ask":"0.54"},{"asset_id":"18124776046378286261632296176797913974857552946923528818498431780145315271239","price":"0.52","size":"898","side":"SELL","hash":"4a8c42e0182aafbbc493bcc7fbe31f52338906f5","best_bid":"0.46","best_ask":"0.47"}],"timestamp":"1779223899194","event_type":"price_change"};;{"market":"0x865ac5b1fdc1706ca8cf0f25cc63544b5abcbb6819e25d52d9ac3ee4b3446726","price_changes":[{"asset_id":"35897145766259317849531537649732979331853484456543966713822507439506839868603","price":"0.49","size":"12","side":"BUY","hash":"a9d23244bb7dcd15befb82884037d39fcd386f90","best_bid":"0.53","best_ask":"0.54"},{"asset_id":"18124776046378286261632296176797913974857552946923528818498431780145315271239","price":"0.51","size":"12","side":"SELL","hash":"c0bc2a34d80120954fcab6204fda969621be0db4","best_bid":"0.46","best_ask":"0.47"}],"timestamp":"1779223899194","event_type":"price_change"};;{"market":"0x865ac5b1fdc1706ca8cf0f25cc63544b5abcbb6819e25d52d9ac3ee4b3446726","price_changes":[{"asset_id":"35897145766259317849531537649732979331853484456543966713822507439506839868603","price":"0.48","size":"923","side":"BUY","hash":"e497faffe1adc8bea5b55cdf958e6ab4399b3f63","best_bid":"0.53","best_ask":"0.54"},{"asset_id":"18124776046378286261632296176797913974857552946923528818498431780145315271239","price":"0.52","size":"923","side":"SELL","hash":"2e602197f6d2b4bc645bb5306c6076a6f0009c1d","best_bid":"0.46","best_ask":"0.47"}],"timestamp":"1779223899200","event_type":"price_change"};;{"market":"0x865ac5b1fdc1706ca8cf0f25cc63544b5abcbb6819e25d52d9ac3ee4b3446726","price_changes":[{"asset_id":"18124776046378286261632296176797913974857552946923528818498431780145315271239","price":"0.42","size":"202","side":"BUY","hash":"391a0fb3c1244ae1d6b9bb343c00cd9f7e25f55a","best_bid":"0.46","best_ask":"0.47"},{"asset_id":"35897145766259317849531537649732979331853484456543966713822507439506839868603","price":"0.58","size":"202","side":"SELL","hash":"c8eea3d1e9d4e58b27ae678b246df652eff00d9e","best_bid":"0.53","best_ask":"0.54"}],"timestamp":"1779223899217","event_type":"price_change"};;{"market":"0x865ac5b1fdc1706ca8cf0f25cc63544b5abcbb6819e25d52d9ac3ee4b3446726","price_changes":[{"asset_id":"35897145766259317849531537649732979331853484456543966713822507439506839868603","price":"0.47","size":"219","side":"BUY","hash":"6b5f3f9c29d5fde376b9c4b9dc60e68d173123f4","best_bid":"0.53","best_ask":"0.54"},{"asset_id":"18124776046378286261632296176797913974857552946923528818498431780145315271239","price":"0.53","size":"219","side":"SELL","hash":"393034a04dbc07ab9ad0ba3afcd9f198140d4bfc","best_bid":"0.46","best_ask":"0.47"}],"timestamp":"1779223899219","event_type":"price_change"};;{"market":"0x0e4a0c937b8934c2475613b6322b3f8edc8dedc24762e01e42b0e6f87424a089","price_changes":[{"asset_id":"42918220085288219341491829385501246298233444593663440094436147850542032590016","price":"0.89","size":"63708.87","side":"BUY","hash":"d9dc94987311c95069efe3c2d8a96b9adcc32091","best_bid":"0.9","best_ask":"0.91"},{"asset_id":"72094069823942324362885404801938332659316240217382754851102758232469673300092","price":"0.11","size":"63708.87","side":"SELL","hash":"d1af1790b39e4d6997f44fa3704b1805a4b6088a","best_bid":"0.09","best_ask":"0.1"}],"timestamp":"1779223899220","event_type":"price_change"};;{"market":"0x865ac5b1fdc1706ca8cf0f25cc63544b5abcbb6819e25d52d9ac3ee4b3446726","price_changes":[{"asset_id":"35897145766259317849531537649732979331853484456543966713822507439506839868603","price":"0.12","size":"0","side":"BUY","hash":"2407fa9036f801c837fc556a16e3b59dc14b8dc0","best_bid":"0.53","best_ask":"0.54"},{"asset_id":"18124776046378286261632296176797913974857552946923528818498431780145315271239","price":"0.88","size":"0","side":"SELL","hash":"0e456c1242726cea79a6edefffd17bc4abfa34ad","best_bid":"0.46","best_ask":"0.47"}],"timestamp":"1779223899224","event_type":"price_change"};;{"market":"0x865ac5b1fdc1706ca8cf0f25cc63544b5abcbb6819e25d52d9ac3ee4b3446726","price_changes":[{"asset_id":"35897145766259317849531537649732979331853484456543966713822507439506839868603","price":"0.47","size":"189","side":"BUY","hash":"d8e10b293df723243dc7fdb29033c5e91af4c53c","best_bid":"0.53","best_ask":"0.54"},{"asset_id":"18124776046378286261632296176797913974857552946923528818498431780145315271239","price":"0.53","size":"189","side":"SELL","hash":"c5132e1729cbe522de0ee861c7636cbe23efd26b","best_bid":"0.46","best_ask":"0.47"}],"timestamp":"1779223899227","event_type":"price_change"};;{"market":"0x865ac5b1fdc1706ca8cf0f25cc63544b5abcbb6819e25d52d9ac3ee4b3446726","price_changes":[{"asset_id":"18124776046378286261632296176797913974857552946923528818498431780145315271239","price":"0.43","size":"474","side":"BUY","hash":"6f5a893095f3e770261c8a118b1bdc988d41eb39","best_bid":"0.46","best_ask":"0.47"},{"asset_id":"35897145766259317849531537649732979331853484456543966713822507439506839868603","price":"0.57","size":"474","side":"SELL","hash":"9a46c11c15d6f5809d6a95a38cd15ef2fdc42320","best_bid":"0.53","best_ask":"0.54"}],"timestamp":"1779223899230","event_type":"price_change"};;{"market":"0x865ac5b1fdc1706ca8cf0f25cc63544b5abcbb6819e25d52d9ac3ee4b3446726","price_changes":[{"asset_id":"35897145766259317849531537649732979331853484456543966713822507439506839868603","price":"0.45","size":"45","side":"BUY","hash":"97637573f8e023c7b27ba2c46a8e43cdb7b69d40","best_bid":"0.53","best_ask":"0.54"},{"asset_id":"18124776046378286261632296176797913974857552946923528818498431780145315271239","price":"0.55","size":"45","side":"SELL","hash":"d51294a2e2efd76036d93fb1bc9b97f40053966a","best_bid":"0.46","best_ask":"0.47"}],"timestamp":"1779223899238","event_type":"price_change"};;{"market":"0x865ac5b1fdc1706ca8cf0f25cc63544b5abcbb6819e25d52d9ac3ee4b3446726","price_changes":[{"asset_id":"18124776046378286261632296176797913974857552946923528818498431780145315271239","price":"0.42","size":"212","side":"BUY","hash":"ec6b66a1a2b071b080aec356d3df18dde62060bd","best_bid":"0.46","best_ask":"0.47"},{"asset_id":"35897145766259317849531537649732979331853484456543966713822507439506839868603","price":"0.58","size":"212","side":"SELL","hash":"fafe06c7f93af5e1a1bd5d2bf97d4ffb21783362","best_bid":"0.53","best_ask":"0.54"}],"timestamp":"1779223899238","event_type":"price_change"};;{"market":"0x865ac5b1fdc1706ca8cf0f25cc63544b5abcbb6819e25d52d9ac3ee4b3446726","price_changes":[{"asset_id":"35897145766259317849531537649732979331853484456543966713822507439506839868603","price":"0.5","size":"85.07","side":"BUY","hash":"a64e45356b07c00d3ccdf6b031eaee36b0962f09","best_bid":"0.53","best_ask":"0.54"},{"asset_id":"18124776046378286261632296176797913974857552946923528818498431780145315271239","price":"0.5","size":"85.07","side":"SELL","hash":"371c1b22425331f2dcc7c80e882a3cc18aacbd66","best_bid":"0.46","best_ask":"0.47"}],"timestamp":"1779223899258","event_type":"price_change"};;{"market":"0x865ac5b1fdc1706ca8cf0f25cc63544b5abcbb6819e25d52d9ac3ee4b3446726","price_changes":[{"asset_id":"18124776046378286261632296176797913974857552946923528818498431780145315271239","price":"0.41","size":"1327","side":"BUY","hash":"bac2393dc2027d1e5a9869baf22f277d2406fd97","best_bid":"0.46","best_ask":"0.47"},{"asset_id":"35897145766259317849531537649732979331853484456543966713822507439506839868603","price":"0.59","size":"1327","side":"SELL","hash":"cfec0dcaee7aad002bcd61cdeab4afc0dd3d84a9","best_bid":"0.53","best_ask":"0.54"}],"timestamp":"1779223899282","event_type":"price_change"};;{"market":"0x865ac5b1fdc1706ca8cf0f25cc63544b5abcbb6819e25d52d9ac3ee4b3446726","price_changes":[{"asset_id":"18124776046378286261632296176797913974857552946923528818498431780145315271239","price":"0.42","size":"242","side":"BUY","hash":"997f8b95966904451716813550bdc45f249eaa22","best_bid":"0.46","best_ask":"0.47"},{"asset_id":"35897145766259317849531537649732979331853484456543966713822507439506839868603","price":"0.58","size":"242","side":"SELL","hash":"98afb9cc06dc3782f4261b883dca60f8d8934d2c","best_bid":"0.53","best_ask":"0.54"}],"timestamp":"1779223899290","event_type":"price_change"};;{"market":"0x865ac5b1fdc1706ca8cf0f25cc63544b5abcbb6819e25d52d9ac3ee4b3446726","price_changes":[{"asset_id":"35897145766259317849531537649732979331853484456543966713822507439506839868603","price":"0.52","size":"977","side":"BUY","hash":"5a7f04739a6cf0ccc4557f88dad9ab444e7d1420","best_bid":"0.53","best_ask":"0.54"},{"asset_id":"18124776046378286261632296176797913974857552946923528818498431780145315271239","price":"0.48","size":"977","side":"SELL","hash":"fe01803c1bdaab4391d309f4942de54ef1ef1527","best_bid":"0.46","best_ask":"0.47"}],"timestamp":"1779223899316","event_type":"price_change"};;{"market":"0x865ac5b1fdc1706ca8cf0f25cc63544b5abcbb6819e25d52d9ac3ee4b3446726","price_changes":[{"asset_id":"18124776046378286261632296176797913974857552946923528818498431780145315271239","price":"0.44","size":"1606.27","side":"BUY","hash":"f08dc29fa81baadc3c16e30ad73d68808ea4e7ac","best_bid":"0.46","best_ask":"0.47"},{"asset_id":"35897145766259317849531537649732979331853484456543966713822507439506839868603","price":"0.56","size":"1606.27","side":"SELL","hash":"84d3a1a8ec187808f1c23fce733199dcfe8c0459","best_bid":"0.53","best_ask":"0.54"}],"timestamp":"1779223899316","event_type":"price_change"};;{"market":"0x865ac5b1fdc1706ca8cf0f25cc63544b5abcbb6819e25d52d9ac3ee4b3446726","asset_id":"35897145766259317849531537649732979331853484456543966713822507439506839868603","best_bid":"0.52","best_ask":"0.54","spread":"0.02","timestamp":"1779223899328","event_type":"best_bid_ask"};;{"market":"0x865ac5b1fdc1706ca8cf0f25cc63544b5abcbb6819e25d52d9ac3ee4b3446726","asset_id":"18124776046378286261632296176797913974857552946923528818498431780145315271239","best_bid":"0.46","best_ask":"0.48","spread":"0.02","timestamp":"1779223899328","event_type":"best_bid_ask"};;{"market":"0x865ac5b1fdc1706ca8cf0f25cc63544b5abcbb6819e25d52d9ac3ee4b3446726","price_changes":[{"asset_id":"35897145766259317849531537649732979331853484456543966713822507439506839868603","price":"0.53","size":"0","side":"BUY","hash":"6901fc4cdcc504917810287814b1f30a930e26b9","best_bid":"0.52","best_ask":"0.54"},{"asset_id":"18124776046378286261632296176797913974857552946923528818498431780145315271239","price":"0.47","size":"0","side":"SELL","hash":"0158adcb8ed9f7fbd4ba699edec023395ec75d75","best_bid":"0.46","best_ask":"0.48"}],"timestamp":"1779223899327","event_type":"price_change"};;{"market":"0xb99047b9bdf8132c367cf327936676a1186a6eb57b86a742fdfe812f86b2e3b9","price_changes":[{"asset_id":"101407360275578242025559123794924815546227269981219987932032932255334246314286","price":"0.13","size":"5702","side":"BUY","hash":"f1bb2c8b6a8d07379ea551aa0c49d1248e38602a","best_bid":"0.8","best_ask":"0.81"},{"asset_id":"76150632180345500942617667303892128055275310542626568919906405357352468359168","price":"0.87","size":"5702","side":"SELL","hash":"3ead138e89313c6eaee48e5ac4b83446046ed78e","best_bid":"0.19","best_ask":"0.2"}],"timestamp":"1779223899328","event_type":"price_change"};;{"market":"0x865ac5b1fdc1706ca8cf0f25cc63544b5abcbb6819e25d52d9ac3ee4b3446726","price_changes":[{"asset_id":"18124776046378286261632296176797913974857552946923528818498431780145315271239","price":"0.1","size":"5400","side":"BUY","hash":"2ea22a0ee3577f288fba275a6ec3d26402bbf030","best_bid":"0.46","best_ask":"0.48"},{"asset_id":"35897145766259317849531537649732979331853484456543966713822507439506839868603","price":"0.9","size":"5400","side":"SELL","hash":"1839425bc8a29521638cc1e832aca9c851e7744b","best_bid":"0.52","best_ask":"0.54"}],"timestamp":"1779223899328","event_type":"price_change"};;{"market":"0x865ac5b1fdc1706ca8cf0f25cc63544b5abcbb6819e25d52d9ac3ee4b3446726","price_changes":[{"asset_id":"35897145766259317849531537649732979331853484456543966713822507439506839868603","price":"0.48","size":"893","side":"BUY","hash":"166f0000d171f6e0c53a0e7380d77578e1c206b0","best_bid":"0.52","best_ask":"0.54"},{"asset_id":"18124776046378286261632296176797913974857552946923528818498431780145315271239","price":"0.52","size":"893","side":"SELL","hash":"990646dce4f3829df6db8339fd3b95df9f595f77","best_bid":"0.46","best_ask":"0.48"}],"timestamp":"1779223899332","event_type":"price_change"};;{"market":"0x0e4a0c937b8934c2475613b6322b3f8edc8dedc24762e01e42b0e6f87424a089","price_changes":[{"asset_id":"72094069823942324362885404801938332659316240217382754851102758232469673300092","price":"0.08","size":"254681.38","side":"BUY","hash":"a425d8e4ae4288bf3fd7a89f099cff93f3167cbf","best_bid":"0.09","best_ask":"0.1"},{"asset_id":"42918220085288219341491829385501246298233444593663440094436147850542032590016","price":"0.92","size":"254681.38","side":"SELL","hash":"77d3acb5dd1560a4f160bc1e3bd60c2da227a194","best_bid":"0.9","best_ask":"0.91"}],"timestamp":"1779223899344","event_type":"price_change"};;{"market":"0x0e4a0c937b8934c2475613b6322b3f8edc8dedc24762e01e42b0e6f87424a089","price_changes":[{"asset_id":"42918220085288219341491829385501246298233444593663440094436147850542032590016","price":"0.89","size":"63416.87","side":"BUY","hash":"1a9304f74b1e3edec95cd8124edb4a2c05eafe78","best_bid":"0.9","best_ask":"0.91"},{"asset_id":"72094069823942324362885404801938332659316240217382754851102758232469673300092","price":"0.11","size":"63416.87","side":"SELL","hash":"372f5e694f1daa16582d34da86cfc5e279e6cd55","best_bid":"0.09","best_ask":"0.1"}],"timestamp":"1779223899349","event_type":"price_change"};;{"market":"0x865ac5b1fdc1706ca8cf0f25cc63544b5abcbb6819e25d52d9ac3ee4b3446726","price_changes":[{"asset_id":"35897145766259317849531537649732979331853484456543966713822507439506839868603","price":"0.45","size":"75","side":"BUY","hash":"fbb554dc758d33674d32e13c85259c2418ba617a","best_bid":"0.52","best_ask":"0.54"},{"asset_id":"18124776046378286261632296176797913974857552946923528818498431780145315271239","price":"0.55","size":"75","side":"SELL","hash":"557b703d6693547993dc51ab06bf8162db326cc0","best_bid":"0.46","best_ask":"0.48"}],"timestamp":"1779223899351","event_type":"price_change"};;{"market":"0xb99047b9bdf8132c367cf327936676a1186a6eb57b86a742fdfe812f86b2e3b9","price_changes":[{"asset_id":"76150632180345500942617667303892128055275310542626568919906405357352468359168","price":"0.2","size":"10748.17","side":"SELL","hash":"615da0f70a214e96f0d7ddfbb690a124a83d1303","best_bid":"0.19","best_ask":"0.2"},{"asset_id":"101407360275578242025559123794924815546227269981219987932032932255334246314286","price":"0.8","size":"10748.17","side":"BUY","hash":"596277671dae525457814a6da70691dc6e871a83","best_bid":"0.8","best_ask":"0.81"}],"timestamp":"1779223899353","event_type":"price_change"};;{"market":"0xb99047b9bdf8132c367cf327936676a1186a6eb57b86a742fdfe812f86b2e3b9","price_changes":[{"asset_id":"101407360275578242025559123794924815546227269981219987932032932255334246314286","price":"0.81","size":"244.91","side":"SELL","hash":"e3aae84242287cef8921bfc70092ce000b1026ac","best_bid":"0.8","best_ask":"0.81"},{"asset_id":"76150632180345500942617667303892128055275310542626568919906405357352468359168","price":"0.19","size":"244.91","side":"BUY","hash":"9786946808e2521f2a7a6bc4981512e6045b5da8","best_bid":"0.19","best_ask":"0.2"}],"timestamp":"1779223899357","event_type":"price_change"};;{"market":"0x865ac5b1fdc1706ca8cf0f25cc63544b5abcbb6819e25d52d9ac3ee4b3446726","price_changes":[{"asset_id":"35897145766259317849531537649732979331853484456543966713822507439506839868603","price":"0.5","size":"69.07","side":"BUY","hash":"c5c591c9a218133a5196ce8299f32963335fe814","best_bid":"0.52","best_ask":"0.54"},{"asset_id":"18124776046378286261632296176797913974857552946923528818498431780145315271239","price":"0.5","size":"69.07","side":"SELL","hash":"5a419c62c5e40232d0dff9be2a9687e2ac33011d","best_bid":"0.46","best_ask":"0.48"}],"timestamp":"1779223899361","event_type":"price_change"};;{"market":"0x865ac5b1fdc1706ca8cf0f25cc63544b5abcbb6819e25d52d9ac3ee4b3446726","asset_id":"35897145766259317849531537649732979331853484456543966713822507439506839868603","best_bid":"0.51","best_ask":"0.54","spread":"0.03","timestamp":"1779223899370","event_type":"best_bid_ask"};;{"market":"0x865ac5b1fdc1706ca8cf0f25cc63544b5abcbb6819e25d52d9ac3ee4b3446726","asset_id":"18124776046378286261632296176797913974857552946923528818498431780145315271239","best_bid":"0.46","best_ask":"0.49","spread":"0.03","timestamp":"1779223899370","event_type":"best_bid_ask"};;{"market":"0x865ac5b1fdc1706ca8cf0f25cc63544b5abcbb6819e25d52d9ac3ee4b3446726","price_changes":[{"asset_id":"35897145766259317849531537649732979331853484456543966713822507439506839868603","price":"0.52","size":"0","side":"BUY","hash":"efa75c634b0ba57bad9e6a9a8f874a9c7afed9cf","best_bid":"0.51","best_ask":"0.54"},{"asset_id":"18124776046378286261632296176797913974857552946923528818498431780145315271239","price":"0.48","size":"0","side":"SELL","hash":"3bcbcbc6a644d858a14c214ae17b3de1a45efa85","best_bid":"0.46","best_ask":"0.49"}],"timestamp":"1779223899369","event_type":"price_change"};;{"market":"0x865ac5b1fdc1706ca8cf0f25cc63544b5abcbb6819e25d52d9ac3ee4b3446726","price_changes":[{"asset_id":"35897145766259317849531537649732979331853484456543966713822507439506839868603","price":"0.44","size":"0","side":"BUY","hash":"d29e27440bd2915bc13d8f3ebd4c396b8a527937","best_bid":"0.51","best_ask":"0.54"},{"asset_id":"18124776046378286261632296176797913974857552946923528818498431780145315271239","price":"0.56","size":"0","side":"SELL","hash":"21691dd7b5fa022b59183250e9418a907a31d079","best_bid":"0.46","best_ask":"0.49"}],"timestamp":"1779223899375","event_type":"price_change"};;{"market":"0x865ac5b1fdc1706ca8cf0f25cc63544b5abcbb6819e25d52d9ac3ee4b3446726","price_changes":[{"asset_id":"35897145766259317849531537649732979331853484456543966713822507439506839868603","price":"0.24","size":"300","side":"BUY","hash":"2924288ca7d9471d3af685cf3eeb9eb078e97329","best_bid":"0.51","best_ask":"0.54"},{"asset_id":"18124776046378286261632296176797913974857552946923528818498431780145315271239","price":"0.76","size":"300","side":"SELL","hash":"baf0521bbecc61b466b171ebe5c54d1bdaf27cff","best_bid":"0.46","best_ask":"0.49"}],"timestamp":"1779223899378","event_type":"price_change"};;{"market":"0x865ac5b1fdc1706ca8cf0f25cc63544b5abcbb6819e25d52d9ac3ee4b3446726","price_changes":[{"asset_id":"35897145766259317849531537649732979331853484456543966713822507439506839868603","price":"0.47","size":"219","side":"BUY","hash":"a8fd05cb99549c36cdf0ba2de3eb83b5eeac58b2","best_bid":"0.51","best_ask":"0.54"},{"asset_id":"18124776046378286261632296176797913974857552946923528818498431780145315271239","price":"0.53","size":"219","side":"SELL","hash":"7c36329b501bd626b49d3efd82f3d36d98f1899c","best_bid":"0.46","best_ask":"0.49"}],"timestamp":"1779223899383","event_type":"price_change"};;{"market":"0x865ac5b1fdc1706ca8cf0f25cc63544b5abcbb6819e25d52d9ac3ee4b3446726","price_changes":[{"asset_id":"35897145766259317849531537649732979331853484456543966713822507439506839868603","price":"0.49","size":"0","side":"BUY","hash":"3b8cb6b8324492b7c1106efb35a3fcdc2c0c5a19","best_bid":"0.51","best_ask":"0.54"},{"asset_id":"18124776046378286261632296176797913974857552946923528818498431780145315271239","price":"0.51","size":"0","side":"SELL","hash":"1505a4baec438cfd3cdf6fe0f2458e669b5f8d17","best_bid":"0.46","best_ask":"0.49"}],"timestamp":"1779223899389","event_type":"price_change"};;{"market":"0x865ac5b1fdc1706ca8cf0f25cc63544b5abcbb6819e25d52d9ac3ee4b3446726","price_changes":[{"asset_id":"18124776046378286261632296176797913974857552946923528818498431780145315271239","price":"0.5","size":"122.07","side":"SELL","hash":"f81eeeb20b51e71b1e7f55bdb2df6c8814711f99","best_bid":"0.46","best_ask":"0.49"},{"asset_id":"35897145766259317849531537649732979331853484456543966713822507439506839868603","price":"0.5","size":"122.07","side":"BUY","hash":"c63dc70bc0f10a8ec9d17e6a47ed22de82477364","best_bid":"0.51","best_ask":"0.54"}],"timestamp":"1779223899397","event_type":"price_change"};;{"market":"0x865ac5b1fdc1706ca8cf0f25cc63544b5abcbb6819e25d52d9ac3ee4b3446726","price_changes":[{"asset_id":"35897145766259317849531537649732979331853484456543966713822507439506839868603","price":"0.5","size":"128.07","side":"BUY","hash":"4d551e307d685274eb84b2801c60fbfc570bdc44","best_bid":"0.51","best_ask":"0.54"},{"asset_id":"18124776046378286261632296176797913974857552946923528818498431780145315271239","price":"0.5","size":"128.07","side":"SELL","hash":"52d3e1e0019dd3334b5ceffebe332042313799df","best_bid":"0.46","best_ask":"0.49"}],"timestamp":"1779223899398","event_type":"price_change"};;{"market":"0x865ac5b1fdc1706ca8cf0f25cc63544b5abcbb6819e25d52d9ac3ee4b3446726","price_changes":[{"asset_id":"18124776046378286261632296176797913974857552946923528818498431780145315271239","price":"0.42","size":"232","side":"BUY","hash":"af925d0e35fc9afa9bbea4928937ba7548f66fbe","best_bid":"0.46","best_ask":"0.49"},{"asset_id":"35897145766259317849531537649732979331853484456543966713822507439506839868603","price":"0.58","size":"232","side":"SELL","hash":"28b647db368bb877432b7295b6a66b4b3d0496fd","best_bid":"0.51","best_ask":"0.54"}],"timestamp":"1779223899400","event_type":"price_change"};;{"market":"0x865ac5b1fdc1706ca8cf0f25cc63544b5abcbb6819e25d52d9ac3ee4b3446726","price_changes":[{"asset_id":"35897145766259317849531537649732979331853484456543966713822507439506839868603","price":"0.48","size":"883","side":"BUY","hash":"8e81e1acdd8bbab51f8a2abd0f288ebeb851759d","best_bid":"0.51","best_ask":"0.54"},{"asset_id":"18124776046378286261632296176797913974857552946923528818498431780145315271239","price":"0.52","size":"883","side":"SELL","hash":"ce5f686cc754ee507cb5454bd3824122fef1cbf7","best_bid":"0.46","best_ask":"0.49"}],"timestamp":"1779223899400","event_type":"price_change"};;{"market":"0xb99047b9bdf8132c367cf327936676a1186a6eb57b86a742fdfe812f86b2e3b9","price_changes":[{"asset_id":"101407360275578242025559123794924815546227269981219987932032932255334246314286","price":"0.13","size":"5650","side":"BUY","hash":"7afe39853e915895275be0462053b7cfe4391929","best_bid":"0.8","best_ask":"0.81"},{"asset_id":"76150632180345500942617667303892128055275310542626568919906405357352468359168","price":"0.87","size":"5650","side":"SELL","hash":"8623c8c10ae75085d8d2c7420cbe9af7161e7ca2","best_bid":"0.19","best_ask":"0.2"}],"timestamp":"1779223899403","event_type":"price_change"};;{"market":"0x865ac5b1fdc1706ca8cf0f25cc63544b5abcbb6819e25d52d9ac3ee4b3446726","price_changes":[{"asset_id":"35897145766259317849531537649732979331853484456543966713822507439506839868603","price":"0.47","size":"235","side":"BUY","hash":"f4fe5b50b6bdf99f05233657bcc74e8f76b1592b","best_bid":"0.51","best_ask":"0.54"},{"asset_id":"18124776046378286261632296176797913974857552946923528818498431780145315271239","price":"0.53","size":"235","side":"SELL","hash":"d87f460c06fa9d99d5789131fab48196802fb617","best_bid":"0.46","best_ask":"0.49"}],"timestamp":"1779223899405","event_type":"price_change"};;{"market":"0x865ac5b1fdc1706ca8cf0f25cc63544b5abcbb6819e25d52d9ac3ee4b3446726","asset_id":"35897145766259317849531537649732979331853484456543966713822507439506839868603","best_bid":"0.51","best_ask":"0.53","spread":"0.02","timestamp":"1779223899430","event_type":"best_bid_ask"};;{"market":"0x865ac5b1fdc1706ca8cf0f25cc63544b5abcbb6819e25d52d9ac3ee4b3446726","asset_id":"18124776046378286261632296176797913974857552946923528818498431780145315271239","best_bid":"0.47","best_ask":"0.49","spread":"0.02","timestamp":"1779223899430","event_type":"best_bid_ask"};;{"market":"0x865ac5b1fdc1706ca8cf0f25cc63544b5abcbb6819e25d52d9ac3ee4b3446726","price_changes":[{"asset_id":"18124776046378286261632296176797913974857552946923528818498431780145315271239","price":"0.47","size":"150","side":"BUY","hash":"04482235c58e2bfedd4f6e5dfd908af90920bcce","best_bid":"0.47","best_ask":"0.49"},{"asset_id":"35897145766259317849531537649732979331853484456543966713822507439506839868603","price":"0.53","size":"150","side":"SELL","hash":"c73be995bd8e694aeb937f7909898a8cdd7e54a9","best_bid":"0.51","best_ask":"0.53"}],"timestamp":"1779223899430","event_type":"price_change"};;{"market":"0x8530b96422523df2024c4242021b58da538c5e94ba525e8f9893c3fc2f469160","price_changes":[{"asset_id":"91811271690939763569588501717168303099799014127066745654294854264052726562982","price":"0.3","size":"1514297.7","side":"BUY","hash":"a4a75b51899cf35b7a0fbca182c8947d9a5ac410","best_bid":"0.31","best_ask":"0.32"},{"asset_id":"90341073610328513874226762002064133262679100936760740635957635490606188341771","price":"0.7","size":"1514297.7","side":"SELL","hash":"8f31bda22ce4e1c330825a55725b549abf025054","best_bid":"0.68","best_ask":"0.69"}],"timestamp":"1779223899441","event_type":"price_change"};;{"market":"0x865ac5b1fdc1706ca8cf0f25cc63544b5abcbb6819e25d52d9ac3ee4b3446726","price_changes":[{"asset_id":"35897145766259317849531537649732979331853484456543966713822507439506839868603","price":"0.46","size":"169","side":"BUY","hash":"19741bfc1f66b8c9c61bb9f8c296e02493069d70","best_bid":"0.51","best_ask":"0.53"},{"asset_id":"18124776046378286261632296176797913974857552946923528818498431780145315271239","price":"0.54","size":"169","side":"SELL","hash":"1fde41552c6fbd519186ad80e70066f67ec13e65","best_bid":"0.47","best_ask":"0.49"}],"timestamp":"1779223899447","event_type":"price_change"};;{"market":"0x865ac5b1fdc1706ca8cf0f25cc63544b5abcbb6819e25d52d9ac3ee4b3446726","price_changes":[{"asset_id":"18124776046378286261632296176797913974857552946923528818498431780145315271239","price":"0.5","size":"75.07","side":"SELL","hash":"afb33a0a726d07d6a2b29fc29de2afd4f3c1a3c3","best_bid":"0.47","best_ask":"0.49"},{"asset_id":"35897145766259317849531537649732979331853484456543966713822507439506839868603","price":"0.5","size":"75.07","side":"BUY","hash":"bc759791de219617a9567acb9a4e0b2161852959","best_bid":"0.51","best_ask":"0.53"}],"timestamp":"1779223899448","event_type":"price_change"};;{"market":"0x865ac5b1fdc1706ca8cf0f25cc63544b5abcbb6819e25d52d9ac3ee4b3446726","price_changes":[{"asset_id":"35897145766259317849531537649732979331853484456543966713822507439506839868603","price":"0.5","size":"69.07","side":"BUY","hash":"42c003d774dd5e5e3fceba841a77505ee122fe48","best_bid":"0.51","best_ask":"0.53"},{"asset_id":"18124776046378286261632296176797913974857552946923528818498431780145315271239","price":"0.5","size":"69.07","side":"SELL","hash":"51764ac937becdee4f2d9a54c277062f8378d2d9","best_bid":"0.47","best_ask":"0.49"}],"timestamp":"1779223899449","event_type":"price_change"};;{"market":"0x865ac5b1fdc1706ca8cf0f25cc63544b5abcbb6819e25d52d9ac3ee4b3446726","price_changes":[{"asset_id":"35897145766259317849531537649732979331853484456543966713822507439506839868603","price":"0.48","size":"871","side":"BUY","hash":"071248acfd5377cf4f7e967952d822dac238df03","best_bid":"0.51","best_ask":"0.53"},{"asset_id":"18124776046378286261632296176797913974857552946923528818498431780145315271239","price":"0.52","size":"871","side":"SELL","hash":"8101f072bc58a3fefc57ea59e148a2dc4b36a4fb","best_bid":"0.47","best_ask":"0.49"}],"timestamp":"1779223899478","event_type":"price_change"};;{"market":"0x865ac5b1fdc1706ca8cf0f25cc63544b5abcbb6819e25d52d9ac3ee4b3446726","price_changes":[{"asset_id":"35897145766259317849531537649732979331853484456543966713822507439506839868603","price":"0.36","size":"0","side":"BUY","hash":"d859543446c9a02a1dde7841628fa1d6d0dbdf2e","best_bid":"0.51","best_ask":"0.53"},{"asset_id":"18124776046378286261632296176797913974857552946923528818498431780145315271239","price":"0.64","size":"0","side":"SELL","hash":"25c80c027a47aa5aaa3cb01e3bf4c62814a549d1","best_bid":"0.47","best_ask":"0.49"}],"timestamp":"1779223899509","event_type":"price_change"};;{"market":"0x865ac5b1fdc1706ca8cf0f25cc63544b5abcbb6819e25d52d9ac3ee4b3446726","price_changes":[{"asset_id":"35897145766259317849531537649732979331853484456543966713822507439506839868603","price":"0.45","size":"100","side":"BUY","hash":"f0ea2bde37d452b076b8dd7f3436a439d876056e","best_bid":"0.51","best_ask":"0.53"},{"asset_id":"18124776046378286261632296176797913974857552946923528818498431780145315271239","price":"0.55","size":"100","side":"SELL","hash":"f33999a47cae7af8bf195c8e66838b5881f7eb1e","best_bid":"0.47","best_ask":"0.49"}],"timestamp":"1779223899513","event_type":"price_change"};;{"market":"0xb99047b9bdf8132c367cf327936676a1186a6eb57b86a742fdfe812f86b2e3b9","price_changes":[{"asset_id":"101407360275578242025559123794924815546227269981219987932032932255334246314286","price":"0.14","size":"8341.15","side":"BUY","hash":"73f4e287d7964ba4f88105824337be6251f9e3f6","best_bid":"0.8","best_ask":"0.81"},{"asset_id":"76150632180345500942617667303892128055275310542626568919906405357352468359168","price":"0.86","size":"8341.15","side":"SELL","hash":"24a28ef4430b5e9da710cbc1a7b6e1eece8ed9e4","best_bid":"0.19","best_ask":"0.2"}],"timestamp":"1779223899531","event_type":"price_change"};;{"market":"0x865ac5b1fdc1706ca8cf0f25cc63544b5abcbb6819e25d52d9ac3ee4b3446726","price_changes":[{"asset_id":"35897145766259317849531537649732979331853484456543966713822507439506839868603","price":"0.39","size":"0","side":"BUY","hash":"2a4d21a37707745a05dcfa67b651c34eda496afd","best_bid":"0.51","best_ask":"0.53"},{"asset_id":"18124776046378286261632296176797913974857552946923528818498431780145315271239","price":"0.61","size":"0","side":"SELL","hash":"1cdfbfd654f47b4a10a33c3666c042176aa3c535","best_bid":"0.47","best_ask":"0.49"}],"timestamp":"1779223899538","event_type":"price_change"};;{"market":"0x865ac5b1fdc1706ca8cf0f25cc63544b5abcbb6819e25d52d9ac3ee4b3446726","price_changes":[{"asset_id":"35897145766259317849531537649732979331853484456543966713822507439506839868603","price":"0.45","size":"85","side":"BUY","hash":"2a4d21a37707745a05dcfa67b651c34eda496afd","best_bid":"0.51","best_ask":"0.53"},{"asset_id":"18124776046378286261632296176797913974857552946923528818498431780145315271239","price":"0.55","size":"85","side":"SELL","hash":"1cdfbfd654f47b4a10a33c3666c042176aa3c535","best_bid":"0.47","best_ask":"0.49"}],"timestamp":"1779223899538","event_type":"price_change"};;{"market":"0x865ac5b1fdc1706ca8cf0f25cc63544b5abcbb6819e25d52d9ac3ee4b3446726","price_changes":[{"asset_id":"35897145766259317849531537649732979331853484456543966713822507439506839868603","price":"0.32","size":"300","side":"BUY","hash":"2a4d21a37707745a05dcfa67b651c34eda496afd","best_bid":"0.51","best_ask":"0.53"},{"asset_id":"18124776046378286261632296176797913974857552946923528818498431780145315271239","price":"0.68","size":"300","side":"SELL","hash":"1cdfbfd654f47b4a10a33c3666c042176aa3c535","best_bid":"0.47","best_ask":"0.49"}],"timestamp":"1779223899538","event_type":"price_change"};;{"market":"0x865ac5b1fdc1706ca8cf0f25cc63544b5abcbb6819e25d52d9ac3ee4b3446726","price_changes":[{"asset_id":"35897145766259317849531537649732979331853484456543966713822507439506839868603","price":"0.54","size":"111.35","side":"SELL","hash":"4b11b01ae21b890b2e42ee37bd4b4f026c05b6a3","best_bid":"0.51","best_ask":"0.53"},{"asset_id":"18124776046378286261632296176797913974857552946923528818498431780145315271239","price":"0.46","size":"111.35","side":"BUY","hash":"b9f6e715d67e876c63705dfb0288673c9742e355","best_bid":"0.47","best_ask":"0.49"}],"timestamp":"1779223899551","event_type":"price_change"};;{"market":"0x865ac5b1fdc1706ca8cf0f25cc63544b5abcbb6819e25d52d9ac3ee4b3446726","price_changes":[{"asset_id":"18124776046378286261632296176797913974857552946923528818498431780145315271239","price":"0.46","size":"3.35","side":"BUY","hash":"883546c04839acc73b5a051fb3cd4ea43fcd5443","best_bid":"0.47","best_ask":"0.49"},{"asset_id":"35897145766259317849531537649732979331853484456543966713822507439506839868603","price":"0.54","size":"3.35","side":"SELL","hash":"d5b8c3fa6c8ad81efdb5d027ec70dc8959c21848","best_bid":"0.51","best_ask":"0.53"}],"timestamp":"1779223899551","event_type":"price_change"};;{"market":"0x865ac5b1fdc1706ca8cf0f25cc63544b5abcbb6819e25d52d9ac3ee4b3446726","price_changes":[{"asset_id":"35897145766259317849531537649732979331853484456543966713822507439506839868603","price":"0.36","size":"281","side":"BUY","hash":"635c3aa2c36b19e2b34f6211fef801fb3b69c4a5","best_bid":"0.51","best_ask":"0.53"},{"asset_id":"18124776046378286261632296176797913974857552946923528818498431780145315271239","price":"0.64","size":"281","side":"SELL","hash":"1b653c81200276662dd7dc453f9de1b850c947b6","best_bid":"0.47","best_ask":"0.49"}],"timestamp":"1779223899564","event_type":"price_change"};;{"market":"0x865ac5b1fdc1706ca8cf0f25cc63544b5abcbb6819e25d52d9ac3ee4b3446726","price_changes":[{"asset_id":"18124776046378286261632296176797913974857552946923528818498431780145315271239","price":"0.11","size":"1150","side":"BUY","hash":"875c80516bca2b6e4fcce4f0892594931588fc82","best_bid":"0.47","best_ask":"0.49"},{"asset_id":"35897145766259317849531537649732979331853484456543966713822507439506839868603","price":"0.89","size":"1150","side":"SELL","hash":"bb185afde93e964add873f6eb526f22ad449fbf8","best_bid":"0.51","best_ask":"0.53"}],"timestamp":"1779223899571","event_type":"price_change"};;{"market":"0x865ac5b1fdc1706ca8cf0f25cc63544b5abcbb6819e25d52d9ac3ee4b3446726","price_changes":[{"asset_id":"18124776046378286261632296176797913974857552946923528818498431780145315271239","price":"0.42","size":"222","side":"BUY","hash":"f824f79f5174e14ab1eece87fd572a479643268f","best_bid":"0.47","best_ask":"0.49"},{"asset_id":"35897145766259317849531537649732979331853484456543966713822507439506839868603","price":"0.58","size":"222","side":"SELL","hash":"70daccd3a098d06e1b4f9c4b8f89f4e862f55304","best_bid":"0.51","best_ask":"0.53"}],"timestamp":"1779223899578","event_type":"price_change"};;{"market":"0x865ac5b1fdc1706ca8cf0f25cc63544b5abcbb6819e25d52d9ac3ee4b3446726","price_changes":[{"asset_id":"18124776046378286261632296176797913974857552946923528818498431780145315271239","price":"0.41","size":"1287","side":"BUY","hash":"bd0da605726f9f4bbb7c13687f30cfae0778971e","best_bid":"0.47","best_ask":"0.49"},{"asset_id":"35897145766259317849531537649732979331853484456543966713822507439506839868603","price":"0.59","size":"1287","side":"SELL","hash":"efc89e0e0b98308430e2f4d08a986b4c57359e26","best_bid":"0.51","best_ask":"0.53"}],"timestamp":"1779223899581","event_type":"price_change"};;{"market":"0x865ac5b1fdc1706ca8cf0f25cc63544b5abcbb6819e25d52d9ac3ee4b3446726","price_changes":[{"asset_id":"18124776046378286261632296176797913974857552946923528818498431780145315271239","price":"0.42","size":"192","side":"BUY","hash":"c52462d79af15fba7f332ea5ba781476deaad42e","best_bid":"0.47","best_ask":"0.49"},{"asset_id":"35897145766259317849531537649732979331853484456543966713822507439506839868603","price":"0.58","size":"192","side":"SELL","hash":"7865b41e3036d7300f53ef901215e5ce233b011c","best_bid":"0.51","best_ask":"0.53"}],"timestamp":"1779223899582","event_type":"price_change"};;{"market":"0x865ac5b1fdc1706ca8cf0f25cc63544b5abcbb6819e25d52d9ac3ee4b3446726","price_changes":[{"asset_id":"18124776046378286261632296176797913974857552946923528818498431780145315271239","price":"0.4","size":"196","side":"BUY","hash":"8e1272781457f067fcfe42b738bc4e2d48a7beba","best_bid":"0.47","best_ask":"0.49"},{"asset_id":"35897145766259317849531537649732979331853484456543966713822507439506839868603","price":"0.6","size":"196","side":"SELL","hash":"cc25cc6dcc9722d3c7e9ec7a42ef979764ca636b","best_bid":"0.51","best_ask":"0.53"}],"timestamp":"1779223899583","event_type":"price_change"};;{"market":"0x865ac5b1fdc1706ca8cf0f25cc63544b5abcbb6819e25d52d9ac3ee4b3446726","price_changes":[{"asset_id":"18124776046378286261632296176797913974857552946923528818498431780145315271239","price":"0.41","size":"1297","side":"BUY","hash":"c69cf1648f222612ba581d1f9bbbf71dc8ccf4d9","best_bid":"0.47","best_ask":"0.49"},{"asset_id":"35897145766259317849531537649732979331853484456543966713822507439506839868603","price":"0.59","size":"1297","side":"SELL","hash":"78427860bdb6d6ec13cf4d3cf64b25aded5a51f6","best_bid":"0.51","best_ask":"0.53"}],"timestamp":"1779223899585","event_type":"price_change"};;{"market":"0xb99047b9bdf8132c367cf327936676a1186a6eb57b86a742fdfe812f86b2e3b9","price_changes":[{"asset_id":"101407360275578242025559123794924815546227269981219987932032932255334246314286","price":"0.14","size":"8591.15","side":"BUY","hash":"2c83abf31166be5fdd4bb398257be1ef99ea3a2c","best_bid":"0.8","best_ask":"0.81"},{"asset_id":"76150632180345500942617667303892128055275310542626568919906405357352468359168","price":"0.86","size":"8591.15","side":"SELL","hash":"ad452871fdd1d022ff3a21b0217a49707d4e6d27","best_bid":"0.19","best_ask":"0.2"}],"timestamp":"1779223899585","event_type":"price_change"};;{"market":"0x865ac5b1fdc1706ca8cf0f25cc63544b5abcbb6819e25d52d9ac3ee4b3446726","price_changes":[{"asset_id":"18124776046378286261632296176797913974857552946923528818498431780145315271239","price":"0.41","size":"1327","side":"BUY","hash":"27b65bdb7a6c0fb381782d15aca62aa4388c7346","best_bid":"0.47","best_ask":"0.49"},{"asset_id":"35897145766259317849531537649732979331853484456543966713822507439506839868603","price":"0.59","size":"1327","side":"SELL","hash":"0a7a9abe637a7e27730e7aec81664361ea4e1ee6","best_bid":"0.51","best_ask":"0.53"}],"timestamp":"1779223899592","event_type":"price_change"};;{"market":"0xb99047b9bdf8132c367cf327936676a1186a6eb57b86a742fdfe812f86b2e3b9","price_changes":[{"asset_id":"76150632180345500942617667303892128055275310542626568919906405357352468359168","price":"0.2","size":"10538.17","side":"SELL","hash":"1c476ff73ea29a5e5a33bf9e45aec643097b2fd0","best_bid":"0.19","best_ask":"0.2"},{"asset_id":"101407360275578242025559123794924815546227269981219987932032932255334246314286","price":"0.8","size":"10538.17","side":"BUY","hash":"dffbc3a37e0631e1143c15c1c240e642932ba17f","best_bid":"0.8","best_ask":"0.81"}],"timestamp":"1779223899623","event_type":"price_change"};;{"market":"0x865ac5b1fdc1706ca8cf0f25cc63544b5abcbb6819e25d52d9ac3ee4b3446726","asset_id":"35897145766259317849531537649732979331853484456543966713822507439506839868603","best_bid":"0.51","best_ask":"0.54","spread":"0.03","timestamp":"1779223899632","event_type":"best_bid_ask"};;{"market":"0x865ac5b1fdc1706ca8cf0f25cc63544b5abcbb6819e25d52d9ac3ee4b3446726","asset_id":"18124776046378286261632296176797913974857552946923528818498431780145315271239","best_bid":"0.46","best_ask":"0.49","spread":"0.03","timestamp":"1779223899632","event_type":"best_bid_ask"};;{"market":"0x865ac5b1fdc1706ca8cf0f25cc63544b5abcbb6819e25d52d9ac3ee4b3446726","price_changes":[{"asset_id":"18124776046378286261632296176797913974857552946923528818498431780145315271239","price":"0.47","size":"0","side":"BUY","hash":"f127b48abea2c7f3f079e4006b2de991a8639016","best_bid":"0.46","best_ask":"0.49"},{"asset_id":"35897145766259317849531537649732979331853484456543966713822507439506839868603","price":"0.53","size":"0","side":"SELL","hash":"b4f96ad2e78d9a1413ec3fafbf96d9e35931bc79","best_bid":"0.51","best_ask":"0.54"}],"timestamp":"1779223899632","event_type":"price_change"};;{"market":"0x865ac5b1fdc1706ca8cf0f25cc63544b5abcbb6819e25d52d9ac3ee4b3446726","price_changes":[{"asset_id":"35897145766259317849531537649732979331853484456543966713822507439506839868603","price":"0.42","size":"311.9","side":"BUY","hash":"2e9348f85f61b8713d895a8a07e0e24f3722e02a","best_bid":"0.51","best_ask":"0.54"},{"asset_id":"18124776046378286261632296176797913974857552946923528818498431780145315271239","price":"0.58","size":"311.9","side":"SELL","hash":"15b79fa8fcec2f7bceb53acb5fcc561193b16547","best_bid":"0.46","best_ask":"0.49"}],"timestamp":"1779223899632","event_type":"price_change"};;{"market":"0x865ac5b1fdc1706ca8cf0f25cc63544b5abcbb6819e25d52d9ac3ee4b3446726","price_changes":[{"asset_id":"35897145766259317849531537649732979331853484456543966713822507439506839868603","price":"0.42","size":"326.9","side":"BUY","hash":"a14b97f22eac90cb652b336f6b0ac988bc86a7d9","best_bid":"0.51","best_ask":"0.54"},{"asset_id":"18124776046378286261632296176797913974857552946923528818498431780145315271239","price":"0.58","size":"326.9","side":"SELL","hash":"4aed1af2e1e6e76bed00b1f20160ba315db31bed","best_bid":"0.46","best_ask":"0.49"}],"timestamp":"1779223899636","event_type":"price_change"};;{"market":"0x865ac5b1fdc1706ca8cf0f25cc63544b5abcbb6819e25d52d9ac3ee4b3446726","price_changes":[{"asset_id":"18124776046378286261632296176797913974857552946923528818498431780145315271239","price":"0.1","size":"4400","side":"BUY","hash":"46aec3cc4bbd748557a6f0a310943f0ad33b2156","best_bid":"0.46","best_ask":"0.49"},{"asset_id":"35897145766259317849531537649732979331853484456543966713822507439506839868603","price":"0.9","size":"4400","side":"SELL","hash":"d244581feb8db5769c2c403e791ee8131aafcdf1","best_bid":"0.51","best_ask":"0.54"}],"timestamp":"1779223899669","event_type":"price_change"};;{"market":"0x865ac5b1fdc1706ca8cf0f25cc63544b5abcbb6819e25d52d9ac3ee4b3446726","price_changes":[{"asset_id":"35897145766259317849531537649732979331853484456543966713822507439506839868603","price":"0.47","size":"261","side":"BUY","hash":"ba037f4acfd98d5f1ccab4594b4548bf49f9a1b8","best_bid":"0.51","best_ask":"0.54"},{"asset_id":"18124776046378286261632296176797913974857552946923528818498431780145315271239","price":"0.53","size":"261","side":"SELL","hash":"48c99c6e01209f1cd6200c18b67dd68903ab29ab","best_bid":"0.46","best_ask":"0.49"}],"timestamp":"1779223899696","event_type":"price_change"};;{"market":"0x8530b96422523df2024c4242021b58da538c5e94ba525e8f9893c3fc2f469160","price_changes":[{"asset_id":"91811271690939763569588501717168303099799014127066745654294854264052726562982","price":"0.31","size":"3287086.85","side":"BUY","hash":"99d8069a70806e0d025173af837854bd9a70ae23","best_bid":"0.31","best_ask":"0.32"},{"asset_id":"90341073610328513874226762002064133262679100936760740635957635490606188341771","price":"0.69","size":"3287086.85","side":"SELL","hash":"3fc078275ec964846debafe0d17b75add66da7ea","best_bid":"0.68","best_ask":"0.69"}],"timestamp":"1779223899734","event_type":"price_change"};;{"market":"0x865ac5b1fdc1706ca8cf0f25cc63544b5abcbb6819e25d52d9ac3ee4b3446726","price_changes":[{"asset_id":"18124776046378286261632296176797913974857552946923528818498431780145315271239","price":"0.46","size":"153.35","side":"BUY","hash":"585efea28385a8a06d41629c49d51d054f284f47","best_bid":"0.46","best_ask":"0.49"},{"asset_id":"35897145766259317849531537649732979331853484456543966713822507439506839868603","price":"0.54","size":"153.35","side":"SELL","hash":"6761ed805a2e8a1ba577eec920b0bc0225aa361f","best_bid":"0.51","best_ask":"0.54"}],"timestamp":"1779223899736","event_type":"price_change"};;{"market":"0x865ac5b1fdc1706ca8cf0f25cc63544b5abcbb6819e25d52d9ac3ee4b3446726","price_changes":[{"asset_id":"18124776046378286261632296176797913974857552946923528818498431780145315271239","price":"0.1","size":"3750","side":"BUY","hash":"92946b1092532965403aa0ecbe1f5b7adc5cfbed","best_bid":"0.46","best_ask":"0.49"},{"asset_id":"35897145766259317849531537649732979331853484456543966713822507439506839868603","price":"0.9","size":"3750","side":"SELL","hash":"9b8b9fb2644a8d96ab7f9c76f502f2b494e4a99a","best_bid":"0.51","best_ask":"0.54"}],"timestamp":"1779223899737","event_type":"price_change"};;{"market":"0xb99047b9bdf8132c367cf327936676a1186a6eb57b86a742fdfe812f86b2e3b9","price_changes":[{"asset_id":"101407360275578242025559123794924815546227269981219987932032932255334246314286","price":"0.77","size":"1731.17","side":"BUY","hash":"0633a2f713b395b628de250c1ea27b0f17cb3ff5","best_bid":"0.8","best_ask":"0.81"},{"asset_id":"76150632180345500942617667303892128055275310542626568919906405357352468359168","price":"0.23","size":"1731.17","side":"SELL","hash":"0874ad960ebb9ad385629ec26545646c154a3cab","best_bid":"0.19","best_ask":"0.2"}],"timestamp":"1779223899742","event_type":"price_change"};;{"market":"0x865ac5b1fdc1706ca8cf0f25cc63544b5abcbb6819e25d52d9ac3ee4b3446726","price_changes":[{"asset_id":"35897145766259317849531537649732979331853484456543966713822507439506839868603","price":"0.35","size":"30","side":"BUY","hash":"9d1427cb03bd4c5bae3a9ff80c8bbd4d7b7c3e23","best_bid":"0.51","best_ask":"0.54"},{"asset_id":"18124776046378286261632296176797913974857552946923528818498431780145315271239","price":"0.65","size":"30","side":"SELL","hash":"dc720aa01a27170275845a99ffd295cdd1afa4a8","best_bid":"0.46","best_ask":"0.49"}],"timestamp":"1779223899743","event_type":"price_change"};;{"market":"0x865ac5b1fdc1706ca8cf0f25cc63544b5abcbb6819e25d52d9ac3ee4b3446726","price_changes":[{"asset_id":"35897145766259317849531537649732979331853484456543966713822507439506839868603","price":"0.28","size":"360","side":"BUY","hash":"9014c9ca791c00ce1cd93b507366a65bdf698e08","best_bid":"0.51","best_ask":"0.54"},{"asset_id":"18124776046378286261632296176797913974857552946923528818498431780145315271239","price":"0.72","size":"360","side":"SELL","hash":"c28b48e389d443bfc5614d46773d10abdcc7defb","best_bid":"0.46","best_ask":"0.49"}],"timestamp":"1779223899750","event_type":"price_change"};;{"market":"0x8530b96422523df2024c4242021b58da538c5e94ba525e8f9893c3fc2f469160","price_changes":[{"asset_id":"90341073610328513874226762002064133262679100936760740635957635490606188341771","price":"0.68","size":"70280.07","side":"BUY","hash":"cb0967cb1e1e337de02bf58f5437c2fe90fa689c","best_bid":"0.68","best_ask":"0.69"},{"asset_id":"91811271690939763569588501717168303099799014127066745654294854264052726562982","price":"0.32","size":"70280.07","side":"SELL","hash":"6fef9a1e287402933679f48c14a839ba440cf370","best_bid":"0.31","best_ask":"0.32"}],"timestamp":"1779223899775","event_type":"price_change"};;{"market":"0x0e4a0c937b8934c2475613b6322b3f8edc8dedc24762e01e42b0e6f87424a089","price_changes":[{"asset_id":"72094069823942324362885404801938332659316240217382754851102758232469673300092","price":"0.07","size":"126935","side":"BUY","hash":"d9996d994f60e57b6111b0519c9c869e65d9863b","best_bid":"0.09","best_ask":"0.1"},{"asset_id":"42918220085288219341491829385501246298233444593663440094436147850542032590016","price":"0.93","size":"126935","side":"SELL","hash":"366bea8d68e6c5c8eb3b6e2de2cd985bac8ad058","best_bid":"0.9","best_ask":"0.91"}],"timestamp":"1779223899777","event_type":"price_change"};;{"market":"0x865ac5b1fdc1706ca8cf0f25cc63544b5abcbb6819e25d52d9ac3ee4b3446726","price_changes":[{"asset_id":"18124776046378286261632296176797913974857552946923528818498431780145315271239","price":"0.11","size":"850","side":"BUY","hash":"647fd5343116a9de9e5246fc122931084b773036","best_bid":"0.46","best_ask":"0.49"},{"asset_id":"35897145766259317849531537649732979331853484456543966713822507439506839868603","price":"0.89","size":"850","side":"SELL","hash":"910062b168b2312f5979f9584cfdd6ff99488e24","best_bid":"0.51","best_ask":"0.54"}],"timestamp":"1779223899780","event_type":"price_change"};;{"market":"0x865ac5b1fdc1706ca8cf0f25cc63544b5abcbb6819e25d52d9ac3ee4b3446726","price_changes":[{"asset_id":"18124776046378286261632296176797913974857552946923528818498431780145315271239","price":"0.21","size":"3679.15","side":"BUY","hash":"647fd5343116a9de9e5246fc122931084b773036","best_bid":"0.46","best_ask":"0.49"},{"asset_id":"35897145766259317849531537649732979331853484456543966713822507439506839868603","price":"0.79","size":"3679.15","side":"SELL","hash":"910062b168b2312f5979f9584cfdd6ff99488e24","best_bid":"0.51","best_ask":"0.54"}],"timestamp":"1779223899780","event_type":"price_change"};;{"market":"0x865ac5b1fdc1706ca8cf0f25cc63544b5abcbb6819e25d52d9ac3ee4b3446726","price_changes":[{"asset_id":"35897145766259317849531537649732979331853484456543966713822507439506839868603","price":"0.08","size":"1400","side":"BUY","hash":"62ad16b7afd3ccde51da8394cbbab5ee7bd39097","best_bid":"0.51","best_ask":"0.54"},{"asset_id":"18124776046378286261632296176797913974857552946923528818498431780145315271239","price":"0.92","size":"1400","side":"SELL","hash":"6b8ceb97cc9b5a567d3b15d5ba2d2bf6479d20de","best_bid":"0.46","best_ask":"0.49"}],"timestamp":"1779223899780","event_type":"price_change"};;{"market":"0xb99047b9bdf8132c367cf327936676a1186a6eb57b86a742fdfe812f86b2e3b9","price_changes":[{"asset_id":"101407360275578242025559123794924815546227269981219987932032932255334246314286","price":"0.8","size":"10533.17","side":"BUY","hash":"f7c40cad898cdf0bc3b641a8e20f0e920cdadad5","best_bid":"0.8","best_ask":"0.81"},{"asset_id":"76150632180345500942617667303892128055275310542626568919906405357352468359168","price":"0.2","size":"10533.17","side":"SELL","hash":"b188c5c1c5d68309f9bc01dca559c566fd3f812c","best_bid":"0.19","best_ask":"0.2"}],"timestamp":"1779223899794","event_type":"price_change"};;{"market":"0x865ac5b1fdc1706ca8cf0f25cc63544b5abcbb6819e25d52d9ac3ee4b3446726","price_changes":[{"asset_id":"35897145766259317849531537649732979331853484456543966713822507439506839868603","price":"0.11","size":"3330","side":"BUY","hash":"e7e4a1feed7caf220cbd362238379727c925baf4","best_bid":"0.51","best_ask":"0.54"},{"asset_id":"18124776046378286261632296176797913974857552946923528818498431780145315271239","price":"0.89","size":"3330","side":"SELL","hash":"a77adaa17878070d1536f3814490eecfb58cc524","best_bid":"0.46","best_ask":"0.49"}],"timestamp":"1779223899864","event_type":"price_change"};;{"market":"0xb99047b9bdf8132c367cf327936676a1186a6eb57b86a742fdfe812f86b2e3b9","price_changes":[{"asset_id":"101407360275578242025559123794924815546227269981219987932032932255334246314286","price":"0.12","size":"12469.15","side":"BUY","hash":"c301e21d09819a883c1c36c1be7dabd0eb293b37","best_bid":"0.8","best_ask":"0.81"},{"asset_id":"76150632180345500942617667303892128055275310542626568919906405357352468359168","price":"0.88","size":"12469.15","side":"SELL","hash":"4303acf5420fc7dc7437359e16cfaae3f975b3e5","best_bid":"0.19","best_ask":"0.2"}],"timestamp":"1779223899870","event_type":"price_change"};;{"market":"0xb99047b9bdf8132c367cf327936676a1186a6eb57b86a742fdfe812f86b2e3b9","price_changes":[{"asset_id":"101407360275578242025559123794924815546227269981219987932032932255334246314286","price":"0.19","size":"1700","side":"BUY","hash":"c301e21d09819a883c1c36c1be7dabd0eb293b37","best_bid":"0.8","best_ask":"0.81"},{"asset_id":"76150632180345500942617667303892128055275310542626568919906405357352468359168","price":"0.81","size":"1700","side":"SELL","hash":"4303acf5420fc7dc7437359e16cfaae3f975b3e5","best_bid":"0.19","best_ask":"0.2"}],"timestamp":"1779223899870","event_type":"price_change"};;{"market":"0x865ac5b1fdc1706ca8cf0f25cc63544b5abcbb6819e25d52d9ac3ee4b3446726","price_changes":[{"asset_id":"18124776046378286261632296176797913974857552946923528818498431780145315271239","price":"0.1","size":"4050","side":"BUY","hash":"e018acbd43241fa9132e63f967a592665f5f352d","best_bid":"0.46","best_ask":"0.49"},{"asset_id":"35897145766259317849531537649732979331853484456543966713822507439506839868603","price":"0.9","size":"4050","side":"SELL","hash":"c1e9c4cd96ce3c7c26078b5de3c91da93008be51","best_bid":"0.51","best_ask":"0.54"}],"timestamp":"1779223899873","event_type":"price_change"};;{"market":"0xb99047b9bdf8132c367cf327936676a1186a6eb57b86a742fdfe812f86b2e3b9","price_changes":[{"asset_id":"76150632180345500942617667303892128055275310542626568919906405357352468359168","price":"0.2","size":"10743.17","side":"SELL","hash":"46d44fd03849b13988a7cf72d3c09d64c63479b7","best_bid":"0.19","best_ask":"0.2"},{"asset_id":"101407360275578242025559123794924815546227269981219987932032932255334246314286","price":"0.8","size":"10743.17","side":"BUY","hash":"5145be2358a97c9a065e8cb91c19edc02d038d93","best_bid":"0.8","best_ask":"0.81"}],"timestamp":"1779223899889","event_type":"price_change"};;{"market":"0x865ac5b1fdc1706ca8cf0f25cc63544b5abcbb6819e25d52d9ac3ee4b3446726","price_changes":[{"asset_id":"35897145766259317849531537649732979331853484456543966713822507439506839868603","price":"0.08","size":"1000","side":"BUY","hash":"420a8c84496e6241f1df0aeb78c570d704e289a9","best_bid":"0.51","best_ask":"0.54"},{"asset_id":"18124776046378286261632296176797913974857552946923528818498431780145315271239","price":"0.92","size":"1000","side":"SELL","hash":"8e191b031c3d859b2b067494a9adc00d151c343a","best_bid":"0.46","best_ask":"0.49"}],"timestamp":"1779223899909","event_type":"price_change"};;{"market":"0xb99047b9bdf8132c367cf327936676a1186a6eb57b86a742fdfe812f86b2e3b9","price_changes":[{"asset_id":"101407360275578242025559123794924815546227269981219987932032932255334246314286","price":"0.78","size":"6069.17","side":"BUY","hash":"13ff14a255240ed0d9c6cd314950df19b01062b7","best_bid":"0.8","best_ask":"0.81"},{"asset_id":"76150632180345500942617667303892128055275310542626568919906405357352468359168","price":"0.22","size":"6069.17","side":"SELL","hash":"ef09011202d6563c51232cfb36c084c86109d48c","best_bid":"0.19","best_ask":"0.2"}],"timestamp":"1779223899951","event_type":"price_change"};;{"market":"0x865ac5b1fdc1706ca8cf0f25cc63544b5abcbb6819e25d52d9ac3ee4b3446726","price_changes":[{"asset_id":"35897145766259317849531537649732979331853484456543966713822507439506839868603","price":"0.08","size":"500","side":"BUY","hash":"dd3ec2907264378e29c0c9170e55ea48bef210c7","best_bid":"0.51","best_ask":"0.54"},{"asset_id":"18124776046378286261632296176797913974857552946923528818498431780145315271239","price":"0.92","size":"500","side":"SELL","hash":"0b5c51256a5322cb7483341f69fb21b68fb32496","best_bid":"0.46","best_ask":"0.49"}],"timestamp":"1779223899978","event_type":"price_change"};;{"market":"0xb99047b9bdf8132c367cf327936676a1186a6eb57b86a742fdfe812f86b2e3b9","price_changes":[{"asset_id":"101407360275578242025559123794924815546227269981219987932032932255334246314286","price":"0.19","size":"1400","side":"BUY","hash":"c0e6dc40cd9f1da24cd523dfd40f0b0aa78517d7","best_bid":"0.8","best_ask":"0.81"},{"asset_id":"76150632180345500942617667303892128055275310542626568919906405357352468359168","price":"0.81","size":"1400","side":"SELL","hash":"cf015727bd69d4d80c359a1dd3343d6dbdb95088","best_bid":"0.19","best_ask":"0.2"}],"timestamp":"1779223899977","event_type":"price_change"};;{"market":"0x865ac5b1fdc1706ca8cf0f25cc63544b5abcbb6819e25d52d9ac3ee4b3446726","price_changes":[{"asset_id":"18124776046378286261632296176797913974857552946923528818498431780145315271239","price":"0.11","size":"1500","side":"BUY","hash":"63ffca4b9d0213a75e25e0e928f4e39fb8c5b8a9","best_bid":"0.46","best_ask":"0.49"},{"asset_id":"35897145766259317849531537649732979331853484456543966713822507439506839868603","price":"0.89","size":"1500","side":"SELL","hash":"3d7a279da255322a00ee6c3b10b2e6fc5dc7586f","best_bid":"0.51","best_ask":"0.54"}],"timestamp":"1779223899986","event_type":"price_change"};;{"market":"0x865ac5b1fdc1706ca8cf0f25cc63544b5abcbb6819e25d52d9ac3ee4b3446726","price_changes":[{"asset_id":"18124776046378286261632296176797913974857552946923528818498431780145315271239","price":"0.41","size":"1317","side":"BUY","hash":"b8d5add4bc70aaa72a09d100bb06c841b7c7aede","best_bid":"0.46","best_ask":"0.49"},{"asset_id":"35897145766259317849531537649732979331853484456543966713822507439506839868603","price":"0.59","size":"1317","side":"SELL","hash":"5ecf849799f68443f8964d80d3bcc217dde4ac0d","best_bid":"0.51","best_ask":"0.54"}],"timestamp":"1779223900050","event_type":"price_change"};;{"market":"0x865ac5b1fdc1706ca8cf0f25cc63544b5abcbb6819e25d52d9ac3ee4b3446726","price_changes":[{"asset_id":"18124776046378286261632296176797913974857552946923528818498431780145315271239","price":"0.4","size":"156","side":"BUY","hash":"94b0bbaf6d5194749584b8c85b412ba5413fc187","best_bid":"0.46","best_ask":"0.49"},{"asset_id":"35897145766259317849531537649732979331853484456543966713822507439506839868603","price":"0.6","size":"156","side":"SELL","hash":"678da3dd5ef70c2202ac743286f3733d0d3059f8","best_bid":"0.51","best_ask":"0.54"}],"timestamp":"1779223900053","event_type":"price_change"};;{"market":"0x865ac5b1fdc1706ca8cf0f25cc63544b5abcbb6819e25d52d9ac3ee4b3446726","price_changes":[{"asset_id":"18124776046378286261632296176797913974857552946923528818498431780145315271239","price":"0.42","size":"202","side":"BUY","hash":"c3f5f530947ddb56f1fd613b65716cd94459c47f","best_bid":"0.46","best_ask":"0.49"},{"asset_id":"35897145766259317849531537649732979331853484456543966713822507439506839868603","price":"0.58","size":"202","side":"SELL","hash":"7da0eba924bd701a14e640a2078db72f2085fc48","best_bid":"0.51","best_ask":"0.54"}],"timestamp":"1779223900055","event_type":"price_change"};;{"market":"0x865ac5b1fdc1706ca8cf0f25cc63544b5abcbb6819e25d52d9ac3ee4b3446726","price_changes":[{"asset_id":"18124776046378286261632296176797913974857552946923528818498431780145315271239","price":"0.41","size":"1357","side":"BUY","hash":"f1742720a4ef759dcfe8e4c67f11500b20c699a0","best_bid":"0.46","best_ask":"0.49"},{"asset_id":"35897145766259317849531537649732979331853484456543966713822507439506839868603","price":"0.59","size":"1357","side":"SELL","hash":"4e508be36fb5f45840e799613b1dcf6155906ac3","best_bid":"0.51","best_ask":"0.54"}],"timestamp":"1779223900055","event_type":"price_change"};;{"market":"0xb99047b9bdf8132c367cf327936676a1186a6eb57b86a742fdfe812f86b2e3b9","price_changes":[{"asset_id":"101407360275578242025559123794924815546227269981219987932032932255334246314286","price":"0.6","size":"1092","side":"BUY","hash":"e1f5c8ded3ef0c26dcc7915c8474a62c10ff1477","best_bid":"0.8","best_ask":"0.81"},{"asset_id":"76150632180345500942617667303892128055275310542626568919906405357352468359168","price":"0.4","size":"1092","side":"SELL","hash":"102cf39eebc404b1ee73a9dd4eea354484fa81b9","best_bid":"0.19","best_ask":"0.2"}],"timestamp":"1779223900057","event_type":"price_change"};;{"market":"0xb99047b9bdf8132c367cf327936676a1186a6eb57b86a742fdfe812f86b2e3b9","price_changes":[{"asset_id":"101407360275578242025559123794924815546227269981219987932032932255334246314286","price":"0.84","size":"4021.39","side":"SELL","hash":"0e0a5e1703f21ce4fe0e0d54f0c0fdac326d57a1","best_bid":"0.8","best_ask":"0.81"},{"asset_id":"76150632180345500942617667303892128055275310542626568919906405357352468359168","price":"0.16","size":"4021.39","side":"BUY","hash":"841cd990164688f3b112126180270f0568a7c5f9","best_bid":"0.19","best_ask":"0.2"}],"timestamp":"1779223900059","event_type":"price_change"};;{"market":"0xb99047b9bdf8132c367cf327936676a1186a6eb57b86a742fdfe812f86b2e3b9","price_changes":[{"asset_id":"101407360275578242025559123794924815546227269981219987932032932255334246314286","price":"0.8","size":"10943.17","side":"BUY","hash":"91d66256b31b39c2c64e8180614aa9c98806e8fc","best_bid":"0.8","best_ask":"0.81"},{"asset_id":"76150632180345500942617667303892128055275310542626568919906405357352468359168","price":"0.2","size":"10943.17","side":"SELL","hash":"03075377e8cec4ae362bf4ccce475d7880da672c","best_bid":"0.19","best_ask":"0.2"}],"timestamp":"1779223900061","event_type":"price_change"};;{"payload":{"data":[{"timestamp":1779223781000,"value":403.67061},{"timestamp":1779223782000,"value":403.67122},{"timestamp":1779223783000,"value":403.6702},{"timestamp":1779223784000,"value":403.6702},{"timestamp":1779223785000,"value":403.67081},{"timestamp":1779223786000,"value":403.67021},{"timestamp":1779223787000,"value":403.67081},{"timestamp":1779223788000,"value":403.67101},{"timestamp":1779223789000,"value":403.67102},{"timestamp":1779223790000,"value":403.67081},{"timestamp":1779223791000,"value":403.67},{"timestamp":1779223792000,"value":403.67},{"timestamp":1779223793000,"value":403.67},{"timestamp":1779223794000,"value":403.67},{"timestamp":1779223795000,"value":403.67},{"timestamp":1779223796000,"value":403.66997},{"timestamp":1779223797000,"value":403.67},{"timestamp":1779223798000,"value":403.66979},{"timestamp":1779223799000,"value":403.6552},{"timestamp":1779223800000,"value":403.655},{"timestamp":1779223801000,"value":403.655},{"timestamp":1779223802000,"value":403.655},{"timestamp":1779223803000,"value":403.655},{"timestamp":1779223804000,"value":403.65641},{"timestamp":1779223805000,"value":403.655},{"timestamp":1779223806000,"value":403.66524},{"timestamp":1779223807000,"value":403.66504},{"timestamp":1779223808000,"value":403.665},{"timestamp":1779223809000,"value":403.66501},{"timestamp":1779223810000,"value":403.665},{"timestamp":1779223811000,"value":403.67003},{"timestamp":1779223812000,"value":403.67},{"timestamp":1779223813000,"value":403.67},{"timestamp":1779223814000,"value":403.67},{"timestamp":1779223815000,"value":403.67},{"timestamp":1779223816000,"value":403.67},{"timestamp":1779223817000,"value":403.67001},{"timestamp":1779223818000,"value":403.67},{"timestamp":1779223819000,"value":403.67},{"timestamp":1779223820000,"value":403.67},{"timestamp":1779223821000,"value":403.67},{"timestamp":1779223822000,"value":403.67},{"timestamp":1779223823000,"value":403.67},{"timestamp":1779223824000,"value":403.67},{"timestamp":1779223825000,"value":403.6698},{"timestamp":1779223826000,"value":403.67},{"timestamp":1779223827000,"value":403.66997},{"timestamp":1779223828000,"value":403.6696},{"timestamp":1779223829000,"value":403.67},{"timestamp":1779223830000,"value":403.66959},{"timestamp":1779223831000,"value":403.67},{"timestamp":1779223832000,"value":403.67},{"timestamp":1779223833000,"value":403.66995},{"timestamp":1779223834000,"value":403.66995},{"timestamp":1779223835000,"value":403.67},{"timestamp":1779223836000,"value":403.66999},{"timestamp":1779223837000,"value":403.6698},{"timestamp":1779223838000,"value":403.67},{"timestamp":1779223839000,"value":403.67},{"timestamp":1779223840000,"value":403.67},{"timestamp":1779223841000,"value":403.67},{"timestamp":1779223842000,"value":403.67},{"timestamp":1779223843000,"value":403.67},{"timestamp":1779223844000,"value":403.67},{"timestamp":1779223845000,"value":403.6704},{"timestamp":1779223846000,"value":403.67},{"timestamp":1779223847000,"value":403.67},{"timestamp":1779223848000,"value":403.67004},{"timestamp":1779223849000,"value":403.67001},{"timestamp":1779223850000,"value":403.6702},{"timestamp":1779223851000,"value":403.66996},{"timestamp":1779223852000,"value":403.67},{"timestamp":1779223853000,"value":403.66995},{"timestamp":1779223854000,"value":403.67},{"timestamp":1779223855000,"value":403.67065},{"timestamp":1779223856000,"value":403.67},{"timestamp":1779223857000,"value":403.67},{"timestamp":1779223858000,"value":403.67},{"timestamp":1779223859000,"value":403.675},{"timestamp":1779223860000,"value":403.67584},{"timestamp":1779223861000,"value":403.67504},{"timestamp":1779223862000,"value":403.6752},{"timestamp":1779223863000,"value":403.67544},{"timestamp":1779223864000,"value":403.6752},{"timestamp":1779223865000,"value":403.67502},{"timestamp":1779223866000,"value":403.675},{"timestamp":1779223867000,"value":403.6752},{"timestamp":1779223868000,"value":403.67541},{"timestamp":1779223869000,"value":403.67585},{"timestamp":1779223870000,"value":403.67603},{"timestamp":1779223871000,"value":403.67505},{"timestamp":1779223872000,"value":403.67502},{"timestamp":1779223873000,"value":403.67581},{"timestamp":1779223874000,"value":403.67603},{"timestamp":1779223875000,"value":403.675},{"timestamp":1779223876000,"value":403.67581},{"timestamp":1779223877000,"value":403.675},{"timestamp":1779223878000,"value":403.675},{"timestamp":1779223879000,"value":403.67642},{"timestamp":1779223880000,"value":403.675},{"timestamp":1779223881000,"value":403.67561},{"timestamp":1779223882000,"value":403.67601},{"timestamp":1779223883000,"value":403.67581},{"timestamp":1779223884000,"value":403.675},{"timestamp":1779223885000,"value":403.67601},{"timestamp":1779223886000,"value":403.65504},{"timestamp":1779223887000,"value":403.6556},{"timestamp":1779223888000,"value":403.655},{"timestamp":1779223889000,"value":403.65605},{"timestamp":1779223890000,"value":403.655},{"timestamp":1779223891000,"value":403.65581},{"timestamp":1779223892000,"value":403.67564},{"timestamp":1779223893000,"value":403.67541},{"timestamp":1779223894000,"value":403.67662},{"timestamp":1779223895000,"value":403.67642},{"timestamp":1779223896000,"value":403.67525},{"timestamp":1779223897000,"value":403.67502},{"timestamp":1779223898000,"value":403.67581},{"timestamp":1779223899000,"value":403.66582},{"timestamp":1779223900000,"value":403.6652}],"symbol":"tsla"},"timestamp":1779223900291,"topic":"equity_prices","type":"subscribe"};;{"payload":{"data":[{"timestamp":1779223841000,"value":76924.1245},{"timestamp":1779223842000,"value":76924.59027},{"timestamp":1779223843000,"value":76926.318615},{"timestamp":1779223844000,"value":76924.58923},{"timestamp":1779223845000,"value":76924.57929},{"timestamp":1779223846000,"value":76924.07507},{"timestamp":1779223848000,"value":76923.251},{"timestamp":1779223849000,"value":76923.252},{"timestamp":1779223850000,"value":76923.252},{"timestamp":1779223851000,"value":76923.70642},{"timestamp":1779223852000,"value":76923.85},{"timestamp":1779223853000,"value":76924.33472},{"timestamp":1779223854000,"value":76925.33796},{"timestamp":1779223855000,"value":76925.5327},{"timestamp":1779223856000,"value":76925.52875},{"timestamp":1779223857000,"value":76925.62579},{"timestamp":1779223858000,"value":76925.66709},{"timestamp":1779223859000,"value":76926.32283},{"timestamp":1779223860000,"value":76926.31914},{"timestamp":1779223861000,"value":76926.31142},{"timestamp":1779223862000,"value":76927.36682},{"timestamp":1779223863000,"value":76927.26704},{"timestamp":1779223864000,"value":76927.51101},{"timestamp":1779223865000,"value":76928.08394},{"timestamp":1779223866000,"value":76928.20221},{"timestamp":1779223867000,"value":76928.20235},{"timestamp":1779223869000,"value":76928.05631},{"timestamp":1779223870000,"value":76928.11974},{"timestamp":1779223871000,"value":76928.11133},{"timestamp":1779223872000,"value":76928.0997},{"timestamp":1779223873000,"value":76928.10292},{"timestamp":1779223874000,"value":76928.14093},{"timestamp":1779223875000,"value":76929.20860627764},{"timestamp":1779223876000,"value":76929.245385},{"timestamp":1779223877000,"value":76928.27397},{"timestamp":1779223878000,"value":76929.33611197202},{"timestamp":1779223879000,"value":76929.36297338035},{"timestamp":1779223880000,"value":76928.28153},{"timestamp":1779223881000,"value":76929.04339},{"timestamp":1779223882000,"value":76929.04339},{"timestamp":1779223883000,"value":76929.8263331943},{"timestamp":1779223884000,"value":76928.52829},{"timestamp":1779223885000,"value":76929.28591228442},{"timestamp":1779223886000,"value":76929.52471831422},{"timestamp":1779223887000,"value":76929.60896563958},{"timestamp":1779223888000,"value":76929.92317},{"timestamp":1779223889000,"value":76930.07792},{"timestamp":1779223890000,"value":76930.06599},{"timestamp":1779223891000,"value":76930.46134},{"timestamp":1779223892000,"value":76930.75967},{"timestamp":1779223893000,"value":76930.55312335232},{"timestamp":1779223894000,"value":76930.32148744808},{"timestamp":1779223895000,"value":76930.38535628826},{"timestamp":1779223896000,"value":76930.41319675135},{"timestamp":1779223897000,"value":76930.30703},{"timestamp":1779223898000,"value":76930.35467032954},{"timestamp":1779223899000,"value":76930.81084}],"symbol":"btc/usd"},"timestamp":1779223900291,"topic":"crypto_prices","type":"subscribe"};;{"payload":{"data":[{"timestamp":1779223781000,"value":298.67},{"timestamp":1779223782000,"value":298.66996},{"timestamp":1779223783000,"value":298.66954},{"timestamp":1779223784000,"value":298.67},{"timestamp":1779223785000,"value":298.6353},{"timestamp":1779223786000,"value":298.63485},{"timestamp":1779223787000,"value":298.635},{"timestamp":1779223788000,"value":298.63563},{"timestamp":1779223789000,"value":298.63503},{"timestamp":1779223790000,"value":298.635},{"timestamp":1779223791000,"value":298.635},{"timestamp":1779223792000,"value":298.63502},{"timestamp":1779223793000,"value":298.63503},{"timestamp":1779223794000,"value":298.63498},{"timestamp":1779223795000,"value":298.635},{"timestamp":1779223796000,"value":298.63503},{"timestamp":1779223797000,"value":298.63503},{"timestamp":1779223798000,"value":298.67499},{"timestamp":1779223799000,"value":298.67499},{"timestamp":1779223800000,"value":298.67499},{"timestamp":1779223801000,"value":298.67503},{"timestamp":1779223802000,"value":298.67499},{"timestamp":1779223803000,"value":298.67496},{"timestamp":1779223804000,"value":298.67499},{"timestamp":1779223805000,"value":298.67497},{"timestamp":1779223806000,"value":298.67499},{"timestamp":1779223807000,"value":298.67503},{"timestamp":1779223808000,"value":298.67499},{"timestamp":1779223809000,"value":298.67515},{"timestamp":1779223810000,"value":298.67499},{"timestamp":1779223811000,"value":298.67494},{"timestamp":1779223812000,"value":298.67501},{"timestamp":1779223813000,"value":298.67501},{"timestamp":1779223814000,"value":298.67501},{"timestamp":1779223815000,"value":298.67502},{"timestamp":1779223816000,"value":298.67499},{"timestamp":1779223817000,"value":298.67502},{"timestamp":1779223818000,"value":298.67519},{"timestamp":1779223819000,"value":298.6756},{"timestamp":1779223820000,"value":298.67501},{"timestamp":1779223821000,"value":298.6753},{"timestamp":1779223822000,"value":298.67501},{"timestamp":1779223823000,"value":298.67515},{"timestamp":1779223824000,"value":298.67494},{"timestamp":1779223825000,"value":298.67501},{"timestamp":1779223826000,"value":298.6753},{"timestamp":1779223827000,"value":298.67499},{"timestamp":1779223828000,"value":298.67499},{"timestamp":1779223829000,"value":298.67545},{"timestamp":1779223830000,"value":298.67504},{"timestamp":1779223831000,"value":298.67518},{"timestamp":1779223832000,"value":298.67515},{"timestamp":1779223833000,"value":298.6753},{"timestamp":1779223834000,"value":298.675},{"timestamp":1779223835000,"value":298.67499},{"timestamp":1779223836000,"value":298.67501},{"timestamp":1779223837000,"value":298.67499},{"timestamp":1779223838000,"value":298.67499},{"timestamp":1779223839000,"value":298.67501},{"timestamp":1779223840000,"value":298.6753},{"timestamp":1779223841000,"value":298.67498},{"timestamp":1779223842000,"value":298.67499},{"timestamp":1779223843000,"value":298.67545},{"timestamp":1779223844000,"value":298.67548},{"timestamp":1779223845000,"value":298.67495},{"timestamp":1779223846000,"value":298.67499},{"timestamp":1779223847000,"value":298.67501},{"timestamp":1779223848000,"value":298.67499},{"timestamp":1779223849000,"value":298.6747},{"timestamp":1779223850000,"value":298.67502},{"timestamp":1779223851000,"value":298.67495},{"timestamp":1779223852000,"value":298.67499},{"timestamp":1779223853000,"value":298.67442},{"timestamp":1779223854000,"value":298.67498},{"timestamp":1779223855000,"value":298.67469},{"timestamp":1779223856000,"value":298.67457},{"timestamp":1779223857000,"value":298.6744},{"timestamp":1779223858000,"value":298.67941},{"timestamp":1779223859000,"value":298.67956},{"timestamp":1779223860000,"value":298.67971},{"timestamp":1779223861000,"value":298.67882},{"timestamp":1779223862000,"value":298.67957},{"timestamp":1779223863000,"value":298.67982},{"timestamp":1779223864000,"value":298.67981},{"timestamp":1779223865000,"value":298.68},{"timestamp":1779223866000,"value":298.67999},{"timestamp":1779223867000,"value":298.67997},{"timestamp":1779223868000,"value":298.67998},{"timestamp":1779223869000,"value":298.67951},{"timestamp":1779223870000,"value":298.67995},{"timestamp":1779223871000,"value":298.67967},{"timestamp":1779223872000,"value":298.67941},{"timestamp":1779223873000,"value":298.67966},{"timestamp":1779223874000,"value":298.67971},{"timestamp":1779223875000,"value":298.6797},{"timestamp":1779223876000,"value":298.68},{"timestamp":1779223877000,"value":298.67984},{"timestamp":1779223878000,"value":298.68},{"timestamp":1779223879000,"value":298.67956},{"timestamp":1779223880000,"value":298.67986},{"timestamp":1779223881000,"value":298.67954},{"timestamp":1779223882000,"value":298.67955},{"timestamp":1779223883000,"value":298.67957},{"timestamp":1779223884000,"value":298.67969},{"timestamp":1779223885000,"value":298.67966},{"timestamp":1779223886000,"value":298.67969},{"timestamp":1779223887000,"value":298.67927},{"timestamp":1779223888000,"value":298.6794},{"timestamp":1779223889000,"value":298.67995},{"timestamp":1779223890000,"value":298.67982},{"timestamp":1779223891000,"value":298.67952},{"timestamp":1779223892000,"value":298.67997},{"timestamp":1779223893000,"value":298.67941},{"timestamp":1779223894000,"value":298.67941},{"timestamp":1779223895000,"value":298.67995},{"timestamp":1779223896000,"value":298.67912},{"timestamp":1779223897000,"value":298.67997},{"timestamp":1779223898000,"value":298.67998},{"timestamp":1779223899000,"value":298.68},{"timestamp":1779223900000,"value":298.67984}],"symbol":"aapl"},"timestamp":1779223900292,"topic":"equity_prices","type":"subscribe"};;{"connection_id":"connection-id","payload":{"full_accuracy_value":"298.67985","received_at":1779223901000,"symbol":"aapl","timestamp":1779223901000,"value":298.67985},"timestamp":1779223901202,"topic":"equity_prices","type":"update"};;{"connection_id":"connection-id","payload":{"full_accuracy_value":"76930941301885385000000","symbol":"btc/usd","timestamp":1779223900000,"value":76930.94130188538},"timestamp":1779223901136,"topic":"crypto_prices_chainlink","type":"update"};;{"connection_id":"connection-id","payload":{"full_accuracy_value":"298.67897","received_at":1779223902000,"symbol":"aapl","timestamp":1779223902000,"value":298.67897},"timestamp":1779223902201,"topic":"equity_prices","type":"update"};;{"connection_id":"connection-id","payload":{"full_accuracy_value":"76930941195000000000000","symbol":"btc/usd","timestamp":1779223901000,"value":76930.941195},"timestamp":1779223902363,"topic":"crypto_prices_chainlink","type":"update"};;{"connection_id":"connection-id","payload":{"full_accuracy_value":"76930940930000000000000","symbol":"btc/usd","timestamp":1779223902000,"value":76930.94093},"timestamp":1779223902931,"topic":"crypto_prices_chainlink","type":"update"};;{"connection_id":"connection-id","payload":{"full_accuracy_value":"298.67982","received_at":1779223903000,"symbol":"aapl","timestamp":1779223903000,"value":298.67982},"timestamp":1779223903224,"topic":"equity_prices","type":"update"};;{"connection_id":"connection-id","payload":{"full_accuracy_value":"76931586431502570000000","symbol":"btc/usd","timestamp":1779223903000,"value":76931.58643150257},"timestamp":1779223904096,"topic":"crypto_prices_chainlink","type":"update"};;{"connection_id":"connection-id","payload":{"full_accuracy_value":"298.67971","received_at":1779223904000,"symbol":"aapl","timestamp":1779223904000,"value":298.67971},"timestamp":1779223904201,"topic":"equity_prices","type":"update"};;{"connection_id":"connection-id","payload":{"full_accuracy_value":"298.67997","received_at":1779223905000,"symbol":"aapl","timestamp":1779223905000,"value":298.67997},"timestamp":1779223905201,"topic":"equity_prices","type":"update"};;{"connection_id":"connection-id","payload":{"full_accuracy_value":"76929866540000000000000","symbol":"btc/usd","timestamp":1779223904000,"value":76929.86654},"timestamp":1779223905638,"topic":"crypto_prices_chainlink","type":"update"};;{"connection_id":"connection-id","payload":{"body":"sample comment body","createdAt":"2026-05-19T20:51:45.824328Z","id":"sample-comment-id","parentEntityID":10114,"parentEntityType":"Series","profile":{"baseAddress":"0x0000000000000000000000000000000000000000","displayUsernamePublic":false,"name":"sample-user","proxyWallet":"0x0000000000000000000000000000000000000000","pseudonym":"sample-user"},"reactionCount":0,"reportCount":0,"userAddress":"0x0000000000000000000000000000000000000000"},"timestamp":1779223905830,"topic":"comments","type":"comment_created"};;{"connection_id":"connection-id","payload":{"full_accuracy_value":"298.67956","received_at":1779223906000,"symbol":"aapl","timestamp":1779223906000,"value":298.67956},"timestamp":1779223906200,"topic":"equity_prices","type":"update"};;{"connection_id":"connection-id","payload":{"full_accuracy_value":"76930840629487345000000","symbol":"btc/usd","timestamp":1779223905000,"value":76930.84062948734},"timestamp":1779223906268,"topic":"crypto_prices_chainlink","type":"update"};;{"connection_id":"connection-id","payload":{"full_accuracy_value":"76930855017252830000000","symbol":"btc/usd","timestamp":1779223906000,"value":76930.85501725283},"timestamp":1779223907092,"topic":"crypto_prices_chainlink","type":"update"};;{"connection_id":"connection-id","payload":{"full_accuracy_value":"298.67999","received_at":1779223907000,"symbol":"aapl","timestamp":1779223907000,"value":298.67999},"timestamp":1779223907202,"topic":"equity_prices","type":"update"};;{"connection_id":"connection-id","payload":{"full_accuracy_value":"298.67995","received_at":1779223908000,"symbol":"aapl","timestamp":1779223908000,"value":298.67995},"timestamp":1779223908200,"topic":"equity_prices","type":"update"};;{"connection_id":"connection-id","payload":{"full_accuracy_value":"76931705800000000000000","symbol":"btc/usd","timestamp":1779223907000,"value":76931.7058},"timestamp":1779223908273,"topic":"crypto_prices_chainlink","type":"update"};;{"connection_id":"connection-id","payload":{"full_accuracy_value":"76931705800000000000000","symbol":"btc/usd","timestamp":1779223908000,"value":76931.7058},"timestamp":1779223909002,"topic":"crypto_prices_chainlink","type":"update"};;{"connection_id":"connection-id","payload":{"full_accuracy_value":"298.68","received_at":1779223909000,"symbol":"aapl","timestamp":1779223909000,"value":298.68},"timestamp":1779223909200,"topic":"equity_prices","type":"update"};;{"connection_id":"connection-id","payload":{"full_accuracy_value":"298.67998","received_at":1779223910000,"symbol":"aapl","timestamp":1779223910000,"value":298.67998},"timestamp":1779223910201,"topic":"equity_prices","type":"update"};;{"connection_id":"connection-id","payload":{"full_accuracy_value":"76931560000000000000000","symbol":"btc/usd","timestamp":1779223909000,"value":76931.56},"timestamp":1779223910352,"topic":"crypto_prices_chainlink","type":"update"};;{"connection_id":"connection-id","payload":{"full_accuracy_value":"76931605320000000000000","symbol":"btc/usd","timestamp":1779223910000,"value":76931.60532},"timestamp":1779223910873,"topic":"crypto_prices_chainlink","type":"update"};;{"connection_id":"connection-id","payload":{"full_accuracy_value":"298.68","received_at":1779223911000,"symbol":"aapl","timestamp":1779223911000,"value":298.68},"timestamp":1779223911199,"topic":"equity_prices","type":"update"};;{"connection_id":"connection-id","payload":{"full_accuracy_value":"298.68","received_at":1779223912000,"symbol":"aapl","timestamp":1779223912000,"value":298.68},"timestamp":1779223912202,"topic":"equity_prices","type":"update"};;{"connection_id":"connection-id","payload":{"full_accuracy_value":"76931477160000000000000","symbol":"btc/usd","timestamp":1779223911000,"value":76931.47716},"timestamp":1779223912258,"topic":"crypto_prices_chainlink","type":"update"};;{"connection_id":"connection-id","payload":{"body":"sample comment body","createdAt":"2026-05-19T20:51:52.452563Z","id":"sample-comment-id","parentEntityID":16167,"parentEntityType":"Event","profile":{"baseAddress":"0x0000000000000000000000000000000000000000","displayUsernamePublic":false,"name":"sample-user","positions":[{"positionSize":"229625921","tokenId":"3192689304828767159232889612891719105504357313659012189260030438494464480574"}],"proxyWallet":"0x0000000000000000000000000000000000000000","pseudonym":"sample-user"},"reactionCount":0,"reportCount":0,"userAddress":"0x0000000000000000000000000000000000000000"},"timestamp":1779223912459,"topic":"comments","type":"comment_created"};;{"connection_id":"connection-id","payload":{"body":"sample comment body","createdAt":"2026-05-19T20:51:52.76848Z","id":"sample-comment-id","parentCommentID":"sample-comment-id","parentEntityID":11108,"parentEntityType":"Series","profile":{"baseAddress":"0x0000000000000000000000000000000000000000","displayUsernamePublic":false,"name":"sample-user","positions":[{"positionSize":"30000000","tokenId":"66629064489477466768662806250988336872338702240474679979933193350583920321989"},{"positionSize":"1000000000","tokenId":"7122071008540159382319461242464091511726150707752561940556040603147961655749"},{"positionSize":"1009750000","tokenId":"94166303982175958028902656257572626164723180761209063421675449114667885562877"},{"positionSize":"1000000000","tokenId":"113106985083325842388551394508728083081194247309626998773238277594120125794258"},{"positionSize":"111111111","tokenId":"87328467486543867601712185609859202296472222156656577383701214964611756884831"},{"positionSize":"382853333","tokenId":"58043227244299295113170654770356950788118952727141650273362103146461876060132"},{"positionSize":"287905713","tokenId":"113816604203355253805119794118359493506575299149532326875279222539991856010138"}],"proxyWallet":"0x0000000000000000000000000000000000000000","pseudonym":"sample-user"},"reactionCount":0,"replyAddress":"0x0000000000000000000000000000000000000000","reportCount":0,"userAddress":"0x0000000000000000000000000000000000000000"},"timestamp":1779223912775,"topic":"comments","type":"comment_created"};;{"connection_id":"connection-id","payload":{"full_accuracy_value":"76931372160000000000000","symbol":"btc/usd","timestamp":1779223912000,"value":76931.37216},"timestamp":1779223912934,"topic":"crypto_prices_chainlink","type":"update"};;{"connection_id":"connection-id","payload":{"full_accuracy_value":"298.68","received_at":1779223913000,"symbol":"aapl","timestamp":1779223913000,"value":298.68},"timestamp":1779223913202,"topic":"equity_prices","type":"update"};;{"connection_id":"connection-id","payload":{"body":"sample comment body","createdAt":"2026-05-19T20:51:54.064801Z","id":"sample-comment-id","parentCommentID":"sample-comment-id","parentEntityID":45915,"parentEntityType":"Event","profile":{"baseAddress":"0x0000000000000000000000000000000000000000","displayUsernamePublic":false,"name":"sample-user","positions":[{"positionSize":"25995834","tokenId":"111901744542692526827481385722975834672043376661227579870355575009066606657994"},{"positionSize":"2000000000","tokenId":"49821018408733695378907631766783388197384982451576409356148180829521508621967"},{"positionSize":"16000000","tokenId":"109876868437950584369987384406356259939519193117253465815665152916226511121427"},{"positionSize":"819993748","tokenId":"34763699632057764824138626876692302096202604335992573366008355204521657293675"},{"positionSize":"799998532","tokenId":"36262307788727352725358528951052957737657822670589615830114396216160368496388"}],"proxyWallet":"0x0000000000000000000000000000000000000000","pseudonym":"sample-user"},"reactionCount":0,"replyAddress":"0x0000000000000000000000000000000000000000","reportCount":0,"userAddress":"0x0000000000000000000000000000000000000000"},"timestamp":1779223914071,"topic":"comments","type":"comment_created"};;{"connection_id":"connection-id","payload":{"full_accuracy_value":"76931372160000000000000","symbol":"btc/usd","timestamp":1779223913000,"value":76931.37216},"timestamp":1779223914133,"topic":"crypto_prices_chainlink","type":"update"};;{"connection_id":"connection-id","payload":{"full_accuracy_value":"298.67995","received_at":1779223914000,"symbol":"aapl","timestamp":1779223914000,"value":298.67995},"timestamp":1779223914200,"topic":"equity_prices","type":"update"};;{"connection_id":"connection-id","payload":{"full_accuracy_value":"298.68001","received_at":1779223915000,"symbol":"aapl","timestamp":1779223915000,"value":298.68001},"timestamp":1779223915201,"topic":"equity_prices","type":"update"};;{"connection_id":"connection-id","payload":{"full_accuracy_value":"76931350470000000000000","symbol":"btc/usd","timestamp":1779223914000,"value":76931.35047},"timestamp":1779223915341,"topic":"crypto_prices_chainlink","type":"update"};;{"connection_id":"connection-id","payload":{"body":"sample comment body","createdAt":"2026-05-19T20:51:55.467893Z","id":"sample-comment-id","parentCommentID":"sample-comment-id","parentEntityID":45915,"parentEntityType":"Event","profile":{"baseAddress":"0x0000000000000000000000000000000000000000","displayUsernamePublic":false,"name":"sample-user","profileImage":null,"proxyWallet":"0x0000000000000000000000000000000000000000","pseudonym":"sample-user"},"reactionCount":0,"replyAddress":"0x0000000000000000000000000000000000000000","reportCount":0,"userAddress":"0x0000000000000000000000000000000000000000"},"timestamp":1779223915474,"topic":"comments","type":"comment_created"};;{"connection_id":"connection-id","payload":{"full_accuracy_value":"76931331834777135000000","symbol":"btc/usd","timestamp":1779223915000,"value":76931.33183477714},"timestamp":1779223916043,"topic":"crypto_prices_chainlink","type":"update"};;{"connection_id":"connection-id","payload":{"full_accuracy_value":"298.68004","received_at":1779223916000,"symbol":"aapl","timestamp":1779223916000,"value":298.68004},"timestamp":1779223916200,"topic":"equity_prices","type":"update"};;{"connection_id":"connection-id","payload":{"full_accuracy_value":"298.68","received_at":1779223917000,"symbol":"aapl","timestamp":1779223917000,"value":298.68},"timestamp":1779223917201,"topic":"equity_prices","type":"update"};;{"connection_id":"connection-id","payload":{"full_accuracy_value":"76931337622495390000000","symbol":"btc/usd","timestamp":1779223916000,"value":76931.3376224954},"timestamp":1779223917302,"topic":"crypto_prices_chainlink","type":"update"};;{"connection_id":"connection-id","payload":{"full_accuracy_value":"76932673070000000000000","symbol":"btc/usd","timestamp":1779223917000,"value":76932.67307},"timestamp":1779223917882,"topic":"crypto_prices_chainlink","type":"update"};;{"connection_id":"connection-id","payload":{"full_accuracy_value":"298.68","received_at":1779223918000,"symbol":"aapl","timestamp":1779223918000,"value":298.68},"timestamp":1779223918204,"topic":"equity_prices","type":"update"};;{"connection_id":"connection-id","payload":{"full_accuracy_value":"298.67986","received_at":1779223919000,"symbol":"aapl","timestamp":1779223919000,"value":298.67986},"timestamp":1779223919212,"topic":"equity_prices","type":"update"};;{"connection_id":"connection-id","payload":{"full_accuracy_value":"76935841000000000000000","symbol":"btc/usd","timestamp":1779223918000,"value":76935.841},"timestamp":1779223919226,"topic":"crypto_prices_chainlink","type":"update"};;{"connection_id":"connection-id","payload":{"full_accuracy_value":"76935841000000000000000","symbol":"btc/usd","timestamp":1779223919000,"value":76935.841},"timestamp":1779223919884,"topic":"crypto_prices_chainlink","type":"update"};;{"connection_id":"connection-id","payload":{"full_accuracy_value":"298.68003","received_at":1779223920000,"symbol":"aapl","timestamp":1779223920000,"value":298.68003},"timestamp":1779223920201,"topic":"equity_prices","type":"update"};;{"connection_id":"connection-id","payload":{"body":"sample comment body","createdAt":"2026-05-19T20:52:01.12576Z","id":"sample-comment-id","parentEntityID":10659,"parentEntityType":"Series","profile":{"baseAddress":"0x0000000000000000000000000000000000000000","displayUsernamePublic":false,"name":"sample-user","positions":[{"positionSize":"17399957039","tokenId":"60389485299635578552321047069110312097691070838596235573356288001333998664216"}],"profileImage":null,"proxyWallet":"0x0000000000000000000000000000000000000000","pseudonym":"sample-user"},"reactionCount":0,"reportCount":0,"userAddress":"0x0000000000000000000000000000000000000000"},"timestamp":1779223921133,"topic":"comments","type":"comment_created"};;{"connection_id":"connection-id","payload":{"full_accuracy_value":"298.67999","received_at":1779223921000,"symbol":"aapl","timestamp":1779223921000,"value":298.67999},"timestamp":1779223921198,"topic":"equity_prices","type":"update"};;{"connection_id":"connection-id","payload":{"full_accuracy_value":"76935051903501425000000","symbol":"btc/usd","timestamp":1779223920000,"value":76935.05190350143},"timestamp":1779223921217,"topic":"crypto_prices_chainlink","type":"update"};;{"connection_id":"connection-id","payload":{"full_accuracy_value":"298.67971","received_at":1779223922000,"symbol":"aapl","timestamp":1779223922000,"value":298.67971},"timestamp":1779223922200,"topic":"equity_prices","type":"update"};;{"connection_id":"connection-id","payload":{"full_accuracy_value":"76934204100000000000000","symbol":"btc/usd","timestamp":1779223921000,"value":76934.2041},"timestamp":1779223922889,"topic":"crypto_prices_chainlink","type":"update"};;{"connection_id":"connection-id","payload":{"full_accuracy_value":"298.68","received_at":1779223923000,"symbol":"aapl","timestamp":1779223923000,"value":298.68},"timestamp":1779223923200,"topic":"equity_prices","type":"update"};;{"connection_id":"connection-id","payload":{"body":"sample comment body","createdAt":"2026-05-19T20:52:03.65492Z","id":"sample-comment-id","parentCommentID":"sample-comment-id","parentEntityID":10188,"parentEntityType":"Series","profile":{"baseAddress":"0x0000000000000000000000000000000000000000","bio":"Nba fan","displayUsernamePublic":false,"name":"sample-user","positions":[{"positionSize":"16949151","tokenId":"8199493545872276685007649098855627956832512958032108818142031783023965647133"}],"proxyWallet":"0x0000000000000000000000000000000000000000","pseudonym":"sample-user"},"reactionCount":0,"replyAddress":"0x0000000000000000000000000000000000000000","reportCount":0,"userAddress":"0x0000000000000000000000000000000000000000"},"timestamp":1779223923661,"topic":"comments","type":"comment_created"};;{"connection_id":"connection-id","payload":{"full_accuracy_value":"76934216360000000000000","symbol":"btc/usd","timestamp":1779223922000,"value":76934.21636},"timestamp":1779223923782,"topic":"crypto_prices_chainlink","type":"update"};;{"connection_id":"connection-id","payload":{"full_accuracy_value":"298.68","received_at":1779223924000,"symbol":"aapl","timestamp":1779223924000,"value":298.68},"timestamp":1779223924201,"topic":"equity_prices","type":"update"};;{"connection_id":"connection-id","payload":{"full_accuracy_value":"76934632520000000000000","symbol":"btc/usd","timestamp":1779223923000,"value":76934.63252},"timestamp":1779223924743,"topic":"crypto_prices_chainlink","type":"update"};;{"connection_id":"connection-id","payload":{"full_accuracy_value":"298.67957","received_at":1779223925000,"symbol":"aapl","timestamp":1779223925000,"value":298.67957},"timestamp":1779223925201,"topic":"equity_prices","type":"update"};;{"connection_id":"connection-id","payload":{"full_accuracy_value":"76934929965172575000000","symbol":"btc/usd","timestamp":1779223924000,"value":76934.92996517257},"timestamp":1779223925548,"topic":"crypto_prices_chainlink","type":"update"};;{"connection_id":"connection-id","payload":{"full_accuracy_value":"298.67986","received_at":1779223926000,"symbol":"aapl","timestamp":1779223926000,"value":298.67986},"timestamp":1779223926212,"topic":"equity_prices","type":"update"};;{"connection_id":"connection-id","payload":{"full_accuracy_value":"76934910930000000000000","symbol":"btc/usd","timestamp":1779223925000,"value":76934.91093},"timestamp":1779223926390,"topic":"crypto_prices_chainlink","type":"update"};;{"connection_id":"connection-id","payload":{"full_accuracy_value":"298.6794","received_at":1779223927000,"symbol":"aapl","timestamp":1779223927000,"value":298.6794},"timestamp":1779223927222,"topic":"equity_prices","type":"update"};;{"connection_id":"connection-id","payload":{"full_accuracy_value":"76935217946435970000000","symbol":"btc/usd","timestamp":1779223926000,"value":76935.21794643597},"timestamp":1779223927322,"topic":"crypto_prices_chainlink","type":"update"};;{"connection_id":"connection-id","payload":{"full_accuracy_value":"298.67941","received_at":1779223928000,"symbol":"aapl","timestamp":1779223928000,"value":298.67941},"timestamp":1779223928223,"topic":"equity_prices","type":"update"};;{"connection_id":"connection-id","payload":{"full_accuracy_value":"76934887040000000000000","symbol":"btc/usd","timestamp":1779223927000,"value":76934.88704},"timestamp":1779223928764,"topic":"crypto_prices_chainlink","type":"update"};;{"connection_id":"connection-id","payload":{"full_accuracy_value":"298.67927","received_at":1779223929000,"symbol":"aapl","timestamp":1779223929000,"value":298.67927},"timestamp":1779223929231,"topic":"equity_prices","type":"update"};;{"connection_id":"connection-id","payload":{"full_accuracy_value":"76935015741925175000000","symbol":"btc/usd","timestamp":1779223928000,"value":76935.01574192518},"timestamp":1779223929409,"topic":"crypto_prices_chainlink","type":"update"};;{"connection_id":"connection-id","payload":{"full_accuracy_value":"76935015741925175000000","symbol":"btc/usd","timestamp":1779223929000,"value":76935.01574192518},"timestamp":1779223930110,"topic":"crypto_prices_chainlink","type":"update"};;{"connection_id":"connection-id","payload":{"full_accuracy_value":"298.67912","received_at":1779223930000,"symbol":"aapl","timestamp":1779223930000,"value":298.67912},"timestamp":1779223930202,"topic":"equity_prices","type":"update"};;{"connection_id":"connection-id","payload":{"full_accuracy_value":"298.67986","received_at":1779223931000,"symbol":"aapl","timestamp":1779223931000,"value":298.67986},"timestamp":1779223931203,"topic":"equity_prices","type":"update"};;{"connection_id":"connection-id","payload":{"full_accuracy_value":"76935082141556280000000","symbol":"btc/usd","timestamp":1779223930000,"value":76935.08214155628},"timestamp":1779223931327,"topic":"crypto_prices_chainlink","type":"update"};;{"connection_id":"connection-id","payload":{"body":"sample comment body","createdAt":"2026-05-19T20:52:11.973318Z","id":"sample-comment-id","parentCommentID":"sample-comment-id","parentEntityID":11363,"parentEntityType":"Series","profile":{"baseAddress":"0x0000000000000000000000000000000000000000","displayUsernamePublic":false,"name":"sample-user","proxyWallet":"0x0000000000000000000000000000000000000000","pseudonym":"sample-user"},"reactionCount":0,"replyAddress":"0x0000000000000000000000000000000000000000","reportCount":0,"userAddress":"0x0000000000000000000000000000000000000000"},"timestamp":1779223931981,"topic":"comments","type":"comment_created"};;{"connection_id":"connection-id","payload":{"full_accuracy_value":"298.67986","received_at":1779223932000,"symbol":"aapl","timestamp":1779223932000,"value":298.67986},"timestamp":1779223932199,"topic":"equity_prices","type":"update"};;{"connection_id":"connection-id","payload":{"full_accuracy_value":"76935086142114800000000","symbol":"btc/usd","timestamp":1779223931000,"value":76935.0861421148},"timestamp":1779223932057,"topic":"crypto_prices_chainlink","type":"update"};;{"connection_id":"connection-id","payload":{"full_accuracy_value":"298.67969","received_at":1779223933000,"symbol":"aapl","timestamp":1779223933000,"value":298.67969},"timestamp":1779223933201,"topic":"equity_prices","type":"update"};;{"connection_id":"connection-id","payload":{"full_accuracy_value":"76934760020000000000000","symbol":"btc/usd","timestamp":1779223932000,"value":76934.76002},"timestamp":1779223933363,"topic":"crypto_prices_chainlink","type":"update"};;{"connection_id":"connection-id","payload":{"full_accuracy_value":"298.67936","received_at":1779223934000,"symbol":"aapl","timestamp":1779223934000,"value":298.67936},"timestamp":1779223934200,"topic":"equity_prices","type":"update"};;{"connection_id":"connection-id","payload":{"full_accuracy_value":"76935095568257405000000","symbol":"btc/usd","timestamp":1779223933000,"value":76935.0955682574},"timestamp":1779223934221,"topic":"crypto_prices_chainlink","type":"update"};;{"connection_id":"connection-id","payload":{"full_accuracy_value":"298.67952","received_at":1779223935000,"symbol":"aapl","timestamp":1779223935000,"value":298.67952},"timestamp":1779223935201,"topic":"equity_prices","type":"update"};;{"connection_id":"connection-id","payload":{"full_accuracy_value":"76935062104084925000000","symbol":"btc/usd","timestamp":1779223934000,"value":76935.06210408492},"timestamp":1779223935606,"topic":"crypto_prices_chainlink","type":"update"};;{"connection_id":"connection-id","payload":{"full_accuracy_value":"298.68","received_at":1779223936000,"symbol":"aapl","timestamp":1779223936000,"value":298.68},"timestamp":1779223936198,"topic":"equity_prices","type":"update"};;{"connection_id":"connection-id","payload":{"full_accuracy_value":"76935060731338610000000","symbol":"btc/usd","timestamp":1779223935000,"value":76935.06073133861},"timestamp":1779223936115,"topic":"crypto_prices_chainlink","type":"update"};;{"connection_id":"connection-id","payload":{"full_accuracy_value":"298.67966","received_at":1779223937000,"symbol":"aapl","timestamp":1779223937000,"value":298.67966},"timestamp":1779223937200,"topic":"equity_prices","type":"update"};;{"connection_id":"connection-id","payload":{"full_accuracy_value":"76935213796855615000000","symbol":"btc/usd","timestamp":1779223936000,"value":76935.21379685562},"timestamp":1779223937537,"topic":"crypto_prices_chainlink","type":"update"};;{"connection_id":"connection-id","payload":{"full_accuracy_value":"298.67971","received_at":1779223938000,"symbol":"aapl","timestamp":1779223938000,"value":298.67971},"timestamp":1779223938210,"topic":"equity_prices","type":"update"};;{"connection_id":"connection-id","payload":{"full_accuracy_value":"76934827160000000000000","symbol":"btc/usd","timestamp":1779223937000,"value":76934.82716},"timestamp":1779223938447,"topic":"crypto_prices_chainlink","type":"update"};;{"connection_id":"connection-id","payload":{"full_accuracy_value":"298.67956","received_at":1779223939000,"symbol":"aapl","timestamp":1779223939000,"value":298.67956},"timestamp":1779223939199,"topic":"equity_prices","type":"update"};;{"connection_id":"connection-id","payload":{"full_accuracy_value":"76935162345403275000000","symbol":"btc/usd","timestamp":1779223938000,"value":76935.16234540328},"timestamp":1779223939196,"topic":"crypto_prices_chainlink","type":"update"};;{"connection_id":"connection-id","payload":{"full_accuracy_value":"298.67986","received_at":1779223940000,"symbol":"aapl","timestamp":1779223940000,"value":298.67986},"timestamp":1779223940202,"topic":"equity_prices","type":"update"};;{"connection_id":"connection-id","payload":{"full_accuracy_value":"76935429780233920000000","symbol":"btc/usd","timestamp":1779223939000,"value":76935.42978023391},"timestamp":1779223940813,"topic":"crypto_prices_chainlink","type":"update"};;{"connection_id":"connection-id","payload":{"full_accuracy_value":"298.67981","received_at":1779223941000,"symbol":"aapl","timestamp":1779223941000,"value":298.67981},"timestamp":1779223941199,"topic":"equity_prices","type":"update"};;{"connection_id":"connection-id","payload":{"full_accuracy_value":"76935826580000000000000","symbol":"btc/usd","timestamp":1779223941000,"value":76935.82658},"timestamp":1779223942155,"topic":"crypto_prices_chainlink","type":"update"};;{"connection_id":"connection-id","payload":{"full_accuracy_value":"298.67986","received_at":1779223942000,"symbol":"aapl","timestamp":1779223942000,"value":298.67986},"timestamp":1779223942200,"topic":"equity_prices","type":"update"};;{"connection_id":"connection-id","payload":{"body":"sample comment body","createdAt":"2026-05-19T20:52:22.902116Z","id":"sample-comment-id","parentEntityID":16167,"parentEntityType":"Event","profile":{"baseAddress":"0x0000000000000000000000000000000000000000","displayUsernamePublic":false,"name":"sample-user","positions":[{"positionSize":"229625921","tokenId":"3192689304828767159232889612891719105504357313659012189260030438494464480574"}],"proxyWallet":"0x0000000000000000000000000000000000000000","pseudonym":"sample-user"},"reactionCount":0,"reportCount":0,"userAddress":"0x0000000000000000000000000000000000000000"},"timestamp":1779223942908,"topic":"comments","type":"comment_created"};;{"connection_id":"connection-id","payload":{"full_accuracy_value":"76936011881156000000000","symbol":"btc/usd","timestamp":1779223942000,"value":76936.011881156},"timestamp":1779223942886,"topic":"crypto_prices_chainlink","type":"update"};;{"connection_id":"connection-id","payload":{"full_accuracy_value":"298.68","received_at":1779223943000,"symbol":"aapl","timestamp":1779223943000,"value":298.68},"timestamp":1779223943200,"topic":"equity_prices","type":"update"};;{"connection_id":"connection-id","payload":{"full_accuracy_value":"298.67999","received_at":1779223944000,"symbol":"aapl","timestamp":1779223944000,"value":298.67999},"timestamp":1779223944217,"topic":"equity_prices","type":"update"};;{"connection_id":"connection-id","payload":{"full_accuracy_value":"76935878400000000000000","symbol":"btc/usd","timestamp":1779223943000,"value":76935.8784},"timestamp":1779223944579,"topic":"crypto_prices_chainlink","type":"update"};;{"connection_id":"connection-id","payload":{"full_accuracy_value":"76938293510000000000000","symbol":"btc/usd","timestamp":1779223944000,"value":76938.29351},"timestamp":1779223945038,"topic":"crypto_prices_chainlink","type":"update"};;{"connection_id":"connection-id","payload":{"full_accuracy_value":"298.67941","received_at":1779223945000,"symbol":"aapl","timestamp":1779223945000,"value":298.67941},"timestamp":1779223945201,"topic":"equity_prices","type":"update"};;{"connection_id":"connection-id","payload":{"full_accuracy_value":"298.67999","received_at":1779223946000,"symbol":"aapl","timestamp":1779223946000,"value":298.67999},"timestamp":1779223946201,"topic":"equity_prices","type":"update"};;{"connection_id":"connection-id","payload":{"full_accuracy_value":"76939457600000000000000","symbol":"btc/usd","timestamp":1779223945000,"value":76939.4576},"timestamp":1779223946298,"topic":"crypto_prices_chainlink","type":"update"};;{"connection_id":"connection-id","payload":{"full_accuracy_value":"76940400000000000000000","symbol":"btc/usd","timestamp":1779223946000,"value":76940.4},"timestamp":1779223947085,"topic":"crypto_prices_chainlink","type":"update"};;{"connection_id":"connection-id","payload":{"full_accuracy_value":"298.67997","received_at":1779223947000,"symbol":"aapl","timestamp":1779223947000,"value":298.67997},"timestamp":1779223947201,"topic":"equity_prices","type":"update"};;{"connection_id":"connection-id","payload":{"full_accuracy_value":"76942345030000000000000","symbol":"btc/usd","timestamp":1779223947000,"value":76942.34503},"timestamp":1779223948193,"topic":"crypto_prices_chainlink","type":"update"};;{"connection_id":"connection-id","payload":{"full_accuracy_value":"298.68","received_at":1779223948000,"symbol":"aapl","timestamp":1779223948000,"value":298.68},"timestamp":1779223948202,"topic":"equity_prices","type":"update"};;{"connection_id":"connection-id","payload":{"full_accuracy_value":"76942314400000000000000","symbol":"btc/usd","timestamp":1779223948000,"value":76942.3144},"timestamp":1779223948795,"topic":"crypto_prices_chainlink","type":"update"};;{"connection_id":"connection-id","payload":{"full_accuracy_value":"298.67956","received_at":1779223949000,"symbol":"aapl","timestamp":1779223949000,"value":298.67956},"timestamp":1779223949199,"topic":"equity_prices","type":"update"};;{"connection_id":"connection-id","payload":{"full_accuracy_value":"76942296410000000000000","symbol":"btc/usd","timestamp":1779223949000,"value":76942.29641},"timestamp":1779223949931,"topic":"crypto_prices_chainlink","type":"update"};;{"connection_id":"connection-id","payload":{"full_accuracy_value":"298.68","received_at":1779223950000,"symbol":"aapl","timestamp":1779223950000,"value":298.68},"timestamp":1779223950204,"topic":"equity_prices","type":"update"};;{"connection_id":"connection-id","payload":{"full_accuracy_value":"76942464220000000000000","symbol":"btc/usd","timestamp":1779223950000,"value":76942.46422},"timestamp":1779223951112,"topic":"crypto_prices_chainlink","type":"update"};;{"connection_id":"connection-id","payload":{"full_accuracy_value":"298.67912","received_at":1779223951000,"symbol":"aapl","timestamp":1779223951000,"value":298.67912},"timestamp":1779223951202,"topic":"equity_prices","type":"update"};;{"connection_id":"connection-id","payload":{"full_accuracy_value":"298.68","received_at":1779223952000,"symbol":"aapl","timestamp":1779223952000,"value":298.68},"timestamp":1779223952209,"topic":"equity_prices","type":"update"};;{"connection_id":"connection-id","payload":{"full_accuracy_value":"76943526508973130000000","symbol":"btc/usd","timestamp":1779223951000,"value":76943.52650897313},"timestamp":1779223952257,"topic":"crypto_prices_chainlink","type":"update"};;{"connection_id":"connection-id","payload":{"full_accuracy_value":"76943774770000000000000","symbol":"btc/usd","timestamp":1779223952000,"value":76943.77477},"timestamp":1779223952921,"topic":"crypto_prices_chainlink","type":"update"};;{"connection_id":"connection-id","payload":{"full_accuracy_value":"298.68","received_at":1779223953000,"symbol":"aapl","timestamp":1779223953000,"value":298.68},"timestamp":1779223953198,"topic":"equity_prices","type":"update"};;{"connection_id":"connection-id","payload":{"full_accuracy_value":"76943745599955960000000","symbol":"btc/usd","timestamp":1779223953000,"value":76943.74559995596},"timestamp":1779223954066,"topic":"crypto_prices_chainlink","type":"update"};;{"connection_id":"connection-id","payload":{"full_accuracy_value":"298.68","received_at":1779223954000,"symbol":"aapl","timestamp":1779223954000,"value":298.68},"timestamp":1779223954201,"topic":"equity_prices","type":"update"};;{"connection_id":"connection-id","payload":{"full_accuracy_value":"298.67998","received_at":1779223955000,"symbol":"aapl","timestamp":1779223955000,"value":298.67998},"timestamp":1779223955201,"topic":"equity_prices","type":"update"};;